<?xml version="1.0" ?>
<!-- Generated using onshape-to-robot -->
<!-- OnShape document_id: 6a6e5b10ef079339c2ddde84 -->
<robot name="adjustable_height_arm_urdf">
    <!-- Link base -->
    <link name="base">
        <inertial>
            <origin xyz="-6.03445e-19 3.12383e-18 0.020169" rpy="0 0 0"/>
            <mass value="0.39382"/>
            <inertia ixx="0.000177195" ixy="0" ixz="0" iyy="0.000177195" iyz="0" izz="0.000123463"/>
        </inertial>
        <!-- Part base -->
        <visual>
            <origin xyz="0 0 0" rpy="0 -0 0"/>
            <geometry>
                <mesh filename="package://base.stl"/>
            </geometry>
            <material name="base_material">
                <color rgba="0.301961 0.290196 0.262745 1.0"/>
            </material>
        </visual>
    </link>
    <!-- Link part1 -->
    <link name="part1">
        <inertial>
            <origin xyz="1.04896e-19 1.19328e-18 0.027892" rpy="0 0 0"/>
            <mass value="0.298971"/>
            <inertia ixx="0.000123868" ixy="0" ixz="0" iyy="0.000123868" iyz="0" izz="9.58869e-05"/>
        </inertial>
        <!-- Part part1 -->
        <visual>
            <origin xyz="0 -4.65366e-18 -0.053" rpy="0 -0 0"/>
            <geometry>
                <mesh filename="package://part1.stl"/>
            </geometry>
            <material name="part1_material">
                <color rgba="0.866667 0.321569 0.156863 1.0"/>
            </material>
        </visual>
    </link>
    <!-- Link part2 -->
    <link name="part2">
        <inertial>
            <origin xyz="6.6239e-09 -1.69553e-10 -0.0149478" rpy="0 0 0"/>
            <mass value="0.148575"/>
            <inertia ixx="6.89125e-05" ixy="6.11498e-11" ixz="-5.85353e-12" iyy="6.97803e-05" iyz="1.49834e-13" izz="6.69782e-05"/>
        </inertial>
        <!-- Part part2 -->
        <visual>
            <origin xyz="2.82344e-18 1.22153e-17 0.106" rpy="3.14159 -0 -8.41403e-56"/>
            <geometry>
                <mesh filename="package://part2.stl"/>
            </geometry>
            <material name="part2_material">
                <color rgba="0.372549 0.654902 0.239216 1.0"/>
            </material>
        </visual>
    </link>
    <!-- Link part3 -->
    <link name="part3">
        <inertial>
            <origin xyz="-3.06226e-08 -0.0314519 -0.02" rpy="0 0 0"/>
            <mass value="0.642728"/>
            <inertia ixx="0.000872587" ixy="2.83073e-11" ixz="2.04764e-10" iyy="0.000126043" iyz="-1.52882e-10" izz="0.000853226"/>
        </inertial>
        <!-- Part part3 -->
        <visual>
            <origin xyz="0 0.131 -0.02" rpy="1.5708 1.5708 0"/>
            <geometry>
                <mesh filename="package://part3.stl"/>
            </geometry>
            <material name="part3_material">
                <color rgba="0.0862745 0.317647 0.690196 1.0"/>
            </material>
        </visual>
    </link>
    <!-- Link part4 -->
    <link name="part4">
        <inertial>
            <origin xyz="-3.54611e-08 -0.0331362 -0.02" rpy="0 0 0"/>
            <mass value="0.64593"/>
            <inertia ixx="0.000969336" ixy="2.66297e-11" ixz="-2.9556e-10" iyy="8.7724e-05" iyz="2.45199e-10" izz="0.000952436"/>
        </inertial>
        <!-- Part part4 -->
        <visual>
            <origin xyz="0 0.2285 -0.02" rpy="1.5708 1.5708 0"/>
            <geometry>
                <mesh filename="package://part4.stl"/>
            </geometry>
            <material name="part4_material">
                <color rgba="0.972549 0.529412 0.00392157 1.0"/>
            </material>
        </visual>
    </link>
    <!-- Frame tip (dummy link + fixed joint) -->
    <link name="tip">
        <origin xyz="0 0 0" rpy="0 -0 0"/>
        <inertial>
            <origin xyz="0 0 0" rpy="0 0 0"/>
            <mass value="1e-9"/>
            <inertia ixx="0" ixy="0" ixz="0" iyy="0" iyz="0" izz="0"/>
        </inertial>
    </link>
    <joint name="tip_frame" type="fixed">
        <origin xyz="1.00568e-18 -0.1325 -0.02" rpy="1.5708 -5.42342e-31 -1.57772e-30"/>
        <parent link="part4"/>
        <child link="tip"/>
        <axis xyz="0 0 0"/>
    </joint>
    <!-- Joint from part3 to part4 -->
    <joint name="part4" type="revolute">
        <origin xyz="9.86076e-32 -0.0975 0" rpy="1.20178e-31 -4.12919e-31 -2.16493e-15"/>
        <parent link="part3"/>
        <child link="part4"/>
        <axis xyz="0 0 1"/>
        <limit effort="10" velocity="10" lower="-3.141592653589793" upper="3.141592653589793"/>
    </joint>
    <!-- Joint from part2 to part3 -->
    <joint name="part3" type="revolute">
        <origin xyz="-0.02 1.22153e-17 -0.025" rpy="1.5708 3.58047e-15 -1.5708"/>
        <parent link="part2"/>
        <child link="part3"/>
        <axis xyz="0 0 1"/>
        <limit effort="10" velocity="10" lower="-3.141592653589793" upper="3.141592653589793"/>
    </joint>
    <!-- Joint from part1 to part2 -->
    <joint name="part2" type="revolute">
        <origin xyz="-2.82344e-18 2.35752e-18 0.053" rpy="-3.14159 1.71113e-29 -5.55112e-17"/>
        <parent link="part1"/>
        <child link="part2"/>
        <axis xyz="0 0 1"/>
        <limit effort="10" velocity="10" lower="-3.141592653589793" upper="3.141592653589793"/>
    </joint>
    <!-- Joint from base to part1 -->
    <joint name="slider" type="prismatic">
        <origin xyz="0 2.91893e-18 0.053" rpy="0 -0 0"/>
        <parent link="base"/>
        <child link="part1"/>
        <axis xyz="0 0 1"/>
        <limit effort="10" velocity="10" lower="-0.05" upper="-0"/>
    </joint>
</robot>
