<?xml version="1.0" ?>
<!-- Generated using onshape-to-robot -->
<!-- OnShape https://cad.onshape.com/documents/11a7f59e37f711d732274fca/w/7807518dc67487ad405722c8/e/5233c6445c575366a6cc0d50 -->
<mujoco model="quadruped_mujoco">
    <compiler angle="radian" meshdir="." autolimits="true"/>
    <option noslip_iterations="1"/>
    <default>
        <default class="quadruped_mujoco">
            <joint frictionloss="0.1" armature="0.005"/>
            <position kp="50" dampratio="1"/>
            <default class="visual">
                <geom type="mesh" contype="0" conaffinity="0" group="2"/>
            </default>
            <default class="collision">
                <geom group="3"/>
            </default>
        </default>
    </default>
    <worldbody>
        <!-- Link body -->
        <body name="body" pos="0 0 0" quat="1 0 0 0" childclass="quadruped_mujoco">
            <freejoint name="root"/>
            <inertial pos="-4.02184e-18 1.95168e-18 0.0143384" mass="0.0808736" fullinertia="7.37408e-05 7.37408e-05 0.000135878 -7.58445e-21 -2.11758e-21 1.66497e-21"/>
            <!-- Part body -->
            <!-- Mesh body -->
            <geom type="mesh" class="visual" pos="0 3.46945e-18 0.0286" quat="0 1 0 0" mesh="body" material="body_material"/>
            <geom class="collision" pos="0 3.46945e-18 0.0275" quat="0 1 0 0" type="box" size="0.015 0.015 0.001"/>
            <!-- Part body_2 -->
            <!-- Mesh body_2 -->
            <geom type="mesh" class="visual" pos="0 0 0" quat="1 0 0 0" mesh="body" material="body_material"/>
            <geom class="collision" pos="0 0 0.0011" quat="1 0 0 0" type="box" size="0.015 0.015 0.001"/>
            <!-- Part horn -->
            <!-- Mesh horn -->
            <geom type="mesh" class="visual" pos="-2.212e-18 -0.0485 0.0143" quat="0.733883 0 -5.56738e-17 0.679276" mesh="horn" material="horn_material"/>
            <!-- Part motor -->
            <!-- Mesh motor -->
            <geom type="mesh" class="visual" pos="-1.99015e-18 -0.0485 0.0143" quat="0 0 0 1" mesh="motor" material="motor_material"/>
            <geom class="collision" pos="-2.48001e-18 -0.0405 0.0143" quat="0 0 0 1" type="box" size="0.01 0.015 0.011"/>
            <!-- Part horn_2 -->
            <!-- Mesh horn_2 -->
            <geom type="mesh" class="visual" pos="0.0485 1.76924e-17 0.0143" quat="0.747744 -0 -1.11022e-16 0.663988" mesh="horn" material="horn_material"/>
            <!-- Part motor_2 -->
            <!-- Mesh motor_2 -->
            <geom type="mesh" class="visual" pos="0.0485 1.06975e-17 0.0143" quat="0.707107 0 0 -0.707107" mesh="motor" material="motor_material"/>
            <geom class="collision" pos="0.0405 8.66205e-18 0.0143" quat="0.707107 0 0 -0.707107" type="box" size="0.01 0.015 0.011"/>
            <!-- Part horn_3 -->
            <!-- Mesh horn_3 -->
            <geom type="mesh" class="visual" pos="1.36171e-17 0.0485 0.0143" quat="0.733883 0 0 0.679276" mesh="horn" material="horn_material"/>
            <!-- Part motor_3 -->
            <!-- Mesh motor_3 -->
            <geom type="mesh" class="visual" pos="-9.54098e-18 0.0485 0.0143" quat="1 0 0 4.16334e-16" mesh="motor" material="motor_material"/>
            <geom class="collision" pos="-2.87964e-18 0.0405 0.0143" quat="1 0 0 4.16334e-16" type="box" size="0.01 0.015 0.011"/>
            <!-- Part horn_4 -->
            <!-- Mesh horn_4 -->
            <geom type="mesh" class="visual" pos="-0.0485 2.40122e-18 0.0143" quat="0.733883 4.13823e-16 6.66134e-16 0.679276" mesh="horn" material="horn_material"/>
            <!-- Part motor_4 -->
            <!-- Mesh motor_4 -->
            <geom type="mesh" class="visual" pos="-0.0485 -3.61401e-18 0.0143" quat="0.707107 -2.77556e-16 -1.11022e-16 0.707107" mesh="motor" material="motor_material"/>
            <geom class="collision" pos="-0.0405 -2.24473e-18 0.0143" quat="0.707107 -2.77556e-16 -1.11022e-16 0.707107" type="box" size="0.01 0.015 0.011"/>
            <!-- Link doubleu -->
            <body name="doubleu" pos="-0.0485 -8.5303e-18 -0.0007" quat="3.98474e-16 -0.707107 -0.707107 5.80555e-16">
                <!-- Joint from body to doubleu -->
                <joint name="leg1_a" type="hinge"/>
                <inertial pos="4.20868e-19 -0.0203 -0.01615" mass="0.00830698" fullinertia="2.78361e-06 1.9255e-06 2.78361e-06 -2.9184e-22 -2.64394e-22 1.7062e-22"/>
                <!-- Part u -->
                <!-- Mesh u -->
                <geom type="mesh" class="visual" pos="0 -0.018 -0.01615" quat="0.707107 0.707107 -0 -1.95559e-30" mesh="u" material="u_material"/>
                <geom class="collision" pos="-6.10468e-33 -0.0191 -0.01615" quat="0.707107 0.707107 -0 -1.95559e-30" type="box" size="0.01 0.015 0.001"/>
                <!-- Part u_2 -->
                <!-- Mesh u_2 -->
                <geom type="mesh" class="visual" pos="-4.23155e-18 -0.0226 -0.01615" quat="0.5 -0.5 -0.5 -0.5" mesh="u" material="u_material"/>
                <geom class="collision" pos="-4.23155e-18 -0.0215 -0.01615" quat="0.5 -0.5 -0.5 -0.5" type="box" size="0.01 0.015 0.001"/>
                <!-- Link platesblock -->
                <body name="platesblock" pos="0.015 -0.0406 -0.01615" quat="0.707107 5.10529e-15 -0.707107 -5.14085e-15">
                    <!-- Joint from doubleu to platesblock -->
                    <joint name="leg1_b" type="hinge"/>
                    <inertial pos="5.09559e-15 -0.0315 0.0150372" mass="0.0417755" fullinertia="2.98279e-05 4.6241e-06 2.99828e-05 -2.99773e-12 -9.40927e-21 2.38016e-19"/>
                    <!-- Part plate -->
                    <!-- Mesh plate -->
                    <geom type="mesh" class="visual" pos="0.0143 0.006 0.015" quat="0.5 0.5 -0.5 -0.5" mesh="plate" material="plate_material"/>
                    <geom class="collision" pos="0.0131 -0.0315 0.015" quat="0.5 0.5 -0.5 -0.5" type="box" size="0.0365 0.0075 0.001"/>
                    <!-- Part plate_2 -->
                    <!-- Mesh plate_2 -->
                    <geom type="mesh" class="visual" pos="-0.012 0.006 0.015" quat="0.5 0.5 -0.5 -0.5" mesh="plate" material="plate_material"/>
                    <geom class="collision" pos="-0.0132 -0.0315 0.015" quat="0.5 0.5 -0.5 -0.5" type="box" size="0.0365 0.0075 0.001"/>
                    <!-- Part horn_5 -->
                    <!-- Mesh horn_5 -->
                    <geom type="mesh" class="visual" pos="0 0 0.015" quat="1 -0 -0 -0" mesh="horn" material="horn_material"/>
                    <!-- Part motor_5 -->
                    <!-- Mesh motor_5 -->
                    <geom type="mesh" class="visual" pos="2.67147e-16 4.71845e-16 0.015" quat="1 1.38778e-17 1.11022e-16 6.60305e-14" mesh="motor" material="motor_material"/>
                    <geom class="collision" pos="1.32529e-15 -0.008 0.015" quat="1 1.38778e-17 1.11022e-16 6.60305e-14" type="box" size="0.01 0.015 0.011"/>
                    <!-- Part horn_6 -->
                    <!-- Mesh horn_6 -->
                    <geom type="mesh" class="visual" pos="9.93476e-15 -0.063 0.015" quat="0.287808 -1.53783e-15 -4.996e-15 -0.957688" mesh="horn" material="horn_material"/>
                    <!-- Part motor_6 -->
                    <!-- Mesh motor_6 -->
                    <geom type="mesh" class="visual" pos="9.9365e-15 -0.063 0.015" quat="6.61062e-14 0 -5.32907e-15 -1" mesh="motor" material="motor_material"/>
                    <geom class="collision" pos="8.8788e-15 -0.055 0.015" quat="6.61062e-14 0 -5.32907e-15 -1" type="box" size="0.01 0.015 0.011"/>
                    <!-- Link leg -->
                    <body name="leg" pos="9.9365e-15 -0.063 5.75928e-16" quat="5.75726e-14 -2.77556e-17 5.32907e-15 1">
                        <!-- Joint from platesblock to leg -->
                        <joint name="leg1_c" type="hinge"/>
                        <inertial pos="-1.82494e-17 0.0533786 0.015" mass="0.0154162" fullinertia="2.13816e-05 3.58407e-06 1.88204e-05 6.70364e-35 5.76574e-38 -1.62049e-35"/>
                        <!-- Part leg -->
                        <!-- Mesh leg -->
                        <geom type="mesh" class="visual" pos="0 0 0.015" quat="0.707107 0.707107 -0 1.40248e-30" mesh="leg" material="leg_material"/>
                        <geom class="collision" pos="-1.3769e-31 0.035 -0.001" quat="0.707107 0.707107 -0 1.40248e-30" type="box" size="0.01 0.001 0.045"/>
                        <geom class="collision" pos="-1.38411e-31 0.035 0.031" quat="0.707107 0.707107 -0 1.40248e-30" type="box" size="0.01 0.001 0.045"/>
                        <geom class="collision" pos="-3.54987e-31 0.09 0.015" quat="0.707107 0.707107 -0 1.40248e-30" type="sphere" size="0.015"/>
                    </body>
                </body>
            </body>
            <!-- Link doubleu_2 -->
            <body name="doubleu_2" pos="-4.75344e-19 -0.0485 -0.0007" quat="3.33067e-16 -1.64508e-15 1 -1.39654e-16">
                <!-- Joint from body to doubleu_2 -->
                <joint name="leg2_a" type="hinge"/>
                <inertial pos="-2.11219e-17 -0.0203 -0.015" mass="0.00830698" fullinertia="2.78361e-06 1.9255e-06 2.78361e-06 -2.13471e-21 -2.69222e-22 5.45198e-21"/>
                <!-- Part u_3 -->
                <!-- Mesh u_3 -->
                <geom type="mesh" class="visual" pos="-4.7317e-17 -0.0226 -0.015" quat="0.5 -0.5 -0.5 -0.5" mesh="u" material="u_material"/>
                <geom class="collision" pos="-4.7317e-17 -0.0215 -0.015" quat="0.5 -0.5 -0.5 -0.5" type="box" size="0.01 0.015 0.001"/>
                <!-- Part u_4 -->
                <!-- Mesh u_4 -->
                <geom type="mesh" class="visual" pos="2.46519e-32 -0.018 -0.015" quat="0.707107 0.707107 0 2.78124e-32" mesh="u" material="u_material"/>
                <geom class="collision" pos="2.474e-32 -0.0191 -0.015" quat="0.707107 0.707107 0 2.78124e-32" type="box" size="0.01 0.015 0.001"/>
                <!-- Link platesblock_2 -->
                <body name="platesblock_2" pos="0.015 -0.0406 -0.015" quat="0.5 -0.5 -0.5 0.5">
                    <!-- Joint from doubleu_2 to platesblock_2 -->
                    <joint name="leg2_b" type="hinge"/>
                    <inertial pos="-0.0315 -3.94677e-16 0.0150372" mass="0.0417755" fullinertia="4.6241e-06 2.98279e-05 2.99828e-05 2.99773e-12 1.58289e-20 -2.40142e-21"/>
                    <!-- Part plate_3 -->
                    <!-- Mesh plate_3 -->
                    <geom type="mesh" class="visual" pos="0.006 -0.0143 0.015" quat="9.99201e-16 9.33878e-16 -0.707107 -0.707107" mesh="plate" material="plate_material"/>
                    <geom class="collision" pos="-0.0315 -0.0131 0.015" quat="9.99201e-16 9.33878e-16 -0.707107 -0.707107" type="box" size="0.0365 0.0075 0.001"/>
                    <!-- Part plate_4 -->
                    <!-- Mesh plate_4 -->
                    <geom type="mesh" class="visual" pos="0.006 0.012 0.015" quat="6.72223e-16 1.25117e-15 -0.707107 -0.707107" mesh="plate" material="plate_material"/>
                    <geom class="collision" pos="-0.0315 0.0132 0.015" quat="6.72223e-16 1.25117e-15 -0.707107 -0.707107" type="box" size="0.0365 0.0075 0.001"/>
                    <!-- Part horn_7 -->
                    <!-- Mesh horn_7 -->
                    <geom type="mesh" class="visual" pos="0 0 0.015" quat="1 0 2.22045e-16 1.52656e-16" mesh="horn" material="horn_material"/>
                    <!-- Part motor_7 -->
                    <!-- Mesh motor_7 -->
                    <geom type="mesh" class="visual" pos="-8.74301e-16 3.62557e-16 0.015" quat="0.707107 0 0 -0.707107" mesh="motor" material="motor_material"/>
                    <geom class="collision" pos="-0.008 3.41241e-16 0.015" quat="0.707107 0 0 -0.707107" type="box" size="0.01 0.015 0.011"/>
                    <!-- Part horn_8 -->
                    <!-- Mesh horn_8 -->
                    <geom type="mesh" class="visual" pos="-0.063 -1.14492e-15 0.015" quat="0.591665 -2.63921e-15 7.77156e-16 0.806184" mesh="horn" material="horn_material"/>
                    <!-- Part motor_8 -->
                    <!-- Mesh motor_8 -->
                    <geom type="mesh" class="visual" pos="-0.063 -1.14318e-15 0.015" quat="0.707107 -8.88178e-16 -1.11022e-15 0.707107" mesh="motor" material="motor_material"/>
                    <geom class="collision" pos="-0.055 -1.12187e-15 0.015" quat="0.707107 -8.88178e-16 -1.11022e-15 0.707107" type="box" size="0.01 0.015 0.011"/>
                    <!-- Link leg_2 -->
                    <body name="leg_2" pos="-0.063 -1.14492e-15 -2.60209e-17" quat="0.707107 -9.25028e-16 -7.77156e-16 0.707107">
                        <!-- Joint from platesblock_2 to leg_2 -->
                        <joint name="leg2_c" type="hinge"/>
                        <inertial pos="-1.82494e-17 0.0533786 0.015" mass="0.0154162" fullinertia="2.13816e-05 3.58407e-06 1.88204e-05 7.00778e-37 1.26052e-36 -8.71439e-37"/>
                        <!-- Part leg_2 -->
                        <!-- Mesh leg_2 -->
                        <geom type="mesh" class="visual" pos="0 0 0.015" quat="0.707107 0.707107 -0 4.87538e-32" mesh="leg" material="leg_material"/>
                        <geom class="collision" pos="-3.80872e-33 0.035 -0.001" quat="0.707107 0.707107 -0 4.87538e-32" type="box" size="0.01 0.001 0.045"/>
                        <geom class="collision" pos="-3.09381e-33 0.035 0.031" quat="0.707107 0.707107 -0 4.87538e-32" type="box" size="0.01 0.001 0.045"/>
                        <geom class="collision" pos="-8.87469e-33 0.09 0.015" quat="0.707107 0.707107 -0 4.87538e-32" type="sphere" size="0.015"/>
                    </body>
                </body>
            </body>
            <!-- Link doubleu_3 -->
            <body name="doubleu_3" pos="0.0485 3.19754e-17 -0.0007" quat="3.90397e-16 0.707107 0.707107 -4.17101e-16">
                <!-- Joint from body to doubleu_3 -->
                <joint name="leg3_a" type="hinge"/>
                <inertial pos="-5.56769e-19 0.0203 -0.01615" mass="0.00830698" fullinertia="2.78361e-06 1.9255e-06 2.78361e-06 8.88133e-22 -5.95365e-22 -1.77514e-21"/>
                <!-- Part u_5 -->
                <!-- Mesh u_5 -->
                <geom type="mesh" class="visual" pos="-6.18683e-18 0.0226 -0.01615" quat="0.5 0.5 0.5 -0.5" mesh="u" material="u_material"/>
                <geom class="collision" pos="-6.18683e-18 0.0215 -0.01615" quat="0.5 0.5 0.5 -0.5" type="box" size="0.01 0.015 0.001"/>
                <!-- Part u_6 -->
                <!-- Mesh u_6 -->
                <geom type="mesh" class="visual" pos="0 0.018 -0.01615" quat="0.707107 -0.707107 -0 -1.656e-31" mesh="u" material="u_material"/>
                <geom class="collision" pos="5.96576e-34 0.0191 -0.01615" quat="0.707107 -0.707107 -0 -1.656e-31" type="box" size="0.01 0.015 0.001"/>
                <!-- Link platesblock_3 -->
                <body name="platesblock_3" pos="-0.015 0.0406 -0.01615" quat="0.5 -0.5 0.5 -0.5">
                    <!-- Joint from doubleu_3 to platesblock_3 -->
                    <joint name="leg3_b" type="hinge"/>
                    <inertial pos="-0.0315 -1.26292e-15 0.0150372" mass="0.0417755" fullinertia="4.6241e-06 2.98279e-05 2.99828e-05 2.99773e-12 1.26526e-20 -9.77407e-21"/>
                    <!-- Part plate_5 -->
                    <!-- Mesh plate_5 -->
                    <geom type="mesh" class="visual" pos="0.006 -0.0143 0.015" quat="6.11317e-15 7.40046e-15 -0.707107 -0.707107" mesh="plate" material="plate_material"/>
                    <geom class="collision" pos="-0.0315 -0.0131 0.015" quat="6.11317e-15 7.40046e-15 -0.707107 -0.707107" type="box" size="0.0365 0.0075 0.001"/>
                    <!-- Part plate_6 -->
                    <!-- Mesh plate_6 -->
                    <geom type="mesh" class="visual" pos="0.006 0.012 0.015" quat="7.42612e-15 6.14462e-15 -0.707107 -0.707107" mesh="plate" material="plate_material"/>
                    <geom class="collision" pos="-0.0315 0.0132 0.015" quat="7.42612e-15 6.14462e-15 -0.707107 -0.707107" type="box" size="0.0365 0.0075 0.001"/>
                    <!-- Part horn_9 -->
                    <!-- Mesh horn_9 -->
                    <geom type="mesh" class="visual" pos="0 0 0.015" quat="1 -0 4.12864e-16 -1.73472e-17" mesh="horn" material="horn_material"/>
                    <!-- Part motor_9 -->
                    <!-- Mesh motor_9 -->
                    <geom type="mesh" class="visual" pos="-1.15186e-15 5.37764e-17 0.015" quat="0.707107 -1.02668e-18 2.22045e-16 -0.707107" mesh="motor" material="motor_material"/>
                    <geom class="collision" pos="-0.008 -9.96564e-17 0.015" quat="0.707107 -1.02668e-18 2.22045e-16 -0.707107" type="box" size="0.01 0.015 0.011"/>
                    <!-- Part horn_10 -->
                    <!-- Mesh horn_10 -->
                    <geom type="mesh" class="visual" pos="-0.063 -2.61423e-15 0.015" quat="0.0386127 3.02832e-16 -2.33147e-15 0.999254" mesh="horn" material="horn_material"/>
                    <!-- Part motor_10 -->
                    <!-- Mesh motor_10 -->
                    <geom type="mesh" class="visual" pos="-0.063 -2.61423e-15 0.015" quat="0.707107 1.72703e-16 -1.52656e-15 0.707107" mesh="motor" material="motor_material"/>
                    <geom class="collision" pos="-0.055 -2.43859e-15 0.015" quat="0.707107 1.72703e-16 -1.52656e-15 0.707107" type="box" size="0.01 0.015 0.011"/>
                    <!-- Link leg_3 -->
                    <body name="leg_3" pos="-0.063 -2.5431e-15 6.41848e-17" quat="0.707107 1.87399e-15 -1.33227e-15 0.707107">
                        <!-- Joint from platesblock_3 to leg_3 -->
                        <joint name="leg3_c" type="hinge"/>
                        <inertial pos="-1.82494e-17 0.0533786 0.015" mass="0.0154162" fullinertia="2.13816e-05 3.58407e-06 1.88204e-05 0 0 -1.35045e-34"/>
                        <!-- Part leg_3 -->
                        <!-- Mesh leg_3 -->
                        <geom type="mesh" class="visual" pos="0 0 0.015" quat="0.707107 0.707107 -0 -0" mesh="leg" material="leg_material"/>
                        <geom class="collision" pos="0 0.035 -0.001" quat="0.707107 0.707107 -0 -0" type="box" size="0.01 0.001 0.045"/>
                        <geom class="collision" pos="0 0.035 0.031" quat="0.707107 0.707107 -0 -0" type="box" size="0.01 0.001 0.045"/>
                        <geom class="collision" pos="0 0.09 0.015" quat="0.707107 0.707107 -0 -0" type="sphere" size="0.015"/>
                        <!-- Frame leg_tip (dummy link + fixed joint) -->
                        <site name="leg_tip" pos="-3.64292e-17 0.1053 0.015" quat="2.85151e-17 1.33078e-16 -0.707107 -0.707107"/>
                    </body>
                </body>
            </body>
            <!-- Link doubleu_4 -->
            <body name="doubleu_4" pos="3.81639e-17 0.0485 -0.0007" quat="1.11022e-16 1.0542e-16 -1 3.76491e-15">
                <!-- Joint from body to doubleu_4 -->
                <joint name="leg4_a" type="hinge"/>
                <inertial pos="-4.61075e-17 0.0203 -0.01615" mass="0.00830698" fullinertia="2.78361e-06 1.9255e-06 2.78361e-06 4.31663e-21 1.74197e-22 -1.84249e-20"/>
                <!-- Part u_7 -->
                <!-- Mesh u_7 -->
                <geom type="mesh" class="visual" pos="-9.72883e-17 0.0226 -0.01615" quat="0.5 0.5 0.5 -0.5" mesh="u" material="u_material"/>
                <geom class="collision" pos="-9.72883e-17 0.0215 -0.01615" quat="0.5 0.5 0.5 -0.5" type="box" size="0.01 0.015 0.001"/>
                <!-- Part u_8 -->
                <!-- Mesh u_8 -->
                <geom type="mesh" class="visual" pos="0 0.018 -0.01615" quat="0.707107 -0.707107 -0 -4.15692e-33" mesh="u" material="u_material"/>
                <geom class="collision" pos="1.29333e-35 0.0191 -0.01615" quat="0.707107 -0.707107 -0 -4.15692e-33" type="box" size="0.01 0.015 0.001"/>
                <!-- Link platesblock_4 -->
                <body name="platesblock_4" pos="-0.015 0.0406 -0.01615" quat="0.5 -0.5 0.5 -0.5">
                    <!-- Joint from doubleu_4 to platesblock_4 -->
                    <joint name="leg4_b" type="hinge"/>
                    <inertial pos="-0.0315 -5.43176e-16 0.0135372" mass="0.0417755" fullinertia="4.6241e-06 2.98279e-05 2.99828e-05 2.99773e-12 -6.49039e-20 5.54562e-21"/>
                    <!-- Part plate_7 -->
                    <!-- Mesh plate_7 -->
                    <geom type="mesh" class="visual" pos="0.006 -0.0143 0.0135" quat="3.33067e-16 2.1654e-15 -0.707107 -0.707107" mesh="plate" material="plate_material"/>
                    <geom class="collision" pos="-0.0315 -0.0131 0.0135" quat="3.33067e-16 2.1654e-15 -0.707107 -0.707107" type="box" size="0.0365 0.0075 0.001"/>
                    <!-- Part plate_8 -->
                    <!-- Mesh plate_8 -->
                    <geom type="mesh" class="visual" pos="0.006 0.012 0.0135" quat="9.4369e-16 1.33227e-15 -0.707107 -0.707107" mesh="plate" material="plate_material"/>
                    <geom class="collision" pos="-0.0315 0.0132 0.0135" quat="9.4369e-16 1.33227e-15 -0.707107 -0.707107" type="box" size="0.0365 0.0075 0.001"/>
                    <!-- Part horn_11 -->
                    <!-- Mesh horn_11 -->
                    <geom type="mesh" class="visual" pos="0 1.73472e-18 0.0135" quat="1 0 0 0" mesh="horn" material="horn_material"/>
                    <!-- Part motor_11 -->
                    <!-- Mesh motor_11 -->
                    <geom type="mesh" class="visual" pos="9.71445e-17 2.25514e-16 0.0135" quat="0.707107 1.27974e-15 1.66533e-15 -0.707107" mesh="motor" material="motor_material"/>
                    <geom class="collision" pos="-0.008 2.02199e-16 0.0135" quat="0.707107 1.27974e-15 1.66533e-15 -0.707107" type="box" size="0.01 0.015 0.011"/>
                    <!-- Part horn_12 -->
                    <!-- Mesh horn_12 -->
                    <geom type="mesh" class="visual" pos="-0.063 -1.31319e-15 0.0135" quat="0.608446 2.91552e-15 1.33227e-15 -0.793595" mesh="horn" material="horn_material"/>
                    <!-- Part motor_12 -->
                    <!-- Mesh motor_12 -->
                    <geom type="mesh" class="visual" pos="-0.063 -1.30278e-15 0.0135" quat="0.707107 7.49401e-16 -2.55351e-15 0.707107" mesh="motor" material="motor_material"/>
                    <geom class="collision" pos="-0.055 -1.27724e-15 0.0135" quat="0.707107 7.49401e-16 -2.55351e-15 0.707107" type="box" size="0.01 0.015 0.011"/>
                    <!-- Link leg_4 -->
                    <body name="leg_4" pos="-0.063 -1.22471e-15 -0.0015" quat="0.707107 3.10617e-15 8.88178e-16 -0.707107">
                        <!-- Joint from platesblock_4 to leg_4 -->
                        <joint name="leg4_c" type="hinge"/>
                        <inertial pos="-1.82494e-17 -0.0533786 0.015" mass="0.0154162" fullinertia="2.13816e-05 3.58407e-06 1.88204e-05 7.31818e-35 1.50662e-35 -7.25752e-36"/>
                        <!-- Part leg_4 -->
                        <!-- Mesh leg_4 -->
                        <geom type="mesh" class="visual" pos="0 0 0.015" quat="0.707107 -0.707107 0 1.33787e-30" mesh="leg" material="leg_material"/>
                        <geom class="collision" pos="1.51264e-31 -0.035 0.031" quat="0.707107 -0.707107 0 1.33787e-30" type="box" size="0.01 0.001 0.045"/>
                        <geom class="collision" pos="1.38642e-31 -0.035 -0.001" quat="0.707107 -0.707107 0 1.33787e-30" type="box" size="0.01 0.001 0.045"/>
                        <geom class="collision" pos="3.72737e-31 -0.09 0.015" quat="0.707107 -0.707107 0 1.33787e-30" type="sphere" size="0.015"/>
                    </body>
                </body>
            </body>
        </body>
    </worldbody>
    <asset>
        <mesh file="motor.stl"/>
        <mesh file="horn.stl"/>
        <mesh file="plate.stl"/>
        <mesh file="u.stl"/>
        <mesh file="body.stl"/>
        <mesh file="leg.stl"/>
        <material name="body_material" rgba="0.972549 0.529412 0.00392157 1"/>
        <material name="horn_material" rgba="0.917647 0.917647 0.917647 1"/>
        <material name="motor_material" rgba="0.470588 0.470588 0.470588 1"/>
        <material name="u_material" rgba="0.972549 0.529412 0.00392157 1"/>
        <material name="plate_material" rgba="0.972549 0.529412 0.00392157 1"/>
        <material name="leg_material" rgba="0.972549 0.529412 0.00392157 1"/>
    </asset>
    <actuator>
        <position class="quadruped_mujoco" name="leg1_c" joint="leg1_c" forcerange="-1 1" ctrlrange="-3 3"/>
        <position class="quadruped_mujoco" name="leg1_b" joint="leg1_b" forcerange="-1 1" ctrlrange="-3 3"/>
        <position class="quadruped_mujoco" name="leg1_a" joint="leg1_a" forcerange="-1 1" ctrlrange="-3 3"/>
        <position class="quadruped_mujoco" name="leg2_c" joint="leg2_c" forcerange="-1 1" ctrlrange="-3 3"/>
        <position class="quadruped_mujoco" name="leg2_b" joint="leg2_b" forcerange="-1 1" ctrlrange="-3 3"/>
        <position class="quadruped_mujoco" name="leg2_a" joint="leg2_a" forcerange="-1 1" ctrlrange="-3 3"/>
        <position class="quadruped_mujoco" name="leg3_c" joint="leg3_c" forcerange="-1 1" ctrlrange="-3 3"/>
        <position class="quadruped_mujoco" name="leg3_b" joint="leg3_b" forcerange="-1 1" ctrlrange="-3 3"/>
        <position class="quadruped_mujoco" name="leg3_a" joint="leg3_a" forcerange="-1 1" ctrlrange="-3 3"/>
        <position class="quadruped_mujoco" name="leg4_c" joint="leg4_c" forcerange="-1 1" ctrlrange="-3 3"/>
        <position class="quadruped_mujoco" name="leg4_b" joint="leg4_b" forcerange="-1 1" ctrlrange="-3 3"/>
        <position class="quadruped_mujoco" name="leg4_a" joint="leg4_a" forcerange="-1 1" ctrlrange="-3 3"/>
    </actuator>
    <equality/>
</mujoco>
