<robot name="onshape">
<link name="body_1">
<collision>
<origin xyz="0.0725 0.3217 0.0382" rpy="-1.5708 -1.5708 0" />
<geometry>
<mesh filename="package://mounting_cube_25_30.stl"/>
</geometry>
<material name="mounting_cube_25_30_material">
<color rgba="0.8 0.8 0.8 1.0"/>
</material>
</collision>
<collision>
<origin xyz="-0.0345 0.0283 0.0083" rpy="1.5708 1.5708 0" />
<geometry>
<mesh filename="package://mounting_cube_25_30.stl"/>
</geometry>
<material name="mounting_cube_25_30_material">
<color rgba="0.8 0.8 0.8 1.0"/>
</material>
</collision>
<collision>
<origin xyz="-0.028 0.3557 0.0234" rpy="1.5708 0.186913 -3.14159" />
<geometry>
<mesh filename="package://rx64-cap.stl"/>
</geometry>
<material name="rx64-cap_material">
<color rgba="0.8 0.776471 0.713725 1.0"/>
</material>
</collision>
<collision>
<origin xyz="0.0555 0.3457 0.0382" rpy="1.5708 -1.5708 0" />
<geometry>
<mesh filename="package://mounting_cube_25_30.stl"/>
</geometry>
<material name="mounting_cube_25_30_material">
<color rgba="0.8 0.8 0.8 1.0"/>
</material>
</collision>
<collision>
<origin xyz="-0.0125 0.0283 0.0083" rpy="1.5708 1.5708 0" />
<geometry>
<mesh filename="package://mounting_cube_25_30.stl"/>
</geometry>
<material name="mounting_cube_25_30_material">
<color rgba="0.8 0.8 0.8 1.0"/>
</material>
</collision>
<collision>
<origin xyz="-0.028 -0.00342 0.0231" rpy="-1.5708 -0.792005 3.14159" />
<geometry>
<mesh filename="package://hn05-i101.stl"/>
</geometry>
<material name="hn05-i101_material">
<color rgba="0.8 0.776471 0.713725 1.0"/>
</material>
</collision>
<collision>
<origin xyz="0.0725 0.0283 0.0086" rpy="1.5708 1.5708 0" />
<geometry>
<mesh filename="package://mounting_cube_25_30.stl"/>
</geometry>
<material name="mounting_cube_25_30_material">
<color rgba="0.8 0.8 0.8 1.0"/>
</material>
</collision>
<collision>
<origin xyz="-0.0295 0.0043 0.0083" rpy="-1.5708 1.5708 0" />
<geometry>
<mesh filename="package://mounting_cube_25_30.stl"/>
</geometry>
<material name="mounting_cube_25_30_material">
<color rgba="0.8 0.8 0.8 1.0"/>
</material>
</collision>
<collision>
<origin xyz="0.0555 0.3217 0.0432" rpy="-1.5708 1.5708 0" />
<geometry>
<mesh filename="package://mounting_cube_25_30.stl"/>
</geometry>
<material name="mounting_cube_25_30_material">
<color rgba="0.8 0.8 0.8 1.0"/>
</material>
</collision>
<collision>
<origin xyz="-0.0295 0.3217 0.0086" rpy="-1.5708 1.5708 0" />
<geometry>
<mesh filename="package://mounting_cube_25_30.stl"/>
</geometry>
<material name="mounting_cube_25_30_material">
<color rgba="0.8 0.8 0.8 1.0"/>
</material>
</collision>
<collision>
<origin xyz="-0.028 0.35698 0.0234" rpy="-1.5708 0.186913 -3.14159" />
<geometry>
<mesh filename="package://mf128zz.stl"/>
</geometry>
<material name="mf128zz_material">
<color rgba="0.8 0.776471 0.713725 1.0"/>
</material>
</collision>
<collision>
<origin xyz="0.0555 0.0043 0.0086" rpy="-1.5708 1.5708 0" />
<geometry>
<mesh filename="package://mounting_cube_25_30.stl"/>
</geometry>
<material name="mounting_cube_25_30_material">
<color rgba="0.8 0.8 0.8 1.0"/>
</material>
</collision>
<collision>
<origin xyz="0.071 -0.0057 0.0234" rpy="1.5708 0.186913 -1.15194e-12" />
<geometry>
<mesh filename="package://rx64-cap.stl"/>
</geometry>
<material name="rx64-cap_material">
<color rgba="0.8 0.776471 0.713725 1.0"/>
</material>
</collision>
<collision>
<origin xyz="0.071 0.3337 0.0234" rpy="1.5708 1.5708 0" />
<geometry>
<mesh filename="package://mx64.stl"/>
</geometry>
<material name="mx64_material">
<color rgba="0.211765 0.211765 0.211765 1.0"/>
</material>
</collision>
<collision>
<origin xyz="-0.0125 0.3457 0.0086" rpy="1.5708 1.5708 0" />
<geometry>
<mesh filename="package://mounting_cube_25_30.stl"/>
</geometry>
<material name="mounting_cube_25_30_material">
<color rgba="0.8 0.8 0.8 1.0"/>
</material>
</collision>
<collision>
<origin xyz="-0.0125 0.3217 0.0036" rpy="-1.5708 -1.5708 0" />
<geometry>
<mesh filename="package://mounting_cube_25_30.stl"/>
</geometry>
<material name="mounting_cube_25_30_material">
<color rgba="0.8 0.8 0.8 1.0"/>
</material>
</collision>
<collision>
<origin xyz="3.38883e-15 -1.14492e-14 0.0432" rpy="4.7653e-15 -2.96645e-15 -3.3045e-13" />
<geometry>
<mesh filename="package://body_back.stl"/>
</geometry>
<material name="body_back_material">
<color rgba="0.447059 0.243137 0 1.0"/>
</material>
</collision>
<collision>
<origin xyz="0.0555 0.0283 0.0036" rpy="1.5708 -1.5708 0" />
<geometry>
<mesh filename="package://mounting_cube_25_30.stl"/>
</geometry>
<material name="mounting_cube_25_30_material">
<color rgba="0.8 0.8 0.8 1.0"/>
</material>
</collision>
<collision>
<origin xyz="0.0505 0.0043 0.0382" rpy="-1.5708 -1.5708 0" />
<geometry>
<mesh filename="package://mounting_cube_25_30.stl"/>
</geometry>
<material name="mounting_cube_25_30_material">
<color rgba="0.8 0.8 0.8 1.0"/>
</material>
</collision>
<collision>
<origin xyz="0.071 0.3557 0.0234" rpy="1.5708 -0.391796 3.14159" />
<geometry>
<mesh filename="package://rx64-cap.stl"/>
</geometry>
<material name="rx64-cap_material">
<color rgba="0.8 0.776471 0.713725 1.0"/>
</material>
</collision>
<collision>
<origin xyz="-0.0075 0.3457 0.0382" rpy="1.5708 -1.5708 0" />
<geometry>
<mesh filename="package://mounting_cube_25_30.stl"/>
</geometry>
<material name="mounting_cube_25_30_material">
<color rgba="0.8 0.8 0.8 1.0"/>
</material>
</collision>
<collision>
<origin xyz="0.0775 0.3217 0.0086" rpy="-1.5708 1.5708 0" />
<geometry>
<mesh filename="package://mounting_cube_25_30.stl"/>
</geometry>
<material name="mounting_cube_25_30_material">
<color rgba="0.8 0.8 0.8 1.0"/>
</material>
</collision>
<collision>
<origin xyz="0 0 0" rpy="0 -0 0" />
<geometry>
<mesh filename="package://body_plate.stl"/>
</geometry>
<material name="body_plate_material">
<color rgba="0.447059 0.243137 0 1.0"/>
</material>
</collision>
<collision>
<origin xyz="0.071 0.35342 0.0234" rpy="-1.5708 -0.792005 -2.28207e-12" />
<geometry>
<mesh filename="package://hn05-i101.stl"/>
</geometry>
<material name="hn05-i101_material">
<color rgba="0.8 0.776471 0.713725 1.0"/>
</material>
</collision>
<collision>
<origin xyz="0.071 -0.00342 0.0234" rpy="-1.5708 -1.37072 3.14159" />
<geometry>
<mesh filename="package://hn05-i101.stl"/>
</geometry>
<material name="hn05-i101_material">
<color rgba="0.8 0.776471 0.713725 1.0"/>
</material>
</collision>
<collision>
<origin xyz="2.50494e-15 -1.02314e-14 0.0432" rpy="-2.49278e-15 -2.96645e-15 -3.3045e-13" />
<geometry>
<mesh filename="package://body_plate.stl"/>
</geometry>
<material name="body_plate_material">
<color rgba="0.447059 0.243137 0 1.0"/>
</material>
</collision>
<collision>
<origin xyz="0.0775 0.3457 0.0382" rpy="1.5708 -1.5708 0" />
<geometry>
<mesh filename="package://mounting_cube_25_30.stl"/>
</geometry>
<material name="mounting_cube_25_30_material">
<color rgba="0.8 0.8 0.8 1.0"/>
</material>
</collision>
<collision>
<origin xyz="-0.028 -0.00698 0.0231" rpy="1.5708 0.391796 3.14159" />
<geometry>
<mesh filename="package://mf128zz.stl"/>
</geometry>
<material name="mf128zz_material">
<color rgba="0.8 0.776471 0.713725 1.0"/>
</material>
</collision>
<collision>
<origin xyz="0.0775 0.0283 0.0382" rpy="1.5708 -1.5708 0" />
<geometry>
<mesh filename="package://mounting_cube_25_30.stl"/>
</geometry>
<material name="mounting_cube_25_30_material">
<color rgba="0.8 0.8 0.8 1.0"/>
</material>
</collision>
<collision>
<origin xyz="0.0555 0.0283 0.0382" rpy="1.5708 -1.5708 0" />
<geometry>
<mesh filename="package://mounting_cube_25_30.stl"/>
</geometry>
<material name="mounting_cube_25_30_material">
<color rgba="0.8 0.8 0.8 1.0"/>
</material>
</collision>
<collision>
<origin xyz="-0.0125 0.3217 0.0382" rpy="-1.5708 -1.5708 0" />
<geometry>
<mesh filename="package://mounting_cube_25_30.stl"/>
</geometry>
<material name="mounting_cube_25_30_material">
<color rgba="0.8 0.8 0.8 1.0"/>
</material>
</collision>
<collision>
<origin xyz="0.0725 0.3457 0.0086" rpy="1.5708 1.5708 0" />
<geometry>
<mesh filename="package://mounting_cube_25_30.stl"/>
</geometry>
<material name="mounting_cube_25_30_material">
<color rgba="0.8 0.8 0.8 1.0"/>
</material>
</collision>
<collision>
<origin xyz="-0.0345 0.3217 0.0382" rpy="-1.5708 -1.5708 0" />
<geometry>
<mesh filename="package://mounting_cube_25_30.stl"/>
</geometry>
<material name="mounting_cube_25_30_material">
<color rgba="0.8 0.8 0.8 1.0"/>
</material>
</collision>
<collision>
<origin xyz="-0.028 0.0163 0.0231" rpy="-1.5708 1.5708 0" />
<geometry>
<mesh filename="package://mx64.stl"/>
</geometry>
<material name="mx64_material">
<color rgba="0.211765 0.211765 0.211765 1.0"/>
</material>
</collision>
<collision>
<origin xyz="0.071 0.0163 0.0234" rpy="-1.5708 -1.5708 0" />
<geometry>
<mesh filename="package://mx64.stl"/>
</geometry>
<material name="mx64_material">
<color rgba="0.211765 0.211765 0.211765 1.0"/>
</material>
</collision>
<collision>
<origin xyz="-0.0295 0.3457 0.0382" rpy="1.5708 -1.5708 0" />
<geometry>
<mesh filename="package://mounting_cube_25_30.stl"/>
</geometry>
<material name="mounting_cube_25_30_material">
<color rgba="0.8 0.8 0.8 1.0"/>
</material>
</collision>
<collision>
<origin xyz="0.0725 0.0043 0.0382" rpy="-1.5708 -1.5708 0" />
<geometry>
<mesh filename="package://mounting_cube_25_30.stl"/>
</geometry>
<material name="mounting_cube_25_30_material">
<color rgba="0.8 0.8 0.8 1.0"/>
</material>
</collision>
<collision>
<origin xyz="-0.028 0.35342 0.0234" rpy="-1.5708 -1.37072 2.188e-12" />
<geometry>
<mesh filename="package://hn05-i101.stl"/>
</geometry>
<material name="hn05-i101_material">
<color rgba="0.8 0.776471 0.713725 1.0"/>
</material>
</collision>
<collision>
<origin xyz="0.071 -0.00698 0.0234" rpy="-1.5708 0.186913 -1.15279e-12" />
<geometry>
<mesh filename="package://mf128zz.stl"/>
</geometry>
<material name="mf128zz_material">
<color rgba="0.8 0.776471 0.713725 1.0"/>
</material>
</collision>
<collision>
<origin xyz="-0.0075 0.0043 0.0083" rpy="-1.5708 1.5708 0" />
<geometry>
<mesh filename="package://mounting_cube_25_30.stl"/>
</geometry>
<material name="mounting_cube_25_30_material">
<color rgba="0.8 0.8 0.8 1.0"/>
</material>
</collision>
<collision>
<origin xyz="-0.0345 0.0043 0.0379" rpy="-1.5708 -1.5708 0" />
<geometry>
<mesh filename="package://mounting_cube_25_30.stl"/>
</geometry>
<material name="mounting_cube_25_30_material">
<color rgba="0.8 0.8 0.8 1.0"/>
</material>
</collision>
<collision>
<origin xyz="-0.028 -0.0057 0.0231" rpy="1.5708 -0.391796 -7.85824e-13" />
<geometry>
<mesh filename="package://rx64-cap.stl"/>
</geometry>
<material name="rx64-cap_material">
<color rgba="0.8 0.776471 0.713725 1.0"/>
</material>
</collision>
<collision>
<origin xyz="-0.028 0.3337 0.0234" rpy="1.5708 -1.5708 0" />
<geometry>
<mesh filename="package://mx64.stl"/>
</geometry>
<material name="mx64_material">
<color rgba="0.211765 0.211765 0.211765 1.0"/>
</material>
</collision>
<collision>
<origin xyz="-0.0125 0.0283 0.0429" rpy="1.5708 1.5708 0" />
<geometry>
<mesh filename="package://mounting_cube_25_30.stl"/>
</geometry>
<material name="mounting_cube_25_30_material">
<color rgba="0.8 0.8 0.8 1.0"/>
</material>
</collision>
<collision>
<origin xyz="0.071 0.35698 0.0234" rpy="1.5708 0.391796 -2.28238e-12" />
<geometry>
<mesh filename="package://mf128zz.stl"/>
</geometry>
<material name="mf128zz_material">
<color rgba="0.8 0.776471 0.713725 1.0"/>
</material>
</collision>
<collision>
<origin xyz="-0.0125 0.0043 0.0379" rpy="-1.5708 -1.5708 0" />
<geometry>
<mesh filename="package://mounting_cube_25_30.stl"/>
</geometry>
<material name="mounting_cube_25_30_material">
<color rgba="0.8 0.8 0.8 1.0"/>
</material>
</collision>
<collision>
<origin xyz="0.0775 0.0043 0.0086" rpy="-1.5708 1.5708 0" />
<geometry>
<mesh filename="package://mounting_cube_25_30.stl"/>
</geometry>
<material name="mounting_cube_25_30_material">
<color rgba="0.8 0.8 0.8 1.0"/>
</material>
</collision>
<collision>
<origin xyz="0.0555 0.3217 0.0086" rpy="-1.5708 1.5708 0" />
<geometry>
<mesh filename="package://mounting_cube_25_30.stl"/>
</geometry>
<material name="mounting_cube_25_30_material">
<color rgba="0.8 0.8 0.8 1.0"/>
</material>
</collision>
<collision>
<origin xyz="-0.0345 0.3457 0.0086" rpy="1.5708 1.5708 0" />
<geometry>
<mesh filename="package://mounting_cube_25_30.stl"/>
</geometry>
<material name="mounting_cube_25_30_material">
<color rgba="0.8 0.8 0.8 1.0"/>
</material>
</collision>
<collision>
<origin xyz="-0.0295 0.0283 0.0379" rpy="1.5708 -1.5708 0" />
<geometry>
<mesh filename="package://mounting_cube_25_30.stl"/>
</geometry>
<material name="mounting_cube_25_30_material">
<color rgba="0.8 0.8 0.8 1.0"/>
</material>
</collision>
<collision>
<origin xyz="0.0505 0.3457 0.0086" rpy="1.5708 1.5708 0" />
<geometry>
<mesh filename="package://mounting_cube_25_30.stl"/>
</geometry>
<material name="mounting_cube_25_30_material">
<color rgba="0.8 0.8 0.8 1.0"/>
</material>
</collision>
<collision>
<origin xyz="6.04705e-14 0.1722 0.0432" rpy="4.7653e-15 -2.96645e-15 -3.3018e-13" />
<geometry>
<mesh filename="package://body_back.stl"/>
</geometry>
<material name="body_back_material">
<color rgba="0.447059 0.243137 0 1.0"/>
</material>
</collision>
<collision>
<origin xyz="4.14433e-14 0.1148 0.0432" rpy="4.7653e-15 -2.96645e-15 -3.3018e-13" />
<geometry>
<mesh filename="package://body_back.stl"/>
</geometry>
<material name="body_back_material">
<color rgba="0.447059 0.243137 0 1.0"/>
</material>
</collision>
<collision>
<origin xyz="2.2416e-14 0.0574 0.0432" rpy="4.7653e-15 -2.96645e-15 -3.3018e-13" />
<geometry>
<mesh filename="package://body_back.stl"/>
</geometry>
<material name="body_back_material">
<color rgba="0.447059 0.243137 0 1.0"/>
</material>
</collision>
<visual>
<origin xyz="0 0 0" rpy="0 -0 0" />
<geometry>
<mesh filename="package://body_1.stl"/>
</geometry>
<material name="body_1_material">
<color rgba="0.378896 0.30823 0.221127 1.0"/>
</material>
</visual>
<inertial>
<origin xyz="0.0214807 0.174889 0.0251766" rpy="0 0 0"/>
<mass value="0.59334" />
<inertia ixx="0.0122979" ixy="-7.82226e-07"  ixz="-6.09619e-07" iyy="0.00108576" iyz="-1.91683e-06" izz="0.012932" />
</inertial>
</link>

<link name="leg_top_1">
<collision>
<origin xyz="0.0123 -0.0783608 0.0083" rpy="-3.14159 1.5708 0" />
<geometry>
<mesh filename="package://mounting_cube_25_30.stl"/>
</geometry>
<material name="mounting_cube_25_30_material">
<color rgba="0.8 0.8 0.8 1.0"/>
</material>
</collision>
<collision>
<origin xyz="-0.0117 -0.0833608 0.0083" rpy="7.90201e-13 1.5708 0" />
<geometry>
<mesh filename="package://mounting_cube_25_30.stl"/>
</geometry>
<material name="mounting_cube_25_30_material">
<color rgba="0.8 0.8 0.8 1.0"/>
</material>
</collision>
<collision>
<origin xyz="-0.0117 -0.0613608 0.0083" rpy="7.90368e-13 1.5708 0" />
<geometry>
<mesh filename="package://mounting_cube_25_30.stl"/>
</geometry>
<material name="mounting_cube_25_30_material">
<color rgba="0.8 0.8 0.8 1.0"/>
</material>
</collision>
<collision>
<origin xyz="0.0166 -0.0858608 -1.38778e-17" rpy="-5.20417e-18 -8.32667e-17 1.5708" />
<geometry>
<mesh filename="package://spacing_plate.stl"/>
</geometry>
<material name="spacing_plate_material">
<color rgba="0.447059 0.243137 0 1.0"/>
</material>
</collision>
<collision>
<origin xyz="-0.016 -0.0858608 0.04972" rpy="-3.14159 -7.91134e-17 1.5708" />
<geometry>
<mesh filename="package://spacing_plate_extension.stl"/>
</geometry>
<material name="spacing_plate_extension_material">
<color rgba="0.972549 0.529412 0.00392157 1.0"/>
</material>
</collision>
<collision>
<origin xyz="0.0123 -0.0833608 0.0379" rpy="-7.90368e-13 -1.5708 0" />
<geometry>
<mesh filename="package://mounting_cube_25_30.stl"/>
</geometry>
<material name="mounting_cube_25_30_material">
<color rgba="0.8 0.8 0.8 1.0"/>
</material>
</collision>
<collision>
<origin xyz="-0.0117 -0.0613608 0.0429" rpy="7.90368e-13 1.5708 0" />
<geometry>
<mesh filename="package://mounting_cube_25_30.stl"/>
</geometry>
<material name="mounting_cube_25_30_material">
<color rgba="0.8 0.8 0.8 1.0"/>
</material>
</collision>
<collision>
<origin xyz="0.0123 -0.0613608 0.0379" rpy="-7.90368e-13 -1.5708 0" />
<geometry>
<mesh filename="package://mounting_cube_25_30.stl"/>
</geometry>
<material name="mounting_cube_25_30_material">
<color rgba="0.8 0.8 0.8 1.0"/>
</material>
</collision>
<collision>
<origin xyz="0.02358 -0.0768608 0.0231" rpy="1.5708 1.55849 -1.5708" />
<geometry>
<mesh filename="package://mf128zz.stl"/>
</geometry>
<material name="mf128zz_material">
<color rgba="0.8 0.776471 0.713725 1.0"/>
</material>
</collision>
<collision>
<origin xyz="-0.016 -0.016 0.04672" rpy="8.26366e-17 3.35833e-16 -8.22342e-13" />
<geometry>
<mesh filename="package://leg_top_plate.stl"/>
</geometry>
<material name="leg_top_plate_material">
<color rgba="0.447059 0.243137 0 1.0"/>
</material>
</collision>
<collision>
<origin xyz="-0.016 -0.016 -0.003" rpy="2.74323e-33 -4.73635e-29 4.09715e-29" />
<geometry>
<mesh filename="package://leg_top_plate.stl"/>
</geometry>
<material name="leg_top_plate_material">
<color rgba="0.447059 0.243137 0 1.0"/>
</material>
</collision>
<collision>
<origin xyz="-0.0117 -0.0783608 0.0379" rpy="3.14159 -1.5708 0" />
<geometry>
<mesh filename="package://mounting_cube_25_30.stl"/>
</geometry>
<material name="mounting_cube_25_30_material">
<color rgba="0.8 0.8 0.8 1.0"/>
</material>
</collision>
<collision>
<origin xyz="0.0003 -0.0768608 0.0231" rpy="-3.14159 1.5708 0" />
<geometry>
<mesh filename="package://mx64.stl"/>
</geometry>
<material name="mx64_material">
<color rgba="0.211765 0.211765 0.211765 1.0"/>
</material>
</collision>
<collision>
<origin xyz="0.0166 -0.0538608 0.0459" rpy="3.14159 1.57726e-16 -1.5708" />
<geometry>
<mesh filename="package://spacing_plate.stl"/>
</geometry>
<material name="spacing_plate_material">
<color rgba="0.447059 0.243137 0 1.0"/>
</material>
</collision>
<collision>
<origin xyz="0.0123 -0.0563608 0.0083" rpy="-3.14159 1.5708 0" />
<geometry>
<mesh filename="package://mounting_cube_25_30.stl"/>
</geometry>
<material name="mounting_cube_25_30_material">
<color rgba="0.8 0.8 0.8 1.0"/>
</material>
</collision>
<collision>
<origin xyz="0.02002 -0.0768608 0.0231" rpy="-1.5708 0.0565903 -1.5708" />
<geometry>
<mesh filename="package://hn05-i101.stl"/>
</geometry>
<material name="hn05-i101_material">
<color rgba="0.8 0.776471 0.713725 1.0"/>
</material>
</collision>
<collision>
<origin xyz="0.0223 -0.0768608 0.0231" rpy="-1.5708 -1.10558 -1.5708" />
<geometry>
<mesh filename="package://rx64-cap.stl"/>
</geometry>
<material name="rx64-cap_material">
<color rgba="0.8 0.776471 0.713725 1.0"/>
</material>
</collision>
<visual>
<origin xyz="0 0 0" rpy="0 -0 0" />
<geometry>
<mesh filename="package://leg_top_1.stl"/>
</geometry>
<material name="leg_top_1_material">
<color rgba="0.363504 0.328376 0.28287 1.0"/>
</material>
</visual>
<inertial>
<origin xyz="0.00232729 -0.0615551 0.0232841" rpy="0 0 0"/>
<mass value="0.115968" />
<inertia ixx="6.31714e-05" ixy="3.21149e-06"  ixz="4.3256e-08" iyy="3.98532e-05" iyz="6.73737e-08" izz="6.27571e-05" />
</inertial>
</link>

<link name="leg_middle_1">
<collision>
<origin xyz="0.049 0.0125 0.034" rpy="3.14159 -5.38458e-15 -3.14159" />
<geometry>
<mesh filename="package://leg_spacer_mid.stl"/>
</geometry>
<material name="leg_spacer_mid_material">
<color rgba="0.647059 0.647059 0.647059 1.0"/>
</material>
</collision>
<collision>
<origin xyz="-0.016 -0.0175 -0.05002" rpy="-2.33147e-15 3.88578e-16 6.82787e-15" />
<geometry>
<mesh filename="package://leg_middle_plate.stl"/>
</geometry>
<material name="leg_middle_plate_material">
<color rgba="0.447059 0.243137 0 1.0"/>
</material>
</collision>
<collision>
<origin xyz="0.029 -0.0125 0.034" rpy="3.14159 -5.38458e-15 -3.14159" />
<geometry>
<mesh filename="package://leg_spacer_mid.stl"/>
</geometry>
<material name="leg_spacer_mid_material">
<color rgba="0.647059 0.647059 0.647059 1.0"/>
</material>
</collision>
<collision>
<origin xyz="-0.016 -0.0175 0" rpy="3.8118e-29 1.77494e-30 8.71196e-41" />
<geometry>
<mesh filename="package://leg_middle_plate.stl"/>
</geometry>
<material name="leg_middle_plate_material">
<color rgba="0.447059 0.243137 0 1.0"/>
</material>
</collision>
<visual>
<origin xyz="0 0 0" rpy="0 -0 0" />
<geometry>
<mesh filename="package://leg_middle_1.stl"/>
</geometry>
<material name="leg_middle_1_material">
<color rgba="0.546901 0.444779 0.323018 1.0"/>
</material>
</visual>
<inertial>
<origin xyz="0.039 -8.18728e-17 -0.023505" rpy="0 0 0"/>
<mass value="0.0282748" />
<inertia ixx="1.51213e-05" ixy="-1.76438e-06"  ixz="-2.23301e-19" iyy="2.51079e-05" iyz="-7.0913e-20" izz="1.72974e-05" />
</inertial>
</link>

<link name="leg_tip_1">
<collision>
<origin xyz="-6.93889e-18 0 -0.04322" rpy="3.14159 -4.39671e-16 -0.386994" />
<geometry>
<mesh filename="package://hn05-i101.stl"/>
</geometry>
<material name="hn05-i101_material">
<color rgba="0.8 0.776471 0.713725 1.0"/>
</material>
</collision>
<collision>
<origin xyz="-4.02456e-16 2.77556e-16 -0.0605" rpy="-2.77556e-16 3.55271e-15 6.05072e-15" />
<geometry>
<mesh filename="package://leg_tip_plate.stl"/>
</geometry>
<material name="leg_tip_plate_material">
<color rgba="0.447059 0.243137 0 1.0"/>
</material>
</collision>
<collision>
<origin xyz="-0.013943 -0.11505 -0.0405" rpy="-1.2611e-15 -5.16254e-15 1.5708" />
<geometry>
<mesh filename="package://leg_spacer.stl"/>
</geometry>
<material name="leg_spacer_material">
<color rgba="0.701961 0.701961 0.701961 1.0"/>
</material>
</collision>
<collision>
<origin xyz="-6.93889e-18 -2.77556e-17 -0.04678" rpy="-1.55297e-15 -5.16254e-15 1.5708" />
<geometry>
<mesh filename="package://mf128zz.stl"/>
</geometry>
<material name="mf128zz_material">
<color rgba="0.8 0.776471 0.713725 1.0"/>
</material>
</collision>
<collision>
<origin xyz="0.013943 -0.11505 -0.0405" rpy="-1.2611e-15 -5.16254e-15 1.5708" />
<geometry>
<mesh filename="package://leg_spacer.stl"/>
</geometry>
<material name="leg_spacer_material">
<color rgba="0.701961 0.701961 0.701961 1.0"/>
</material>
</collision>
<collision>
<origin xyz="2.15106e-16 -0.1392 -0.0065" rpy="3.14159 -5.60663e-15 1.5708" />
<geometry>
<mesh filename="package://leg_spacer.stl"/>
</geometry>
<material name="leg_spacer_material">
<color rgba="0.701961 0.701961 0.701961 1.0"/>
</material>
</collision>
<collision>
<origin xyz="0.0161 -0.0831 -0.0405" rpy="-1.2611e-15 -5.16254e-15 1.5708" />
<geometry>
<mesh filename="package://leg_spacer.stl"/>
</geometry>
<material name="leg_spacer_material">
<color rgba="0.701961 0.701961 0.701961 1.0"/>
</material>
</collision>
<collision>
<origin xyz="3.05311e-16 -4.71845e-16 -0.0235" rpy="5.77316e-15 1.94289e-15 3.05311e-15" />
<geometry>
<mesh filename="package://leg_tip_plate.stl"/>
</geometry>
<material name="leg_tip_plate_material">
<color rgba="0.447059 0.243137 0 1.0"/>
</material>
</collision>
<collision>
<origin xyz="-0.0161 -0.0831 -0.0405" rpy="3.03017e-15 2.65926e-15 -0.497652" />
<geometry>
<mesh filename="package://leg_spacer.stl"/>
</geometry>
<material name="leg_spacer_material">
<color rgba="0.701961 0.701961 0.701961 1.0"/>
</material>
</collision>
<collision>
<origin xyz="-1.38778e-17 0 -0.0455" rpy="3.14159 -4.88498e-15 1.5708" />
<geometry>
<mesh filename="package://rx64-cap.stl"/>
</geometry>
<material name="rx64-cap_material">
<color rgba="0.8 0.776471 0.713725 1.0"/>
</material>
</collision>
<collision>
<origin xyz="0 2.77556e-17 -0.0235" rpy="-6.90253e-31 1.42735e-29 3.45127e-31" />
<geometry>
<mesh filename="package://mx64.stl"/>
</geometry>
<material name="mx64_material">
<color rgba="0.211765 0.211765 0.211765 1.0"/>
</material>
</collision>
<visual>
<origin xyz="0 0 0" rpy="0 -0 0" />
<geometry>
<mesh filename="package://leg_tip_1.stl"/>
</geometry>
<material name="leg_tip_1_material">
<color rgba="0.39292 0.363337 0.324854 1.0"/>
</material>
</visual>
<inertial>
<origin xyz="-7.07825e-10 -0.0411183 -0.0252857" rpy="0 0 0"/>
<mass value="0.131575" />
<inertia ixx="0.000294116" ixy="3.09705e-12"  ixz="1.80567e-12" iyy="3.97285e-05" iyz="9.25707e-06" izz="0.00028263" />
</inertial>
</link>

<joint name="fl_3" type="revolute">
<origin xyz="0.078 2.08167e-17 -6.93889e-18" rpy="3.33067e-16 6.38378e-16 1.5708" />
<parent link="leg_middle_1" />
<child link="leg_tip_1" />
<axis xyz="0 0 1"/>
<limit effort="1" velocity="20" />
<joint_properties friction="0.0"/>
</joint>

<joint name="fl_2" type="revolute">
<origin xyz="-0.0232 -0.0768608 0.0231" rpy="1.5708 5.34711e-16 -1.5708" />
<parent link="leg_top_1" />
<child link="leg_middle_1" />
<axis xyz="0 0 -1"/>
<limit effort="1" velocity="20" />
<joint_properties friction="0.0"/>
</joint>

<joint name="fl_1" type="revolute">
<origin xyz="0.071 0.0398 0.0234" rpy="1.5708 -8.2534e-13 -3.31211e-13" />
<parent link="body_1" />
<child link="leg_top_1" />
<axis xyz="0 0 1"/>
<limit effort="1" velocity="20" />
<joint_properties friction="0.0"/>
</joint>

<link name="leg_top_2">
<collision>
<origin xyz="0.0123 -0.0563608 -0.03842" rpy="3.14159 1.5708 0" />
<geometry>
<mesh filename="package://mounting_cube_25_30.stl"/>
</geometry>
<material name="mounting_cube_25_30_material">
<color rgba="0.8 0.8 0.8 1.0"/>
</material>
</collision>
<collision>
<origin xyz="0.0123 -0.0833608 -0.00882" rpy="8.88178e-16 -1.5708 0" />
<geometry>
<mesh filename="package://mounting_cube_25_30.stl"/>
</geometry>
<material name="mounting_cube_25_30_material">
<color rgba="0.8 0.8 0.8 1.0"/>
</material>
</collision>
<collision>
<origin xyz="0.02358 -0.0768608 -0.02362" rpy="-1.5708 -1.55849 1.5708" />
<geometry>
<mesh filename="package://mf128zz.stl"/>
</geometry>
<material name="mf128zz_material">
<color rgba="0.8 0.776471 0.713725 1.0"/>
</material>
</collision>
<collision>
<origin xyz="-0.016 -0.0858608 0.003" rpy="-3.14159 1.0247e-16 1.5708" />
<geometry>
<mesh filename="package://spacing_plate_extension.stl"/>
</geometry>
<material name="spacing_plate_extension_material">
<color rgba="0.972549 0.529412 0.00392157 1.0"/>
</material>
</collision>
<collision>
<origin xyz="0.0223 -0.0768608 -0.02362" rpy="1.5708 1.10558 1.5708" />
<geometry>
<mesh filename="package://rx64-cap.stl"/>
</geometry>
<material name="rx64-cap_material">
<color rgba="0.8 0.776471 0.713725 1.0"/>
</material>
</collision>
<collision>
<origin xyz="-0.016 -0.016 -0.04972" rpy="-4.93823e-15 1.05173e-15 7.93407e-13" />
<geometry>
<mesh filename="package://leg_top_plate.stl"/>
</geometry>
<material name="leg_top_plate_material">
<color rgba="0.447059 0.243137 0 1.0"/>
</material>
</collision>
<collision>
<origin xyz="-0.016 -0.016 0" rpy="-7.13961e-45 -1.0602e-40 -2.5118e-29" />
<geometry>
<mesh filename="package://leg_top_plate.stl"/>
</geometry>
<material name="leg_top_plate_material">
<color rgba="0.447059 0.243137 0 1.0"/>
</material>
</collision>
<collision>
<origin xyz="0.0003 -0.0768608 -0.02362" rpy="3.14159 1.5708 0" />
<geometry>
<mesh filename="package://mx64.stl"/>
</geometry>
<material name="mx64_material">
<color rgba="0.211765 0.211765 0.211765 1.0"/>
</material>
</collision>
<collision>
<origin xyz="-0.0117 -0.0613608 -0.00382" rpy="-7.49401e-16 1.5708 0" />
<geometry>
<mesh filename="package://mounting_cube_25_30.stl"/>
</geometry>
<material name="mounting_cube_25_30_material">
<color rgba="0.8 0.8 0.8 1.0"/>
</material>
</collision>
<collision>
<origin xyz="0.0166 -0.0538608 -0.00082" rpy="3.14159 -3.7651e-16 -1.5708" />
<geometry>
<mesh filename="package://spacing_plate.stl"/>
</geometry>
<material name="spacing_plate_material">
<color rgba="0.447059 0.243137 0 1.0"/>
</material>
</collision>
<collision>
<origin xyz="0.02002 -0.0768608 -0.02362" rpy="1.5708 -0.0565903 1.5708" />
<geometry>
<mesh filename="package://hn05-i101.stl"/>
</geometry>
<material name="hn05-i101_material">
<color rgba="0.8 0.776471 0.713725 1.0"/>
</material>
</collision>
<collision>
<origin xyz="-0.0117 -0.0613608 -0.03842" rpy="-6.80012e-16 1.5708 0" />
<geometry>
<mesh filename="package://mounting_cube_25_30.stl"/>
</geometry>
<material name="mounting_cube_25_30_material">
<color rgba="0.8 0.8 0.8 1.0"/>
</material>
</collision>
<collision>
<origin xyz="-0.0117 -0.0833608 -0.03842" rpy="-5.55112e-16 1.5708 0" />
<geometry>
<mesh filename="package://mounting_cube_25_30.stl"/>
</geometry>
<material name="mounting_cube_25_30_material">
<color rgba="0.8 0.8 0.8 1.0"/>
</material>
</collision>
<collision>
<origin xyz="0.0123 -0.0613608 -0.00882" rpy="8.88178e-16 -1.5708 0" />
<geometry>
<mesh filename="package://mounting_cube_25_30.stl"/>
</geometry>
<material name="mounting_cube_25_30_material">
<color rgba="0.8 0.8 0.8 1.0"/>
</material>
</collision>
<collision>
<origin xyz="-0.0117 -0.0783608 -0.00882" rpy="-3.14159 -1.5708 0" />
<geometry>
<mesh filename="package://mounting_cube_25_30.stl"/>
</geometry>
<material name="mounting_cube_25_30_material">
<color rgba="0.8 0.8 0.8 1.0"/>
</material>
</collision>
<collision>
<origin xyz="0.0166 -0.0858608 -0.04672" rpy="8.26543e-16 2.32632e-15 1.5708" />
<geometry>
<mesh filename="package://spacing_plate.stl"/>
</geometry>
<material name="spacing_plate_material">
<color rgba="0.447059 0.243137 0 1.0"/>
</material>
</collision>
<collision>
<origin xyz="0.0123 -0.0783608 -0.03842" rpy="3.14159 1.5708 0" />
<geometry>
<mesh filename="package://mounting_cube_25_30.stl"/>
</geometry>
<material name="mounting_cube_25_30_material">
<color rgba="0.8 0.8 0.8 1.0"/>
</material>
</collision>
<visual>
<origin xyz="0 0 0" rpy="0 -0 0" />
<geometry>
<mesh filename="package://leg_top_2.stl"/>
</geometry>
<material name="leg_top_2_material">
<color rgba="0.363504 0.328376 0.28287 1.0"/>
</material>
</visual>
<inertial>
<origin xyz="0.00232729 -0.0615551 -0.0234359" rpy="0 0 0"/>
<mass value="0.115968" />
<inertia ixx="6.31714e-05" ixy="3.21149e-06"  ixz="4.3256e-08" iyy="3.98532e-05" iyz="6.73737e-08" izz="6.27571e-05" />
</inertial>
</link>

<link name="leg_middle_2">
<collision>
<origin xyz="-0.016 -0.0175 -0.05002" rpy="1.3739e-15 2.33841e-15 7.92422e-15" />
<geometry>
<mesh filename="package://leg_middle_plate.stl"/>
</geometry>
<material name="leg_middle_plate_material">
<color rgba="0.447059 0.243137 0 1.0"/>
</material>
</collision>
<collision>
<origin xyz="-0.016 -0.0175 -8.67362e-19" rpy="1.08474e-29 2.95092e-29 3.60534e-31" />
<geometry>
<mesh filename="package://leg_middle_plate.stl"/>
</geometry>
<material name="leg_middle_plate_material">
<color rgba="0.447059 0.243137 0 1.0"/>
</material>
</collision>
<collision>
<origin xyz="0.049 0.0125 0.034" rpy="3.14159 2.57037e-15 -1.28928" />
<geometry>
<mesh filename="package://leg_spacer_mid.stl"/>
</geometry>
<material name="leg_spacer_mid_material">
<color rgba="0.647059 0.647059 0.647059 1.0"/>
</material>
</collision>
<collision>
<origin xyz="0.029 -0.0125 0.034" rpy="3.14159 2.57037e-15 -1.28928" />
<geometry>
<mesh filename="package://leg_spacer_mid.stl"/>
</geometry>
<material name="leg_spacer_mid_material">
<color rgba="0.647059 0.647059 0.647059 1.0"/>
</material>
</collision>
<visual>
<origin xyz="0 0 0" rpy="0 -0 0" />
<geometry>
<mesh filename="package://leg_middle_2.stl"/>
</geometry>
<material name="leg_middle_2_material">
<color rgba="0.546901 0.444779 0.323018 1.0"/>
</material>
</visual>
<inertial>
<origin xyz="0.039 -1.02094e-16 -0.023505" rpy="0 0 0"/>
<mass value="0.0282748" />
<inertia ixx="1.51213e-05" ixy="-1.76438e-06"  ixz="-6.40522e-21" iyy="2.51079e-05" iyz="-5.93278e-20" izz="1.72974e-05" />
</inertial>
</link>

<link name="leg_tip_2">
<collision>
<origin xyz="-0.0161 -0.0831 -0.0405" rpy="-8.19448e-16 -3.67008e-15 1.35466" />
<geometry>
<mesh filename="package://leg_spacer.stl"/>
</geometry>
<material name="leg_spacer_material">
<color rgba="0.701961 0.701961 0.701961 1.0"/>
</material>
</collision>
<collision>
<origin xyz="-0.013943 -0.11505 -0.0405" rpy="-2.93832e-15 2.47231e-15 -2.86007" />
<geometry>
<mesh filename="package://leg_spacer.stl"/>
</geometry>
<material name="leg_spacer_material">
<color rgba="0.701961 0.701961 0.701961 1.0"/>
</material>
</collision>
<collision>
<origin xyz="3.01842e-16 -5.55112e-17 -0.0605" rpy="8.18789e-16 -6.38378e-16 3.16414e-15" />
<geometry>
<mesh filename="package://leg_tip_plate.stl"/>
</geometry>
<material name="leg_tip_plate_material">
<color rgba="0.447059 0.243137 0 1.0"/>
</material>
</collision>
<collision>
<origin xyz="3.46945e-18 -2.77556e-17 -0.04322" rpy="3.14159 -4.48253e-15 1.46532" />
<geometry>
<mesh filename="package://hn05-i101.stl"/>
</geometry>
<material name="hn05-i101_material">
<color rgba="0.8 0.776471 0.713725 1.0"/>
</material>
</collision>
<collision>
<origin xyz="3.95517e-16 -0.1392 -0.0065" rpy="3.14159 2.17741e-15 -2.86007" />
<geometry>
<mesh filename="package://leg_spacer.stl"/>
</geometry>
<material name="leg_spacer_material">
<color rgba="0.701961 0.701961 0.701961 1.0"/>
</material>
</collision>
<collision>
<origin xyz="0 -2.77556e-17 -0.0235" rpy="-1.44774e-29 8.58876e-30 5.33097e-31" />
<geometry>
<mesh filename="package://mx64.stl"/>
</geometry>
<material name="mx64_material">
<color rgba="0.211765 0.211765 0.211765 1.0"/>
</material>
</collision>
<collision>
<origin xyz="0.0161 -0.0831 -0.0405" rpy="-2.93832e-15 2.47231e-15 -2.86007" />
<geometry>
<mesh filename="package://leg_spacer.stl"/>
</geometry>
<material name="leg_spacer_material">
<color rgba="0.701961 0.701961 0.701961 1.0"/>
</material>
</collision>
<collision>
<origin xyz="0 -2.77556e-17 -0.0455" rpy="3.14159 2.4619e-15 -2.86007" />
<geometry>
<mesh filename="package://rx64-cap.stl"/>
</geometry>
<material name="rx64-cap_material">
<color rgba="0.8 0.776471 0.713725 1.0"/>
</material>
</collision>
<collision>
<origin xyz="3.71231e-16 -1.94289e-16 -0.0235" rpy="2.91435e-16 1.24898e-16 4.67681e-15" />
<geometry>
<mesh filename="package://leg_tip_plate.stl"/>
</geometry>
<material name="leg_tip_plate_material">
<color rgba="0.447059 0.243137 0 1.0"/>
</material>
</collision>
<collision>
<origin xyz="6.93889e-18 -2.77556e-17 -0.04678" rpy="3.27138e-15 -2.54517e-15 0.281518" />
<geometry>
<mesh filename="package://mf128zz.stl"/>
</geometry>
<material name="mf128zz_material">
<color rgba="0.8 0.776471 0.713725 1.0"/>
</material>
</collision>
<collision>
<origin xyz="0.013943 -0.11505 -0.0405" rpy="-2.93832e-15 2.47231e-15 -2.86007" />
<geometry>
<mesh filename="package://leg_spacer.stl"/>
</geometry>
<material name="leg_spacer_material">
<color rgba="0.701961 0.701961 0.701961 1.0"/>
</material>
</collision>
<visual>
<origin xyz="0 0 0" rpy="0 -0 0" />
<geometry>
<mesh filename="package://leg_tip_2.stl"/>
</geometry>
<material name="leg_tip_2_material">
<color rgba="0.39292 0.363337 0.324854 1.0"/>
</material>
</visual>
<inertial>
<origin xyz="-7.07825e-10 -0.0411183 -0.0252857" rpy="0 0 0"/>
<mass value="0.131575" />
<inertia ixx="0.000294116" ixy="3.09705e-12"  ixz="1.80567e-12" iyy="3.97285e-05" iyz="9.25707e-06" izz="0.00028263" />
</inertial>
</link>

<joint name="fr_3" type="revolute">
<origin xyz="0.078 0 0" rpy="-9.85305e-16 -4.71833e-16 1.5708" />
<parent link="leg_middle_2" />
<child link="leg_tip_2" />
<axis xyz="0 0 1"/>
<limit effort="1" velocity="20" />
<joint_properties friction="0.0"/>
</joint>

<joint name="fr_2" type="revolute">
<origin xyz="-0.0232 -0.0768608 -0.02362" rpy="1.5708 5.81479e-15 -1.5708" />
<parent link="leg_top_2" />
<child link="leg_middle_2" />
<axis xyz="0 0 -1"/>
<limit effort="1" velocity="20" />
<joint_properties friction="0.0"/>
</joint>

<joint name="fr_1" type="revolute">
<origin xyz="-0.028 0.0398 0.0231" rpy="1.5708 7.96373e-13 3.14159" />
<parent link="body_1" />
<child link="leg_top_2" />
<axis xyz="0 0 -1"/>
<limit effort="1" velocity="20" />
<joint_properties friction="0.0"/>
</joint>

<link name="leg_top_3">
<collision>
<origin xyz="-0.016 -0.0858608 0.003" rpy="3.14159 6.86067e-20 1.5708" />
<geometry>
<mesh filename="package://spacing_plate_extension.stl"/>
</geometry>
<material name="spacing_plate_extension_material">
<color rgba="0.972549 0.529412 0.00392157 1.0"/>
</material>
</collision>
<collision>
<origin xyz="-0.0117 -0.0613608 -0.00382" rpy="9.4369e-16 1.5708 0" />
<geometry>
<mesh filename="package://mounting_cube_25_30.stl"/>
</geometry>
<material name="mounting_cube_25_30_material">
<color rgba="0.8 0.8 0.8 1.0"/>
</material>
</collision>
<collision>
<origin xyz="0.0003 -0.0768608 -0.02362" rpy="-3.14159 1.5708 0" />
<geometry>
<mesh filename="package://mx64.stl"/>
</geometry>
<material name="mx64_material">
<color rgba="0.211765 0.211765 0.211765 1.0"/>
</material>
</collision>
<collision>
<origin xyz="-0.0117 -0.0783608 -0.00882" rpy="3.14159 -1.5708 0" />
<geometry>
<mesh filename="package://mounting_cube_25_30.stl"/>
</geometry>
<material name="mounting_cube_25_30_material">
<color rgba="0.8 0.8 0.8 1.0"/>
</material>
</collision>
<collision>
<origin xyz="0.0123 -0.0613608 -0.00882" rpy="-8.60423e-16 -1.5708 0" />
<geometry>
<mesh filename="package://mounting_cube_25_30.stl"/>
</geometry>
<material name="mounting_cube_25_30_material">
<color rgba="0.8 0.8 0.8 1.0"/>
</material>
</collision>
<collision>
<origin xyz="0.02002 -0.0768608 -0.02362" rpy="-1.5708 0.0565903 -1.5708" />
<geometry>
<mesh filename="package://hn05-i101.stl"/>
</geometry>
<material name="hn05-i101_material">
<color rgba="0.8 0.776471 0.713725 1.0"/>
</material>
</collision>
<collision>
<origin xyz="-0.0117 -0.0613608 -0.03842" rpy="8.88178e-16 1.5708 0" />
<geometry>
<mesh filename="package://mounting_cube_25_30.stl"/>
</geometry>
<material name="mounting_cube_25_30_material">
<color rgba="0.8 0.8 0.8 1.0"/>
</material>
</collision>
<collision>
<origin xyz="0.0123 -0.0833608 -0.00882" rpy="-8.60423e-16 -1.5708 0" />
<geometry>
<mesh filename="package://mounting_cube_25_30.stl"/>
</geometry>
<material name="mounting_cube_25_30_material">
<color rgba="0.8 0.8 0.8 1.0"/>
</material>
</collision>
<collision>
<origin xyz="0.0223 -0.0768608 -0.02362" rpy="-1.5708 -1.10558 -1.5708" />
<geometry>
<mesh filename="package://rx64-cap.stl"/>
</geometry>
<material name="rx64-cap_material">
<color rgba="0.8 0.776471 0.713725 1.0"/>
</material>
</collision>
<collision>
<origin xyz="0.0123 -0.0563608 -0.03842" rpy="-3.14159 1.5708 0" />
<geometry>
<mesh filename="package://mounting_cube_25_30.stl"/>
</geometry>
<material name="mounting_cube_25_30_material">
<color rgba="0.8 0.8 0.8 1.0"/>
</material>
</collision>
<collision>
<origin xyz="-0.016 -0.016 -0.04972" rpy="-4.88843e-15 -1.7185e-15 7.96053e-13" />
<geometry>
<mesh filename="package://leg_top_plate.stl"/>
</geometry>
<material name="leg_top_plate_material">
<color rgba="0.447059 0.243137 0 1.0"/>
</material>
</collision>
<collision>
<origin xyz="-0.016 -0.016 0" rpy="0 3.04343e-29 1.00974e-28" />
<geometry>
<mesh filename="package://leg_top_plate.stl"/>
</geometry>
<material name="leg_top_plate_material">
<color rgba="0.447059 0.243137 0 1.0"/>
</material>
</collision>
<collision>
<origin xyz="0.0123 -0.0783608 -0.03842" rpy="-3.14159 1.5708 0" />
<geometry>
<mesh filename="package://mounting_cube_25_30.stl"/>
</geometry>
<material name="mounting_cube_25_30_material">
<color rgba="0.8 0.8 0.8 1.0"/>
</material>
</collision>
<collision>
<origin xyz="0.0166 -0.0858608 -0.04672" rpy="-1.67661e-16 -5.50431e-17 1.5708" />
<geometry>
<mesh filename="package://spacing_plate.stl"/>
</geometry>
<material name="spacing_plate_material">
<color rgba="0.447059 0.243137 0 1.0"/>
</material>
</collision>
<collision>
<origin xyz="0.02358 -0.0768608 -0.02362" rpy="1.5708 1.55849 -1.5708" />
<geometry>
<mesh filename="package://mf128zz.stl"/>
</geometry>
<material name="mf128zz_material">
<color rgba="0.8 0.776471 0.713725 1.0"/>
</material>
</collision>
<collision>
<origin xyz="-0.0117 -0.0833608 -0.03842" rpy="9.71445e-16 1.5708 0" />
<geometry>
<mesh filename="package://mounting_cube_25_30.stl"/>
</geometry>
<material name="mounting_cube_25_30_material">
<color rgba="0.8 0.8 0.8 1.0"/>
</material>
</collision>
<collision>
<origin xyz="0.0166 -0.0538608 -0.00082" rpy="-3.14159 -6.86067e-20 -1.5708" />
<geometry>
<mesh filename="package://spacing_plate.stl"/>
</geometry>
<material name="spacing_plate_material">
<color rgba="0.447059 0.243137 0 1.0"/>
</material>
</collision>
<visual>
<origin xyz="0 0 0" rpy="0 -0 0" />
<geometry>
<mesh filename="package://leg_top_3.stl"/>
</geometry>
<material name="leg_top_3_material">
<color rgba="0.363504 0.328376 0.28287 1.0"/>
</material>
</visual>
<inertial>
<origin xyz="0.00232729 -0.0615551 -0.0234359" rpy="0 0 0"/>
<mass value="0.115968" />
<inertia ixx="6.31714e-05" ixy="3.21149e-06"  ixz="4.3256e-08" iyy="3.98532e-05" iyz="6.73737e-08" izz="6.27571e-05" />
</inertial>
</link>

<link name="leg_middle_3">
<collision>
<origin xyz="0.029 -0.0125 0.034" rpy="3.14159 2.63678e-16 -3.14159" />
<geometry>
<mesh filename="package://leg_spacer_mid.stl"/>
</geometry>
<material name="leg_spacer_mid_material">
<color rgba="0.647059 0.647059 0.647059 1.0"/>
</material>
</collision>
<collision>
<origin xyz="-0.016 -0.0175 0" rpy="-1.49635e-30 -3.10551e-29 7.39557e-32" />
<geometry>
<mesh filename="package://leg_middle_plate.stl"/>
</geometry>
<material name="leg_middle_plate_material">
<color rgba="0.447059 0.243137 0 1.0"/>
</material>
</collision>
<collision>
<origin xyz="0.049 0.0125 0.034" rpy="3.14159 2.63678e-16 -3.14159" />
<geometry>
<mesh filename="package://leg_spacer_mid.stl"/>
</geometry>
<material name="leg_spacer_mid_material">
<color rgba="0.647059 0.647059 0.647059 1.0"/>
</material>
</collision>
<collision>
<origin xyz="-0.016 -0.0175 -0.05002" rpy="-8.18789e-16 1.76248e-15 3.16414e-15" />
<geometry>
<mesh filename="package://leg_middle_plate.stl"/>
</geometry>
<material name="leg_middle_plate_material">
<color rgba="0.447059 0.243137 0 1.0"/>
</material>
</collision>
<visual>
<origin xyz="0 0 0" rpy="0 -0 0" />
<geometry>
<mesh filename="package://leg_middle_3.stl"/>
</geometry>
<material name="leg_middle_3_material">
<color rgba="0.546901 0.444779 0.323018 1.0"/>
</material>
</visual>
<inertial>
<origin xyz="0.039 4.34238e-17 -0.023505" rpy="0 0 0"/>
<mass value="0.0282748" />
<inertia ixx="1.51213e-05" ixy="-1.76438e-06"  ixz="-1.47642e-19" iyy="2.51079e-05" iyz="9.21177e-21" izz="1.72974e-05" />
</inertial>
</link>

<link name="leg_tip_3">
<collision>
<origin xyz="8.32667e-16 -0.1392 -0.0065" rpy="3.14159 -4.30211e-15 1.5708" />
<geometry>
<mesh filename="package://leg_spacer.stl"/>
</geometry>
<material name="leg_spacer_material">
<color rgba="0.701961 0.701961 0.701961 1.0"/>
</material>
</collision>
<collision>
<origin xyz="0.0161 -0.0831 -0.0405" rpy="-4.85723e-16 -4.46865e-15 1.5708" />
<geometry>
<mesh filename="package://leg_spacer.stl"/>
</geometry>
<material name="leg_spacer_material">
<color rgba="0.701961 0.701961 0.701961 1.0"/>
</material>
</collision>
<collision>
<origin xyz="0.013943 -0.11505 -0.0405" rpy="-4.85723e-16 -4.46865e-15 1.5708" />
<geometry>
<mesh filename="package://leg_spacer.stl"/>
</geometry>
<material name="leg_spacer_material">
<color rgba="0.701961 0.701961 0.701961 1.0"/>
</material>
</collision>
<collision>
<origin xyz="0 0 -0.0235" rpy="1.40524e-30 -7.34984e-30 1.2326e-32" />
<geometry>
<mesh filename="package://mx64.stl"/>
</geometry>
<material name="mx64_material">
<color rgba="0.211765 0.211765 0.211765 1.0"/>
</material>
</collision>
<collision>
<origin xyz="1.66533e-16 -2.77556e-16 -0.0235" rpy="1.05471e-15 7.77156e-16 4.94049e-15" />
<geometry>
<mesh filename="package://leg_tip_plate.stl"/>
</geometry>
<material name="leg_tip_plate_material">
<color rgba="0.447059 0.243137 0 1.0"/>
</material>
</collision>
<collision>
<origin xyz="5.55112e-17 2.77556e-17 -0.04322" rpy="3.14159 7.94791e-16 -0.386994" />
<geometry>
<mesh filename="package://hn05-i101.stl"/>
</geometry>
<material name="hn05-i101_material">
<color rgba="0.8 0.776471 0.713725 1.0"/>
</material>
</collision>
<collision>
<origin xyz="-0.0161 -0.0831 -0.0405" rpy="4.01165e-15 1.63184e-15 -0.497652" />
<geometry>
<mesh filename="package://leg_spacer.stl"/>
</geometry>
<material name="leg_spacer_material">
<color rgba="0.701961 0.701961 0.701961 1.0"/>
</material>
</collision>
<collision>
<origin xyz="0 0 -0.0455" rpy="3.14159 -4.67681e-15 1.5708" />
<geometry>
<mesh filename="package://rx64-cap.stl"/>
</geometry>
<material name="rx64-cap_material">
<color rgba="0.8 0.776471 0.713725 1.0"/>
</material>
</collision>
<collision>
<origin xyz="5.55112e-17 2.77556e-17 -0.04678" rpy="-5.27356e-16 -4.67681e-15 1.5708" />
<geometry>
<mesh filename="package://mf128zz.stl"/>
</geometry>
<material name="mf128zz_material">
<color rgba="0.8 0.776471 0.713725 1.0"/>
</material>
</collision>
<collision>
<origin xyz="1.66533e-16 -1.38778e-16 -0.0605" rpy="2.19269e-15 2.35922e-16 3.33067e-16" />
<geometry>
<mesh filename="package://leg_tip_plate.stl"/>
</geometry>
<material name="leg_tip_plate_material">
<color rgba="0.447059 0.243137 0 1.0"/>
</material>
</collision>
<collision>
<origin xyz="-0.013943 -0.11505 -0.0405" rpy="-4.85723e-16 -4.46865e-15 1.5708" />
<geometry>
<mesh filename="package://leg_spacer.stl"/>
</geometry>
<material name="leg_spacer_material">
<color rgba="0.701961 0.701961 0.701961 1.0"/>
</material>
</collision>
<visual>
<origin xyz="0 0 0" rpy="0 -0 0" />
<geometry>
<mesh filename="package://leg_tip_3.stl"/>
</geometry>
<material name="leg_tip_3_material">
<color rgba="0.39292 0.363337 0.324854 1.0"/>
</material>
</visual>
<inertial>
<origin xyz="-7.07825e-10 -0.0411183 -0.0252857" rpy="0 0 0"/>
<mass value="0.131575" />
<inertia ixx="0.000294116" ixy="3.09705e-12"  ixz="1.80567e-12" iyy="3.97285e-05" iyz="9.25707e-06" izz="0.00028263" />
</inertial>
</link>

<joint name="bl_3" type="revolute">
<origin xyz="0.078 5.55112e-17 6.93889e-18" rpy="-4.94049e-15 5.55112e-17 1.5708" />
<parent link="leg_middle_3" />
<child link="leg_tip_3" />
<axis xyz="0 0 1"/>
<limit effort="1" velocity="20" />
<joint_properties friction="0.0"/>
</joint>

<joint name="bl_2" type="revolute">
<origin xyz="-0.0232 -0.0768608 -0.02362" rpy="1.5708 -1.00265e-15 -1.5708" />
<parent link="leg_top_3" />
<child link="leg_middle_3" />
<axis xyz="0 0 -1"/>
<limit effort="1" velocity="20" />
<joint_properties friction="0.0"/>
</joint>

<joint name="bl_1" type="revolute">
<origin xyz="0.071 0.3102 0.0234" rpy="1.5708 7.93087e-13 -3.29157e-13" />
<parent link="body_1" />
<child link="leg_top_3" />
<axis xyz="0 0 -1"/>
<limit effort="1" velocity="20" />
<joint_properties friction="0.0"/>
</joint>

<link name="leg_top_4">
<collision>
<origin xyz="0.0003 -0.0768608 0.0231" rpy="-3.14159 1.5708 0" />
<geometry>
<mesh filename="package://mx64.stl"/>
</geometry>
<material name="mx64_material">
<color rgba="0.211765 0.211765 0.211765 1.0"/>
</material>
</collision>
<collision>
<origin xyz="0.0123 -0.0613608 0.0379" rpy="-7.93962e-13 -1.5708 0" />
<geometry>
<mesh filename="package://mounting_cube_25_30.stl"/>
</geometry>
<material name="mounting_cube_25_30_material">
<color rgba="0.8 0.8 0.8 1.0"/>
</material>
</collision>
<collision>
<origin xyz="-0.0117 -0.0783608 0.0379" rpy="3.14159 -1.5708 0" />
<geometry>
<mesh filename="package://mounting_cube_25_30.stl"/>
</geometry>
<material name="mounting_cube_25_30_material">
<color rgba="0.8 0.8 0.8 1.0"/>
</material>
</collision>
<collision>
<origin xyz="0.0166 -0.0858608 -5.55112e-17" rpy="-4.16334e-17 -5.55112e-17 1.5708" />
<geometry>
<mesh filename="package://spacing_plate.stl"/>
</geometry>
<material name="spacing_plate_material">
<color rgba="0.447059 0.243137 0 1.0"/>
</material>
</collision>
<collision>
<origin xyz="0.0123 -0.0833608 0.0379" rpy="-7.93962e-13 -1.5708 0" />
<geometry>
<mesh filename="package://mounting_cube_25_30.stl"/>
</geometry>
<material name="mounting_cube_25_30_material">
<color rgba="0.8 0.8 0.8 1.0"/>
</material>
</collision>
<collision>
<origin xyz="0.02358 -0.0768608 0.0231" rpy="-1.5708 -1.55849 1.5708" />
<geometry>
<mesh filename="package://mf128zz.stl"/>
</geometry>
<material name="mf128zz_material">
<color rgba="0.8 0.776471 0.713725 1.0"/>
</material>
</collision>
<collision>
<origin xyz="0.0166 -0.0538608 0.0459" rpy="-3.14159 5.30094e-17 -1.5708" />
<geometry>
<mesh filename="package://spacing_plate.stl"/>
</geometry>
<material name="spacing_plate_material">
<color rgba="0.447059 0.243137 0 1.0"/>
</material>
</collision>
<collision>
<origin xyz="-0.0117 -0.0833608 0.0083" rpy="7.93731e-13 1.5708 0" />
<geometry>
<mesh filename="package://mounting_cube_25_30.stl"/>
</geometry>
<material name="mounting_cube_25_30_material">
<color rgba="0.8 0.8 0.8 1.0"/>
</material>
</collision>
<collision>
<origin xyz="0.0123 -0.0783608 0.0083" rpy="-3.14159 1.5708 0" />
<geometry>
<mesh filename="package://mounting_cube_25_30.stl"/>
</geometry>
<material name="mounting_cube_25_30_material">
<color rgba="0.8 0.8 0.8 1.0"/>
</material>
</collision>
<collision>
<origin xyz="0.02002 -0.0768608 0.0231" rpy="1.5708 -0.0565903 1.5708" />
<geometry>
<mesh filename="package://hn05-i101.stl"/>
</geometry>
<material name="hn05-i101_material">
<color rgba="0.8 0.776471 0.713725 1.0"/>
</material>
</collision>
<collision>
<origin xyz="0.0123 -0.0563608 0.0083" rpy="-3.14159 1.5708 0" />
<geometry>
<mesh filename="package://mounting_cube_25_30.stl"/>
</geometry>
<material name="mounting_cube_25_30_material">
<color rgba="0.8 0.8 0.8 1.0"/>
</material>
</collision>
<collision>
<origin xyz="-0.0117 -0.0613608 0.0429" rpy="7.94045e-13 1.5708 0" />
<geometry>
<mesh filename="package://mounting_cube_25_30.stl"/>
</geometry>
<material name="mounting_cube_25_30_material">
<color rgba="0.8 0.8 0.8 1.0"/>
</material>
</collision>
<collision>
<origin xyz="0.0223 -0.0768608 0.0231" rpy="1.5708 1.10558 1.5708" />
<geometry>
<mesh filename="package://rx64-cap.stl"/>
</geometry>
<material name="rx64-cap_material">
<color rgba="0.8 0.776471 0.713725 1.0"/>
</material>
</collision>
<collision>
<origin xyz="-0.016 -0.016 -0.003" rpy="-1.29043e-32 1.18331e-29 2.91248e-29" />
<geometry>
<mesh filename="package://leg_top_plate.stl"/>
</geometry>
<material name="leg_top_plate_material">
<color rgba="0.447059 0.243137 0 1.0"/>
</material>
</collision>
<collision>
<origin xyz="-0.016 -0.016 0.04672" rpy="-9.46294e-17 -3.48549e-15 -8.08395e-13" />
<geometry>
<mesh filename="package://leg_top_plate.stl"/>
</geometry>
<material name="leg_top_plate_material">
<color rgba="0.447059 0.243137 0 1.0"/>
</material>
</collision>
<collision>
<origin xyz="-0.016 -0.0858608 0.04972" rpy="3.14159 -5.30094e-17 1.5708" />
<geometry>
<mesh filename="package://spacing_plate_extension.stl"/>
</geometry>
<material name="spacing_plate_extension_material">
<color rgba="0.972549 0.529412 0.00392157 1.0"/>
</material>
</collision>
<collision>
<origin xyz="-0.0117 -0.0613608 0.0083" rpy="7.93962e-13 1.5708 0" />
<geometry>
<mesh filename="package://mounting_cube_25_30.stl"/>
</geometry>
<material name="mounting_cube_25_30_material">
<color rgba="0.8 0.8 0.8 1.0"/>
</material>
</collision>
<visual>
<origin xyz="0 0 0" rpy="0 -0 0" />
<geometry>
<mesh filename="package://leg_top_4.stl"/>
</geometry>
<material name="leg_top_4_material">
<color rgba="0.363504 0.328376 0.28287 1.0"/>
</material>
</visual>
<inertial>
<origin xyz="0.00232729 -0.0615551 0.0232841" rpy="0 0 0"/>
<mass value="0.115968" />
<inertia ixx="6.31714e-05" ixy="3.21149e-06"  ixz="4.3256e-08" iyy="3.98532e-05" iyz="6.73737e-08" izz="6.27571e-05" />
</inertial>
</link>

<link name="leg_middle_4">
<collision>
<origin xyz="0.029 -0.0125 0.034" rpy="-3.14159 3.02973e-16 -1.179" />
<geometry>
<mesh filename="package://leg_spacer_mid.stl"/>
</geometry>
<material name="leg_spacer_mid_material">
<color rgba="0.647059 0.647059 0.647059 1.0"/>
</material>
</collision>
<collision>
<origin xyz="-0.016 -0.0175 0" rpy="-1.40419e-29 -1.39289e-31 1.51609e-30" />
<geometry>
<mesh filename="package://leg_middle_plate.stl"/>
</geometry>
<material name="leg_middle_plate_material">
<color rgba="0.447059 0.243137 0 1.0"/>
</material>
</collision>
<collision>
<origin xyz="-0.016 -0.0175 -0.05002" rpy="-1.52656e-16 5.41234e-16 -2.79624e-16" />
<geometry>
<mesh filename="package://leg_middle_plate.stl"/>
</geometry>
<material name="leg_middle_plate_material">
<color rgba="0.447059 0.243137 0 1.0"/>
</material>
</collision>
<collision>
<origin xyz="0.049 0.0125 0.034" rpy="-3.14159 3.02973e-16 -1.179" />
<geometry>
<mesh filename="package://leg_spacer_mid.stl"/>
</geometry>
<material name="leg_spacer_mid_material">
<color rgba="0.647059 0.647059 0.647059 1.0"/>
</material>
</collision>
<visual>
<origin xyz="0 0 0" rpy="0 -0 0" />
<geometry>
<mesh filename="package://leg_middle_4.stl"/>
</geometry>
<material name="leg_middle_4_material">
<color rgba="0.546901 0.444779 0.323018 1.0"/>
</material>
</visual>
<inertial>
<origin xyz="0.039 3.16347e-17 -0.023505" rpy="0 0 0"/>
<mass value="0.0282748" />
<inertia ixx="1.51213e-05" ixy="-1.76438e-06"  ixz="-1.48102e-19" iyy="2.51079e-05" iyz="5.46532e-20" izz="1.72974e-05" />
</inertial>
</link>

<link name="leg_tip_4">
<collision>
<origin xyz="0 0 -0.0235" rpy="-1.90605e-31 -4.8607e-30 -7.88941e-31" />
<geometry>
<mesh filename="package://mx64.stl"/>
</geometry>
<material name="mx64_material">
<color rgba="0.211765 0.211765 0.211765 1.0"/>
</material>
</collision>
<collision>
<origin xyz="2.22045e-16 1.94289e-16 -0.0605" rpy="-2.05391e-15 8.39606e-16 -1.01053e-14" />
<geometry>
<mesh filename="package://leg_tip_plate.stl"/>
</geometry>
<material name="leg_tip_plate_material">
<color rgba="0.447059 0.243137 0 1.0"/>
</material>
</collision>
<collision>
<origin xyz="0.013943 -0.11505 -0.0405" rpy="-3.43694e-16 5.38499e-16 -2.7498" />
<geometry>
<mesh filename="package://leg_spacer.stl"/>
</geometry>
<material name="leg_spacer_material">
<color rgba="0.701961 0.701961 0.701961 1.0"/>
</material>
</collision>
<collision>
<origin xyz="0 2.77556e-17 -0.04322" rpy="3.14159 -1.08552e-15 1.5756" />
<geometry>
<mesh filename="package://hn05-i101.stl"/>
</geometry>
<material name="hn05-i101_material">
<color rgba="0.8 0.776471 0.713725 1.0"/>
</material>
</collision>
<collision>
<origin xyz="0 2.77556e-17 -0.0455" rpy="3.14159 4.6911e-16 -2.7498" />
<geometry>
<mesh filename="package://rx64-cap.stl"/>
</geometry>
<material name="rx64-cap_material">
<color rgba="0.8 0.776471 0.713725 1.0"/>
</material>
</collision>
<collision>
<origin xyz="-0.013943 -0.11505 -0.0405" rpy="-3.43694e-16 5.38499e-16 -2.7498" />
<geometry>
<mesh filename="package://leg_spacer.stl"/>
</geometry>
<material name="leg_spacer_material">
<color rgba="0.701961 0.701961 0.701961 1.0"/>
</material>
</collision>
<collision>
<origin xyz="0.0161 -0.0831 -0.0405" rpy="-3.43694e-16 5.38499e-16 -2.7498" />
<geometry>
<mesh filename="package://leg_spacer.stl"/>
</geometry>
<material name="leg_spacer_material">
<color rgba="0.701961 0.701961 0.701961 1.0"/>
</material>
</collision>
<collision>
<origin xyz="3.88578e-16 -0.1392 -0.0065" rpy="3.14159 2.40126e-16 -2.7498" />
<geometry>
<mesh filename="package://leg_spacer.stl"/>
</geometry>
<material name="leg_spacer_material">
<color rgba="0.701961 0.701961 0.701961 1.0"/>
</material>
</collision>
<collision>
<origin xyz="-0.0161 -0.0831 -0.0405" rpy="-2.77096e-16 -3.12272e-17 1.46494" />
<geometry>
<mesh filename="package://leg_spacer.stl"/>
</geometry>
<material name="leg_spacer_material">
<color rgba="0.701961 0.701961 0.701961 1.0"/>
</material>
</collision>
<collision>
<origin xyz="1.11022e-16 -1.94289e-16 -0.0235" rpy="-3.10862e-15 1.47105e-15 7.32747e-15" />
<geometry>
<mesh filename="package://leg_tip_plate.stl"/>
</geometry>
<material name="leg_tip_plate_material">
<color rgba="0.447059 0.243137 0 1.0"/>
</material>
</collision>
<collision>
<origin xyz="0 0 -0.04678" rpy="2.18794e-16 -4.62171e-16 0.391796" />
<geometry>
<mesh filename="package://mf128zz.stl"/>
</geometry>
<material name="mf128zz_material">
<color rgba="0.8 0.776471 0.713725 1.0"/>
</material>
</collision>
<visual>
<origin xyz="0 0 0" rpy="0 -0 0" />
<geometry>
<mesh filename="package://leg_tip_4.stl"/>
</geometry>
<material name="leg_tip_4_material">
<color rgba="0.39292 0.363337 0.324854 1.0"/>
</material>
</visual>
<inertial>
<origin xyz="-7.07825e-10 -0.0411183 -0.0252857" rpy="0 0 0"/>
<mass value="0.131575" />
<inertia ixx="0.000294116" ixy="3.09705e-12"  ixz="1.80567e-12" iyy="3.97285e-05" iyz="9.25707e-06" izz="0.00028263" />
</inertial>
</link>

<joint name="br_3" type="revolute">
<origin xyz="0.078 -5.55112e-17 0" rpy="-5.96745e-16 -2.22045e-16 1.5708" />
<parent link="leg_middle_4" />
<child link="leg_tip_4" />
<axis xyz="0 0 1"/>
<limit effort="1" velocity="20" />
<joint_properties friction="0.0"/>
</joint>

<joint name="br_2" type="revolute">
<origin xyz="-0.0232 -0.0768608 0.0231" rpy="1.5708 -4.83207e-16 -1.5708" />
<parent link="leg_top_4" />
<child link="leg_middle_4" />
<axis xyz="0 0 -1"/>
<limit effort="1" velocity="20" />
<joint_properties friction="0.0"/>
</joint>

<joint name="br_1" type="revolute">
<origin xyz="-0.028 0.3102 0.0234" rpy="1.5708 -8.05429e-13 3.14159" />
<parent link="body_1" />
<child link="leg_top_4" />
<axis xyz="0 0 1"/>
<limit effort="1" velocity="20" />
<joint_properties friction="0.0"/>
</joint>


</robot>
