<sdf version="1.6">
<model name="onshape">
<link name="tronc">
<frame name="tronc_frame"><pose>0 0 0 0 -0 0</pose></frame>
<collision name="tronc_5_pillar_tube_collision_1">
<pose>-0.031 -0.054127 0.0909 1.80079e-24 -1.48609e-23 8.63328e-14</pose>
<geometry>
<cylinder><length>0.086</length><radius>0.004</radius></cylinder>
</geometry>
</collision>
<collision name="tronc_6_mx64_collision_1">
<pose>-0.046375 -0.026254 0.02 3.14159 1.48613e-23 -3.14159</pose>
<geometry>
<box><size>0.029 0.05 0.04</size></box>
</geometry>
</collision>
<collision name="tronc_8_mx64_collision_1">
<pose>0.05 -0.017127 0.1609 -3.14159 -1.5708 0</pose>
<geometry>
<box><size>0.029 0.05 0.04</size></box>
</geometry>
</collision>
<collision name="tronc_9_mx64_collision_1">
<pose>0.046375 -0.026254 0.02 3.14159 1.48609e-23 -3.14159</pose>
<geometry>
<box><size>0.029 0.05 0.04</size></box>
</geometry>
</collision>
<collision name="tronc_10_handle_collision_1">
<pose>7.29591e-15 0.071323 0.1899 1.5708 1.5708 0</pose>
<geometry>
<box><size>0.01 0.13 0.003</size></box>
</geometry>
</collision>
<collision name="tronc_10_handle_collision_2">
<pose>-0.06 0.071323 0.1649 1.5708 1.5708 0</pose>
<geometry>
<box><size>0.04 0.01 0.003</size></box>
</geometry>
</collision>
<collision name="tronc_10_handle_collision_3">
<pose>0.06 0.071323 0.1649 1.5708 1.5708 0</pose>
<geometry>
<box><size>0.04 0.01 0.003</size></box>
</geometry>
</collision>
<collision name="tronc_13_pillar_tube_collision_1">
<pose>0.0625 0.037873 0.0909 -3.14159 -1.48609e-23 8.63328e-14</pose>
<geometry>
<cylinder><length>0.086</length><radius>0.004</radius></cylinder>
</geometry>
</collision>
<collision name="tronc_14_mx64_collision_1">
<pose>-0.0505868 -0.017127 0.1609 3.14159 1.5708 0</pose>
<geometry>
<box><size>0.029 0.05 0.04</size></box>
</geometry>
</collision>
<collision name="tronc_18_torso_top_plate_nuc_collision_1">
<pose>1.52206e-14 -0.019127 0.1354 3.14159 1.48609e-23 -3.14159</pose>
<geometry>
<box><size>0.13 0.08 0.003</size></box>
</geometry>
</collision>
<collision name="tronc_21_torso_middle_plate_nuc_collision_1">
<pose>1.27053e-14 0.010373 0.0469 1.78736e-24 -1.48609e-23 8.63328e-14</pose>
<geometry>
<box><size>0.13 0.08 0.003</size></box>
</geometry>
</collision>
<collision name="tronc_22_pillar_tube_collision_1">
<pose>-0.0625 0.037873 0.0909 1.80079e-24 -1.48609e-23 8.63328e-14</pose>
<geometry>
<cylinder><length>0.086</length><radius>0.004</radius></cylinder>
</geometry>
</collision>
<collision name="tronc_23_nuc_collision_1">
<pose>1.24036e-14 0.035873 0.10615 1.5708 1.48609e-23 -3.14159</pose>
<geometry>
<box><size>0.11 0.11 0.033</size></box>
</geometry>
</collision>
<collision name="tronc_24_torso_bottom_plate_nuc_collision_1">
<pose>2.07506e-14 0.031123 0.00149996 -1.88432e-18 -5.37577e-17 8.62212e-14</pose>
<geometry>
<box><size>0.13 0.044 0.003</size></box>
</geometry>
</collision>
<collision name="tronc_24_torso_bottom_plate_nuc_collision_2">
<pose>-0.03 -0.007877 0.00149996 -1.88432e-18 -5.37577e-17 8.62212e-14</pose>
<geometry>
<box><size>0.01 0.035 0.003</size></box>
</geometry>
</collision>
<collision name="tronc_24_torso_bottom_plate_nuc_collision_3">
<pose>0.03 -0.007877 0.00149996 -1.88432e-18 -5.37577e-17 8.62212e-14</pose>
<geometry>
<box><size>0.01 0.035 0.003</size></box>
</geometry>
</collision>
<collision name="tronc_28_nuc_fix_collision_1">
<pose>8.35455e-15 0.059373 0.1384 -3.14159 1.79405e-24 -1.5708</pose>
<geometry>
<box><size>0.01 0.135 0.003</size></box>
</geometry>
</collision>
<collision name="tronc_32_mx64_collision_1">
<pose>2.55418e-14 -0.022127 0.1623 1.12133e-14 -2.28241e-15 -3.14159</pose>
<geometry>
<box><size>0.029 0.05 0.04</size></box>
</geometry>
</collision>
<collision name="tronc_33_pillar_tube_collision_1">
<pose>0.031 -0.054127 0.0914 1.80079e-24 -1.48609e-23 8.63328e-14</pose>
<geometry>
<cylinder><length>0.086</length><radius>0.004</radius></cylinder>
</geometry>
</collision>
<visual name="tronc_visual">
<pose>0 0 0 0 -0 0</pose>
<geometry>
<mesh><uri>file://tronc.stl</uri></mesh>
</geometry>
<material><ambient>0.312249 0.32483 0.318507 1</ambient><diffuse>0.312249 0.32483 0.318507 1</diffuse><specular>0.1 0.1 0.1 1</specular><emissive>0 0 0 0</emissive></material>
</visual>
<inertial>
<pose frame="tronc_frame">0.000185565 0.00052958 0.0922428 0 0 0</pose>
<mass>1.75912</mass>
<inertia><ixx>0.00823896</ixx><ixy>2.57494e-06</ixy><ixz>1.9734e-05</ixz><iyy>0.00915867</iyy><iyz>-0.000169433</iyz><izz>0.00511156</izz></inertia>
</inertial>
</link>

<link name="trunk">
<pose>0 0 0 0 0 0</pose>
<inertial>
<pose>0 0 0 0 0 0</pose>
<mass>1e-9</mass>
<inertia>
<ixx>0</ixx><ixy>0</ixy><ixz>0</ixz><iyy>0</iyy><iyz>0</iyz><izz>0</izz>
</inertia>
</inertial>
</link>
<joint name="trunk_frame" type="floating">
<pose>2.43796e-14 -0.011254 -0.0435 -5.7251e-17 -1.88432e-18 -1.5708</pose>
<parent>tronc</parent>
<child>trunk</child>
</joint>

<link name="head_base">
<pose>0 0 0 0 0 0</pose>
<inertial>
<pose>0 0 0 0 0 0</pose>
<mass>1e-9</mass>
<inertia>
<ixx>0</ixx><ixy>0</ixy><ixz>0</ixz><iyy>0</iyy><iyz>0</iyz><izz>0</izz>
</inertia>
</inertial>
</link>
<joint name="head_base_frame" type="floating">
<pose>2.67832e-14 -0.037127 0.1858 2.77556e-17 1.38778e-17 -1.5708</pose>
<parent>tronc</parent>
<child>head_base</child>
</joint>

<link name="u_block_1">
<frame name="u_block_1_frame"><pose>0 0 0 0 -0 0</pose></frame>
<collision name="u_block_1_0_u_base_motors_blocs_collision_1">
<pose>-0.046375 -0.016194 -0.00650004 3.14159 -1.79404e-24 1.5708</pose>
<geometry>
<box><size>0.05 0.03 0.006</size></box>
</geometry>
</collision>
<collision name="u_block_1_1_u_side_small_collision_1">
<pose>-0.046375 -0.042694 -0.0265 -1.5708 -7.12254e-17 5.40587e-13</pose>
<geometry>
<box><size>0.025 0.044 0.003</size></box>
</geometry>
</collision>
<collision name="u_block_1_2_u_side_small_with_trace_collision_1">
<pose>-0.046375 0.010646 -0.0265 -1.5708 2.0432e-16 -3.14159</pose>
<geometry>
<box><size>0.027 0.042 0.003</size></box>
</geometry>
</collision>
<visual name="u_block_1_visual">
<pose>0 0 0 0 -0 0</pose>
<geometry>
<mesh><uri>file://u_block_1.stl</uri></mesh>
</geometry>
<material><ambient>0.301961 0.301961 0.301961 1</ambient><diffuse>0.301961 0.301961 0.301961 1</diffuse><specular>0.1 0.1 0.1 1</specular><emissive>0 0 0 0</emissive></material>
</visual>
<inertial>
<pose frame="u_block_1_frame">-0.046375 -0.0173245 -0.0152654 0 0 0</pose>
<mass>0.0354404</mass>
<inertia><ixx>2.30163e-05</ixx><ixy>2.53866e-12</ixy><ixz>1.12453e-12</ixz><iyy>8.64707e-06</iyy><iyz>-7.76843e-07</iyz><izz>2.00312e-05</izz></inertia>
</inertial>
</link>

<link name="mx106_block_mir_1">
<frame name="mx106_block_mir_1_frame"><pose>0 0 0 0 -0 0</pose></frame>
<collision name="mx106_block_mir_1_1_mx106_collision_1">
<pose>-0.046375 -0.011254 -0.0585 1.5708 4.54672e-13 -1.5708</pose>
<geometry>
<box><size>0.03 0.055 0.04</size></box>
</geometry>
</collision>
<collision name="mx106_block_mir_1_6_mx106_collision_1">
<pose>-0.046375 0.038146 -0.0585 1.5708 2.89492e-13 5.40601e-13</pose>
<geometry>
<box><size>0.03 0.055 0.04</size></box>
</geometry>
</collision>
<visual name="mx106_block_mir_1_visual">
<pose>0 0 0 0 -0 0</pose>
<geometry>
<mesh><uri>file://mx106_block_mir_1.stl</uri></mesh>
</geometry>
<material><ambient>0.431842 0.425706 0.409343 1</ambient><diffuse>0.431842 0.425706 0.409343 1</diffuse><specular>0.1 0.1 0.1 1</specular><emissive>0 0 0 0</emissive></material>
</visual>
<inertial>
<pose frame="mx106_block_mir_1_frame">-0.0466794 0.00822885 -0.061598 0 0 0</pose>
<mass>0.427481</mass>
<inertia><ixx>0.000471323</ixx><ixy>5.61112e-06</ixy><ixz>-5.85755e-06</ixz><iyy>0.000182316</iyy><iyz>3.72337e-05</iyz><izz>0.000440632</izz></inertia>
</inertial>
</link>

<link name="right_knee_1">
<frame name="right_knee_1_frame"><pose>0 0 0 0 -0 0</pose></frame>
<collision name="right_knee_1_0_u_side_femur_mir_collision_1">
<pose>-0.018875 -0.011254 -0.083 1.5708 -2.0275e-15 1.5708</pose>
<geometry>
<box><size>0.04 0.09 0.003</size></box>
</geometry>
</collision>
<collision name="right_knee_1_5_mx106_collision_1">
<pose>-0.046375 -0.011254 -0.1685 -1.5708 -4.54672e-13 1.5708</pose>
<geometry>
<box><size>0.03 0.055 0.04</size></box>
</geometry>
</collision>
<collision name="right_knee_1_6_u_side_femur_collision_1">
<pose>-0.073875 -0.011254 -0.083 1.5708 -7.02166e-16 1.5708</pose>
<geometry>
<box><size>0.04 0.09 0.003</size></box>
</geometry>
</collision>
<collision name="right_knee_1_7_u_base_64_collision_1">
<pose>-0.046375 -0.011254 -0.126 -2.03443e-15 -1.74962e-17 -3.14159</pose>
<geometry>
<box><size>0.047 0.0275 0.006</size></box>
</geometry>
</collision>
<visual name="right_knee_1_visual">
<pose>0 0 0 0 -0 0</pose>
<geometry>
<mesh><uri>file://right_knee_1.stl</uri></mesh>
</geometry>
<material><ambient>0.367279 0.364193 0.355964 1</ambient><diffuse>0.367279 0.364193 0.355964 1</diffuse><specular>0.1 0.1 0.1 1</specular><emissive>0 0 0 0</emissive></material>
</visual>
<inertial>
<pose frame="right_knee_1_frame">-0.0466617 -0.0110297 -0.141534 0 0 0</pose>
<mass>0.269758</mass>
<inertia><ixx>0.000377081</ixx><ixy>9.26142e-06</ixy><ixz>4.25881e-06</ixz><iyy>0.000493067</iyy><iyz>6.91124e-07</iyz><izz>0.000182032</izz></inertia>
</inertial>
</link>

<link name="tibia_1">
<frame name="tibia_1_frame"><pose>0 0 0 0 -0 0</pose></frame>
<collision name="tibia_1_0_tibia_plate_collision_1">
<pose>-0.073875 -0.011254 -0.2505 1.5708 4.54871e-13 -1.5708</pose>
<geometry>
<box><size>0.03 0.165 0.003</size></box>
</geometry>
</collision>
<collision name="tibia_1_1_tibia_plate_collision_1">
<pose>-0.018875 -0.011254 -0.2505 1.5708 4.54982e-13 -1.5708</pose>
<geometry>
<box><size>0.03 0.165 0.003</size></box>
</geometry>
</collision>
<visual name="tibia_1_visual">
<pose>0 0 0 0 -0 0</pose>
<geometry>
<mesh><uri>file://tibia_1.stl</uri></mesh>
</geometry>
<material><ambient>0.301961 0.301961 0.301961 1</ambient><diffuse>0.301961 0.301961 0.301961 1</diffuse><specular>0.1 0.1 0.1 1</specular><emissive>0 0 0 0</emissive></material>
</visual>
<inertial>
<pose frame="tibia_1_frame">-0.046375 -0.00783231 -0.248107 0 0 0</pose>
<mass>0.0888437</mass>
<inertia><ixx>9.53741e-06</ixx><ixy>-3.80661e-11</ixy><ixz>6.12719e-06</ixz><iyy>0.000254651</iyy><iyz>1.44286e-11</iyz><izz>0.000245247</izz></inertia>
</inertial>
</link>

<link name="mx106_block_1">
<frame name="mx106_block_1_frame"><pose>0 0 0 0 -0 0</pose></frame>
<collision name="mx106_block_1_4_mx106_collision_1">
<pose>-0.046375 -0.011254 -0.3085 -1.5708 -4.55038e-13 1.5708</pose>
<geometry>
<box><size>0.03 0.055 0.04</size></box>
</geometry>
</collision>
<collision name="mx106_block_1_5_mx106_collision_1">
<pose>-0.046375 0.038146 -0.3085 -1.5708 -2.88835e-13 -3.14159</pose>
<geometry>
<box><size>0.03 0.055 0.04</size></box>
</geometry>
</collision>
<visual name="mx106_block_1_visual">
<pose>0 0 0 0 -0 0</pose>
<geometry>
<mesh><uri>file://mx106_block_1.stl</uri></mesh>
</geometry>
<material><ambient>0.431842 0.425706 0.409343 1</ambient><diffuse>0.431842 0.425706 0.409343 1</diffuse><specular>0.1 0.1 0.1 1</specular><emissive>0 0 0 0</emissive></material>
</visual>
<inertial>
<pose frame="mx106_block_1_frame">-0.0465498 0.0083344 -0.305402 0 0 0</pose>
<mass>0.427481</mass>
<inertia><ixx>0.000469432</ixx><ixy>8.86518e-06</ixy><ixz>5.93265e-06</ixz><iyy>0.00018247</iyy><iyz>-3.73023e-05</iyz><izz>0.000438896</izz></inertia>
</inertial>
</link>

<link name="right_foot_cleat_back_left">
<frame name="right_foot_cleat_back_left_frame"><pose>0 0 0 0 -0 0</pose></frame>
<collision name="right_foot_cleat_back_left_0_cleat_collision_1">
<pose>-0.089875 0.044276 -0.3735 3.14159 -8.93103e-14 2.94187</pose>
<geometry>
<cylinder><length>0.02</length><radius>0.008</radius></cylinder>
</geometry>
</collision>
<collision name="right_foot_cleat_back_left_3_cleat_collision_1">
<pose>-0.089875 -0.097324 -0.3735 3.14159 -8.90687e-14 2.94187</pose>
<geometry>
<cylinder><length>0.02</length><radius>0.008</radius></cylinder>
</geometry>
</collision>
<collision name="right_foot_cleat_back_left_8_u_side_small_collision_1">
<pose>-0.046375 -0.042694 -0.3405 1.5708 1.62985e-15 -3.14159</pose>
<geometry>
<box><size>0.025 0.044 0.003</size></box>
</geometry>
</collision>
<collision name="right_foot_cleat_back_left_11_cleat_collision_1">
<pose>-0.013875 -0.097324 -0.3735 -3.14159 -2.40911e-13 0.555221</pose>
<geometry>
<cylinder><length>0.02</length><radius>0.008</radius></cylinder>
</geometry>
</collision>
<collision name="right_foot_cleat_back_left_13_foot_plate_collision_1">
<pose>-0.051875 -0.026524 -0.365 -4.54368e-13 1.30359e-15 -3.14159</pose>
<geometry>
<box><size>0.09 0.155 0.003</size></box>
</geometry>
</collision>
<collision name="right_foot_cleat_back_left_14_u_side_small_with_trace_collision_1">
<pose>-0.046375 0.010646 -0.3405 1.5708 -4.08558e-15 5.42073e-13</pose>
<geometry>
<box><size>0.027 0.042 0.003</size></box>
</geometry>
</collision>
<collision name="right_foot_cleat_back_left_16_cleat_collision_1">
<pose>-0.013875 0.044276 -0.3735 -3.14159 1.3733e-13 -0.311457</pose>
<geometry>
<cylinder><length>0.02</length><radius>0.008</radius></cylinder>
</geometry>
</collision>
<collision name="right_foot_cleat_back_left_17_foot_protection_collision_1">
<pose>-0.051875 -0.110324 -0.351 -2.08226e-15 0.785398 1.5708</pose>
<geometry>
<box><size>0.01 0.09 0.01</size></box>
</geometry>
</collision>
<collision name="right_foot_cleat_back_left_18_u_base_motors_blocs_collision_1">
<pose>-0.046375 -0.016194 -0.3605 -1.47986e-15 -4.54146e-13 1.5708</pose>
<geometry>
<box><size>0.05 0.03 0.006</size></box>
</geometry>
</collision>
<visual name="right_foot_cleat_back_left_visual">
<pose>0 0 0 0 -0 0</pose>
<geometry>
<mesh><uri>file://right_foot_cleat_back_left.stl</uri></mesh>
</geometry>
<material><ambient>0.3811 0.375396 0.359887 1</ambient><diffuse>0.3811 0.375396 0.359887 1</diffuse><specular>0.1 0.1 0.1 1</specular><emissive>0 0 0 0</emissive></material>
</visual>
<inertial>
<pose frame="right_foot_cleat_back_left_frame">-0.0510597 -0.0390069 -0.360078 0 0 0</pose>
<mass>0.239067</mass>
<inertia><ixx>0.000628269</ixx><ixy>-4.22638e-06</ixy><ixz>-1.62931e-06</ixz><iyy>0.000201541</iyy><iyz>2.77688e-05</iyz><izz>0.000791512</izz></inertia>
</inertial>
</link>

<link name="right_foot">
<pose>0 0 0 0 0 0</pose>
<inertial>
<pose>0 0 0 0 0 0</pose>
<mass>1e-9</mass>
<inertia>
<ixx>0</ixx><ixy>0</ixy><ixz>0</ixz><iyy>0</iyy><iyz>0</iyz><izz>0</izz>
</inertia>
</inertial>
</link>
<joint name="right_foot_frame" type="floating">
<pose>-0.046375 -0.011024 -0.3835 -1.81711e-15 4.602e-13 -1.5708</pose>
<parent>right_foot_cleat_back_left</parent>
<child>right_foot</child>
</joint>

<joint name="right_ankle_roll" type="revolute">
<pose>-0.046375 0.012146 -0.3235 1.5708 -4.08558e-15 5.42073e-13</pose>
<parent>mx106_block_1</parent>
<child>right_foot_cleat_back_left</child>
<axis>
<xyz>-0 -0 1</xyz>
<limit><effort>10</effort><velocity>6</velocity></limit>
</axis>
</joint>

<joint name="right_ankle_pitch" type="revolute">
<pose>-0.072375 -0.011254 -0.3235 -1.5708 -4.55038e-13 1.5708</pose>
<parent>tibia_1</parent>
<child>mx106_block_1</child>
<axis>
<xyz>-0 -0 -1</xyz>
<limit><effort>10</effort><velocity>6</velocity></limit>
</axis>
</joint>

<joint name="right_knee" type="revolute">
<pose>-0.072375 -0.011254 -0.1835 1.5708 4.54871e-13 -1.5708</pose>
<parent>right_knee_1</parent>
<child>tibia_1</child>
<axis>
<xyz>0 0 -1</xyz>
<limit><effort>10</effort><velocity>6</velocity></limit>
</axis>
</joint>

<joint name="right_hip_pitch" type="revolute">
<pose>-0.072375 -0.011254 -0.0435 1.5708 -7.02166e-16 1.5708</pose>
<parent>mx106_block_mir_1</parent>
<child>right_knee_1</child>
<axis>
<xyz>0 0 1</xyz>
<limit><effort>10</effort><velocity>6</velocity></limit>
</axis>
</joint>

<joint name="right_hip_roll" type="revolute">
<pose>-0.046375 0.012146 -0.0435 1.5708 2.89492e-13 5.40601e-13</pose>
<parent>u_block_1</parent>
<child>mx106_block_mir_1</child>
<axis>
<xyz>0 0 1</xyz>
<limit><effort>10</effort><velocity>6</velocity></limit>
</axis>
</joint>

<joint name="right_hip_yaw" type="revolute">
<pose>-0.046375 -0.011254 -0.00350004 3.14159 -1.79404e-24 1.5708</pose>
<parent>tronc</parent>
<child>u_block_1</child>
<axis>
<xyz>0 0 -1</xyz>
<limit><effort>10</effort><velocity>6</velocity></limit>
</axis>
</joint>

<link name="u_block_2">
<frame name="u_block_2_frame"><pose>0 0 0 0 -0 0</pose></frame>
<collision name="u_block_2_0_u_base_motors_blocs_collision_1">
<pose>0.046375 -0.016194 -0.00649999 -3.14159 -3.13509e-16 1.5708</pose>
<geometry>
<box><size>0.05 0.03 0.006</size></box>
</geometry>
</collision>
<collision name="u_block_2_1_u_side_small_with_trace_collision_1">
<pose>0.046375 0.010646 -0.0265 -1.5708 -2.45939e-16 -3.14159</pose>
<geometry>
<box><size>0.027 0.042 0.003</size></box>
</geometry>
</collision>
<collision name="u_block_2_2_u_side_small_collision_1">
<pose>0.046375 -0.042694 -0.0265 -1.5708 1.6072e-16 8.61044e-14</pose>
<geometry>
<box><size>0.025 0.044 0.003</size></box>
</geometry>
</collision>
<visual name="u_block_2_visual">
<pose>0 0 0 0 -0 0</pose>
<geometry>
<mesh><uri>file://u_block_2.stl</uri></mesh>
</geometry>
<material><ambient>0.301961 0.301961 0.301961 1</ambient><diffuse>0.301961 0.301961 0.301961 1</diffuse><specular>0.1 0.1 0.1 1</specular><emissive>0 0 0 0</emissive></material>
</visual>
<inertial>
<pose frame="u_block_2_frame">0.046375 -0.0173245 -0.0152654 0 0 0</pose>
<mass>0.0354404</mass>
<inertia><ixx>2.30163e-05</ixx><ixy>2.53865e-12</ixy><ixz>1.12453e-12</ixz><iyy>8.64707e-06</iyy><iyz>-7.76843e-07</iyz><izz>2.00312e-05</izz></inertia>
</inertial>
</link>

<link name="mx106_block_2">
<frame name="mx106_block_2_frame"><pose>0 0 0 0 -0 0</pose></frame>
<collision name="mx106_block_2_4_mx106_collision_1">
<pose>0.046375 0.038146 -0.0585 1.5708 2.88507e-13 8.6382e-14</pose>
<geometry>
<box><size>0.03 0.055 0.04</size></box>
</geometry>
</collision>
<collision name="mx106_block_2_11_mx106_collision_1">
<pose>0.046375 -0.011254 -0.0585 1.5708 -1.45178e-16 1.5708</pose>
<geometry>
<box><size>0.03 0.055 0.04</size></box>
</geometry>
</collision>
<visual name="mx106_block_2_visual">
<pose>0 0 0 0 -0 0</pose>
<geometry>
<mesh><uri>file://mx106_block_2.stl</uri></mesh>
</geometry>
<material><ambient>0.431842 0.425706 0.409343 1</ambient><diffuse>0.431842 0.425706 0.409343 1</diffuse><specular>0.1 0.1 0.1 1</specular><emissive>0 0 0 0</emissive></material>
</visual>
<inertial>
<pose frame="mx106_block_2_frame">0.0465498 0.0083344 -0.061598 0 0 0</pose>
<mass>0.427481</mass>
<inertia><ixx>0.000469848</ixx><ixy>-8.20784e-06</ixy><ixz>6.21669e-06</ixz><iyy>0.000182055</iyy><iyz>3.82823e-05</iyz><izz>0.000438896</izz></inertia>
</inertial>
</link>

<link name="left_knee_1">
<frame name="left_knee_1_frame"><pose>0 0 0 0 -0 0</pose></frame>
<collision name="left_knee_1_1_u_base_64_collision_1">
<pose>0.046375 -0.011254 -0.126 1.45178e-16 2.27835e-16 8.54033e-14</pose>
<geometry>
<box><size>0.047 0.0275 0.006</size></box>
</geometry>
</collision>
<collision name="left_knee_1_2_u_side_femur_collision_1">
<pose>0.073875 -0.011254 -0.083 1.5708 6.44779e-16 -1.5708</pose>
<geometry>
<box><size>0.04 0.09 0.003</size></box>
</geometry>
</collision>
<collision name="left_knee_1_4_u_side_femur_mir_collision_1">
<pose>0.018875 -0.011254 -0.083 1.5708 1.29857e-16 -1.5708</pose>
<geometry>
<box><size>0.04 0.09 0.003</size></box>
</geometry>
</collision>
<collision name="left_knee_1_7_mx106_collision_1">
<pose>0.046375 -0.011254 -0.1685 -1.5708 4.5425e-13 -1.5708</pose>
<geometry>
<box><size>0.03 0.055 0.04</size></box>
</geometry>
</collision>
<visual name="left_knee_1_visual">
<pose>0 0 0 0 -0 0</pose>
<geometry>
<mesh><uri>file://left_knee_1.stl</uri></mesh>
</geometry>
<material><ambient>0.367279 0.364193 0.355964 1</ambient><diffuse>0.367279 0.364193 0.355964 1</diffuse><specular>0.1 0.1 0.1 1</specular><emissive>0 0 0 0</emissive></material>
</visual>
<inertial>
<pose frame="left_knee_1_frame">0.0468476 -0.0111969 -0.141534 0 0 0</pose>
<mass>0.269758</mass>
<inertia><ixx>0.000377165</ixx><ixy>-9.38144e-06</ixy><ixz>-2.92616e-06</ixz><iyy>0.000492957</iyy><iyz>-1.29719e-06</iyz><izz>0.000182006</izz></inertia>
</inertial>
</link>

<link name="tibia_2">
<frame name="tibia_2_frame"><pose>0 0 0 0 -0 0</pose></frame>
<collision name="tibia_2_0_tibia_plate_collision_1">
<pose>0.073875 -0.011254 -0.2505 1.5708 4.5456e-13 -1.5708</pose>
<geometry>
<box><size>0.03 0.165 0.003</size></box>
</geometry>
</collision>
<collision name="tibia_2_1_tibia_plate_collision_1">
<pose>0.018875 -0.011254 -0.2505 1.5708 4.54864e-13 -1.5708</pose>
<geometry>
<box><size>0.03 0.165 0.003</size></box>
</geometry>
</collision>
<visual name="tibia_2_visual">
<pose>0 0 0 0 -0 0</pose>
<geometry>
<mesh><uri>file://tibia_2.stl</uri></mesh>
</geometry>
<material><ambient>0.301961 0.301961 0.301961 1</ambient><diffuse>0.301961 0.301961 0.301961 1</diffuse><specular>0.1 0.1 0.1 1</specular><emissive>0 0 0 0</emissive></material>
</visual>
<inertial>
<pose frame="tibia_2_frame">0.046375 -0.00783231 -0.248107 0 0 0</pose>
<mass>0.0888437</mass>
<inertia><ixx>9.53741e-06</ixx><ixy>-3.80661e-11</ixy><ixz>6.12719e-06</ixz><iyy>0.000254651</iyy><iyz>1.44286e-11</iyz><izz>0.000245247</izz></inertia>
</inertial>
</link>

<link name="mx106_block_mir_2">
<frame name="mx106_block_mir_2_frame"><pose>0 0 0 0 -0 0</pose></frame>
<collision name="mx106_block_mir_2_3_mx106_collision_1">
<pose>0.046375 -0.011254 -0.3085 -1.5708 4.5425e-13 -1.5708</pose>
<geometry>
<box><size>0.03 0.055 0.04</size></box>
</geometry>
</collision>
<collision name="mx106_block_mir_2_7_mx106_collision_1">
<pose>0.046375 0.038146 -0.3085 -1.5708 -2.89839e-13 -3.14159</pose>
<geometry>
<box><size>0.03 0.055 0.04</size></box>
</geometry>
</collision>
<visual name="mx106_block_mir_2_visual">
<pose>0 0 0 0 -0 0</pose>
<geometry>
<mesh><uri>file://mx106_block_mir_2.stl</uri></mesh>
</geometry>
<material><ambient>0.431842 0.425706 0.409343 1</ambient><diffuse>0.431842 0.425706 0.409343 1</diffuse><specular>0.1 0.1 0.1 1</specular><emissive>0 0 0 0</emissive></material>
</visual>
<inertial>
<pose frame="mx106_block_mir_2_frame">0.0466794 0.00822885 -0.305402 0 0 0</pose>
<mass>0.427481</mass>
<inertia><ixx>0.000471153</ixx><ixy>-4.80698e-06</ixy><ixz>-6.14159e-06</ixz><iyy>0.000182486</iyy><iyz>-3.82137e-05</iyz><izz>0.000440632</izz></inertia>
</inertial>
</link>

<link name="left_foot_cleat_front_right">
<frame name="left_foot_cleat_front_right_frame"><pose>0 0 0 0 -0 0</pose></frame>
<collision name="left_foot_cleat_front_right_0_foot_protection_collision_1">
<pose>0.051875 -0.110324 -0.351 1.06922e-14 0.785398 1.5708</pose>
<geometry>
<box><size>0.01 0.09 0.01</size></box>
</geometry>
</collision>
<collision name="left_foot_cleat_front_right_2_cleat_collision_1">
<pose>0.089875 0.044276 -0.3735 3.14159 -4.26267e-13 2.66106</pose>
<geometry>
<cylinder><length>0.02</length><radius>0.008</radius></cylinder>
</geometry>
</collision>
<collision name="left_foot_cleat_front_right_4_u_side_small_collision_1">
<pose>0.046375 -0.042694 -0.3405 1.5708 1.00014e-16 -3.14159</pose>
<geometry>
<box><size>0.025 0.044 0.003</size></box>
</geometry>
</collision>
<collision name="left_foot_cleat_front_right_6_cleat_collision_1">
<pose>0.089875 -0.097324 -0.3735 3.14159 -4.28592e-13 2.66106</pose>
<geometry>
<cylinder><length>0.02</length><radius>0.008</radius></cylinder>
</geometry>
</collision>
<collision name="left_foot_cleat_front_right_12_u_base_motors_blocs_collision_1">
<pose>0.046375 -0.016194 -0.3605 6.56132e-15 -9.09768e-13 1.5708</pose>
<geometry>
<box><size>0.05 0.03 0.006</size></box>
</geometry>
</collision>
<collision name="left_foot_cleat_front_right_14_cleat_collision_1">
<pose>0.013875 -0.097324 -0.3735 3.14159 -4.26989e-13 2.66106</pose>
<geometry>
<cylinder><length>0.02</length><radius>0.008</radius></cylinder>
</geometry>
</collision>
<collision name="left_foot_cleat_front_right_15_cleat_collision_1">
<pose>0.013875 0.044276 -0.3735 3.14159 -4.24818e-13 2.66106</pose>
<geometry>
<cylinder><length>0.02</length><radius>0.008</radius></cylinder>
</geometry>
</collision>
<collision name="left_foot_cleat_front_right_18_u_side_small_with_trace_collision_1">
<pose>0.046375 0.010646 -0.3405 1.5708 6.06172e-15 8.5963e-14</pose>
<geometry>
<box><size>0.027 0.042 0.003</size></box>
</geometry>
</collision>
<collision name="left_foot_cleat_front_right_19_foot_plate_collision_1">
<pose>0.051875 -0.026524 -0.365 -8.70248e-13 1.24944e-14 -3.14159</pose>
<geometry>
<box><size>0.09 0.155 0.003</size></box>
</geometry>
</collision>
<visual name="left_foot_cleat_front_right_visual">
<pose>0 0 0 0 -0 0</pose>
<geometry>
<mesh><uri>file://left_foot_cleat_front_right.stl</uri></mesh>
</geometry>
<material><ambient>0.3811 0.375396 0.359887 1</ambient><diffuse>0.3811 0.375396 0.359887 1</diffuse><specular>0.1 0.1 0.1 1</specular><emissive>0 0 0 0</emissive></material>
</visual>
<inertial>
<pose frame="left_foot_cleat_front_right_frame">0.0510597 -0.0390069 -0.360078 0 0 0</pose>
<mass>0.239067</mass>
<inertia><ixx>0.000628263</ixx><ixy>4.22638e-06</ixy><ixz>1.60503e-06</ixz><iyy>0.000201541</iyy><iyz>2.77688e-05</iyz><izz>0.000791517</izz></inertia>
</inertial>
</link>

<link name="left_foot">
<pose>0 0 0 0 0 0</pose>
<inertial>
<pose>0 0 0 0 0 0</pose>
<mass>1e-9</mass>
<inertia>
<ixx>0</ixx><ixy>0</ixy><ixz>0</ixz><iyy>0</iyy><iyz>0</iyz><izz>0</izz>
</inertia>
</inertial>
</link>
<joint name="left_foot_frame" type="floating">
<pose>0.046375 -0.011024 -0.3835 3.11322e-14 9.09916e-13 -1.5708</pose>
<parent>left_foot_cleat_front_right</parent>
<child>left_foot</child>
</joint>

<joint name="left_ankle_roll" type="revolute">
<pose>0.046375 0.012146 -0.3235 1.5708 6.06172e-15 8.5963e-14</pose>
<parent>mx106_block_mir_2</parent>
<child>left_foot_cleat_front_right</child>
<axis>
<xyz>-0 -0 1</xyz>
<limit><effort>10</effort><velocity>6</velocity></limit>
</axis>
</joint>

<joint name="left_ankle_pitch" type="revolute">
<pose>0.072375 -0.011254 -0.3235 -1.5708 4.5425e-13 -1.5708</pose>
<parent>tibia_2</parent>
<child>mx106_block_mir_2</child>
<axis>
<xyz>0 0 1</xyz>
<limit><effort>10</effort><velocity>6</velocity></limit>
</axis>
</joint>

<joint name="left_knee" type="revolute">
<pose>0.072375 -0.011254 -0.1835 1.5708 4.5456e-13 -1.5708</pose>
<parent>left_knee_1</parent>
<child>tibia_2</child>
<axis>
<xyz>-0 -0 -1</xyz>
<limit><effort>10</effort><velocity>6</velocity></limit>
</axis>
</joint>

<joint name="left_hip_pitch" type="revolute">
<pose>0.072375 -0.011254 -0.0435 1.5708 6.44779e-16 -1.5708</pose>
<parent>mx106_block_2</parent>
<child>left_knee_1</child>
<axis>
<xyz>-0 -0 -1</xyz>
<limit><effort>10</effort><velocity>6</velocity></limit>
</axis>
</joint>

<joint name="left_hip_roll" type="revolute">
<pose>0.046375 0.012146 -0.0435 1.5708 2.88507e-13 8.6382e-14</pose>
<parent>u_block_2</parent>
<child>mx106_block_2</child>
<axis>
<xyz>0 0 1</xyz>
<limit><effort>10</effort><velocity>6</velocity></limit>
</axis>
</joint>

<joint name="left_hip_yaw" type="revolute">
<pose>0.046375 -0.011254 -0.00349999 -3.14159 -3.13509e-16 1.5708</pose>
<parent>tronc</parent>
<child>u_block_2</child>
<axis>
<xyz>0 0 -1</xyz>
<limit><effort>10</effort><velocity>6</velocity></limit>
</axis>
</joint>

<link name="u_shoulder_1">
<frame name="u_shoulder_1_frame"><pose>0 0 0 0 -0 0</pose></frame>
<collision name="u_shoulder_1_2_u_base_64_collision_1">
<pose>0.0765 -0.032127 0.1609 -1.5708 -4.55145e-13 -1.5708</pose>
<geometry>
<box><size>0.047 0.0275 0.006</size></box>
</geometry>
</collision>
<visual name="u_shoulder_1_visual">
<pose>0 0 0 0 -0 0</pose>
<geometry>
<mesh><uri>file://u_shoulder_1.stl</uri></mesh>
</geometry>
<material><ambient>0.301961 0.301961 0.301961 1</ambient><diffuse>0.301961 0.301961 0.301961 1</diffuse><specular>0.1 0.1 0.1 1</specular><emissive>0 0 0 0</emissive></material>
</visual>
<inertial>
<pose frame="u_shoulder_1_frame">0.0902829 -0.032127 0.15604 0 0 0</pose>
<mass>0.042898</mass>
<inertia><ixx>2.33892e-05</ixx><ixy>-1.80265e-06</ixy><ixz>1.95873e-06</ixz><iyy>1.58135e-05</iyy><iyz>6.85626e-18</iyz><izz>3.00983e-05</izz></inertia>
</inertial>
</link>

<link name="left_humerus_1">
<frame name="left_humerus_1_frame"><pose>0 0 0 0 -0 0</pose></frame>
<collision name="left_humerus_1_3_mx64_collision_1">
<pose>0.1085 -0.031127 0.1159 1.5708 5.82834e-17 8.66163e-14</pose>
<geometry>
<box><size>0.029 0.05 0.04</size></box>
</geometry>
</collision>
<collision name="left_humerus_1_6_humerus_plate_collision_1">
<pose>0.1085 -0.0154534 0.0389 1.5708 -4.53804e-13 -1.5708</pose>
<geometry>
<box><size>0.003 0.07 0.03</size></box>
</geometry>
</collision>
<collision name="left_humerus_1_6_humerus_plate_collision_2">
<pose>0.1085 -0.0314534 0.0769 1.5708 -4.53804e-13 -1.5708</pose>
<geometry>
<box><size>0.03 0.003 0.03</size></box>
</geometry>
</collision>
<visual name="left_humerus_1_visual">
<pose>0 0 0 0 -0 0</pose>
<geometry>
<mesh><uri>file://left_humerus_1.stl</uri></mesh>
</geometry>
<material><ambient>0.363401 0.358167 0.34376 1</ambient><diffuse>0.363401 0.358167 0.34376 1</diffuse><specular>0.1 0.1 0.1 1</specular><emissive>0 0 0 0</emissive></material>
</visual>
<inertial>
<pose frame="left_humerus_1_frame">0.107647 -0.0297747 0.0932601 0 0 0</pose>
<mass>0.214223</mass>
<inertia><ixx>0.000334917</ixx><ixy>-1.86651e-06</ixy><ixz>-1.52998e-05</ixz><iyy>0.000332944</iyy><iyz>1.1514e-05</iyz><izz>7.82583e-05</izz></inertia>
</inertial>
</link>

<link name="left_radius_1">
<frame name="left_radius_1_frame"><pose>0 0 0 0 -0 0</pose></frame>
<collision name="left_radius_1_2_mx64_collision_1">
<pose>0.1085 -0.0529534 0.00389996 1.5708 4.53415e-13 1.5708</pose>
<geometry>
<box><size>0.029 0.05 0.04</size></box>
</geometry>
</collision>
<collision name="left_radius_1_5_radius_plate_collision_1">
<pose>0.1085 -0.0349534 -0.0796 1.5708 -9.08273e-13 -1.5708</pose>
<geometry>
<box><size>0.003 0.085 0.03</size></box>
</geometry>
</collision>
<collision name="left_radius_1_5_radius_plate_collision_2">
<pose>0.1085 -0.0454534 -0.1221 1.5708 -9.08273e-13 -1.5708</pose>
<geometry>
<cylinder><length>0.03</length><radius>0.012</radius></cylinder>
</geometry>
</collision>
<visual name="left_radius_1_visual">
<pose>0 0 0 0 -0 0</pose>
<geometry>
<mesh><uri>file://left_radius_1.stl</uri></mesh>
</geometry>
<material><ambient>0.330671 0.326648 0.315918 1</ambient><diffuse>0.330671 0.326648 0.315918 1</diffuse><specular>0.1 0.1 0.1 1</specular><emissive>0 0 0 0</emissive></material>
</visual>
<inertial>
<pose frame="left_radius_1_frame">0.108122 -0.0504197 -0.0181398 0 0 0</pose>
<mass>0.20688</mass>
<inertia><ixx>0.000296486</ixx><ixy>-5.78228e-06</ixy><ixz>4.26778e-06</ixz><iyy>0.000368472</iyy><iyz>3.13705e-05</iyz><izz>0.000131479</izz></inertia>
</inertial>
</link>

<joint name="left_elbow" type="revolute">
<pose>0.132 -0.0529534 0.0189 1.5708 4.53415e-13 1.5708</pose>
<parent>left_humerus_1</parent>
<child>left_radius_1</child>
<axis>
<xyz>0 0 1</xyz>
<limit><effort>10</effort><velocity>6</velocity></limit>
</axis>
</joint>

<joint name="left_shoulder_roll" type="revolute">
<pose>0.1085 -0.054627 0.1309 1.5708 5.82834e-17 8.66163e-14</pose>
<parent>u_shoulder_1</parent>
<child>left_humerus_1</child>
<axis>
<xyz>0 0 1</xyz>
<limit><effort>10</effort><velocity>6</velocity></limit>
</axis>
</joint>

<joint name="left_shoulder_pitch" type="revolute">
<pose>0.0735 -0.032127 0.1609 -1.5708 -4.55145e-13 -1.5708</pose>
<parent>tronc</parent>
<child>u_shoulder_1</child>
<axis>
<xyz>-0 -0 1</xyz>
<limit><effort>10</effort><velocity>6</velocity></limit>
</axis>
</joint>

<link name="u_shoulder_2">
<frame name="u_shoulder_2_frame"><pose>0 0 0 0 -0 0</pose></frame>
<collision name="u_shoulder_2_1_u_base_64_collision_1">
<pose>-0.0770868 -0.032127 0.1609 -1.5708 -6.38201e-16 1.5708</pose>
<geometry>
<box><size>0.047 0.0275 0.006</size></box>
</geometry>
</collision>
<visual name="u_shoulder_2_visual">
<pose>0 0 0 0 -0 0</pose>
<geometry>
<mesh><uri>file://u_shoulder_2.stl</uri></mesh>
</geometry>
<material><ambient>0.301961 0.301961 0.301961 1</ambient><diffuse>0.301961 0.301961 0.301961 1</diffuse><specular>0.1 0.1 0.1 1</specular><emissive>0 0 0 0</emissive></material>
</visual>
<inertial>
<pose frame="u_shoulder_2_frame">-0.0908697 -0.032127 0.15604 0 0 0</pose>
<mass>0.042898</mass>
<inertia><ixx>2.33892e-05</ixx><ixy>1.80265e-06</ixy><ixz>-1.95873e-06</ixz><iyy>1.58135e-05</iyy><iyz>-3.46013e-19</iyz><izz>3.00983e-05</izz></inertia>
</inertial>
</link>

<link name="right_humerus_1">
<frame name="right_humerus_1_frame"><pose>0 0 0 0 -0 0</pose></frame>
<collision name="right_humerus_1_3_humerus_plate_collision_1">
<pose>-0.109087 -0.014627 0.0389 1.5708 -4.00903e-17 -1.5708</pose>
<geometry>
<box><size>0.003 0.07 0.03</size></box>
</geometry>
</collision>
<collision name="right_humerus_1_3_humerus_plate_collision_2">
<pose>-0.109087 -0.030627 0.0769 1.5708 -4.00903e-17 -1.5708</pose>
<geometry>
<box><size>0.03 0.003 0.03</size></box>
</geometry>
</collision>
<collision name="right_humerus_1_7_mx64_collision_1">
<pose>-0.109087 -0.031127 0.1159 1.5708 -1.8792e-17 8.54838e-14</pose>
<geometry>
<box><size>0.029 0.05 0.04</size></box>
</geometry>
</collision>
<visual name="right_humerus_1_visual">
<pose>0 0 0 0 -0 0</pose>
<geometry>
<mesh><uri>file://right_humerus_1.stl</uri></mesh>
</geometry>
<material><ambient>0.363401 0.358167 0.34376 1</ambient><diffuse>0.363401 0.358167 0.34376 1</diffuse><specular>0.1 0.1 0.1 1</specular><emissive>0 0 0 0</emissive></material>
</visual>
<inertial>
<pose frame="right_humerus_1_frame">-0.108043 -0.0292607 0.0932601 0 0 0</pose>
<mass>0.214223</mass>
<inertia><ixx>0.000335074</ixx><ixy>2.98809e-06</ixy><ixz>1.0013e-05</ixz><iyy>0.000332796</iyy><iyz>1.45378e-05</iyz><izz>7.82667e-05</izz></inertia>
</inertial>
</link>

<link name="right_radius_1">
<frame name="right_radius_1_frame"><pose>0 0 0 0 -0 0</pose></frame>
<collision name="right_radius_1_2_radius_plate_collision_1">
<pose>-0.109087 -0.034127 -0.0796 1.5708 -3.01274e-16 -1.5708</pose>
<geometry>
<box><size>0.003 0.085 0.03</size></box>
</geometry>
</collision>
<collision name="right_radius_1_2_radius_plate_collision_2">
<pose>-0.109087 -0.044627 -0.1221 1.5708 -3.01274e-16 -1.5708</pose>
<geometry>
<cylinder><length>0.03</length><radius>0.012</radius></cylinder>
</geometry>
</collision>
<collision name="right_radius_1_4_mx64_collision_1">
<pose>-0.109087 -0.052127 0.00389996 1.5708 -4.00903e-17 -1.5708</pose>
<geometry>
<box><size>0.029 0.05 0.04</size></box>
</geometry>
</collision>
<visual name="right_radius_1_visual">
<pose>0 0 0 0 -0 0</pose>
<geometry>
<mesh><uri>file://right_radius_1.stl</uri></mesh>
</geometry>
<material><ambient>0.330671 0.326648 0.315918 1</ambient><diffuse>0.330671 0.326648 0.315918 1</diffuse><specular>0.1 0.1 0.1 1</specular><emissive>0 0 0 0</emissive></material>
</visual>
<inertial>
<pose frame="right_radius_1_frame">-0.108951 -0.0497915 -0.0181398 0 0 0</pose>
<mass>0.20688</mass>
<inertia><ixx>0.00029654</ixx><ixy>6.16695e-06</ixy><ixz>-7.02898e-06</ixz><iyy>0.000368643</iyy><iyz>3.08971e-05</iyz><izz>0.000131704</izz></inertia>
</inertial>
</link>

<joint name="right_elbow" type="revolute">
<pose>-0.132587 -0.052127 0.0189 1.5708 -4.00903e-17 -1.5708</pose>
<parent>right_humerus_1</parent>
<child>right_radius_1</child>
<axis>
<xyz>-0 -0 -1</xyz>
<limit><effort>10</effort><velocity>6</velocity></limit>
</axis>
</joint>

<joint name="right_shoulder_roll" type="revolute">
<pose>-0.109087 -0.054627 0.1309 1.5708 -1.8792e-17 8.54838e-14</pose>
<parent>u_shoulder_2</parent>
<child>right_humerus_1</child>
<axis>
<xyz>0 0 1</xyz>
<limit><effort>10</effort><velocity>6</velocity></limit>
</axis>
</joint>

<joint name="right_shoulder_pitch" type="revolute">
<pose>-0.0740868 -0.032127 0.1609 -1.5708 -6.38201e-16 1.5708</pose>
<parent>tronc</parent>
<child>u_shoulder_2</child>
<axis>
<xyz>0 0 -1</xyz>
<limit><effort>10</effort><velocity>6</velocity></limit>
</axis>
</joint>

<link name="u_neck_1">
<frame name="u_neck_1_frame"><pose>0 0 0 0 -0 0</pose></frame>
<collision name="u_neck_1_0_u_base_64_collision_1">
<pose>2.67834e-14 -0.037127 0.1888 1.12133e-14 -2.28241e-15 -3.14159</pose>
<geometry>
<box><size>0.047 0.0275 0.006</size></box>
</geometry>
</collision>
<collision name="u_neck_1_1_u_side_small_collision_1">
<pose>0.025 -0.037127 0.2088 1.5708 -1.15425e-14 -1.5708</pose>
<geometry>
<box><size>0.025 0.044 0.003</size></box>
</geometry>
</collision>
<collision name="u_neck_1_2_u_side_small_collision_1">
<pose>-0.025 -0.037127 0.2088 1.5708 1.19741e-14 1.5708</pose>
<geometry>
<box><size>0.025 0.044 0.003</size></box>
</geometry>
</collision>
<visual name="u_neck_1_visual">
<pose>0 0 0 0 -0 0</pose>
<geometry>
<mesh><uri>file://u_neck_1.stl</uri></mesh>
</geometry>
<material><ambient>0.301961 0.301961 0.301961 1</ambient><diffuse>0.301961 0.301961 0.301961 1</diffuse><specular>0.1 0.1 0.1 1</specular><emissive>0 0 0 0</emissive></material>
</visual>
<inertial>
<pose frame="u_neck_1_frame">2.68054e-14 -0.037127 0.198692 0 0 0</pose>
<mass>0.0362092</mass>
<inertia><ixx>6.41955e-06</ixx><ixy>4.27371e-12</ixy><ixz>3.64701e-13</ixz><iyy>2.38199e-05</iyy><iyz>1.39399e-20</iyz><izz>2.02973e-05</izz></inertia>
</inertial>
</link>

<link name="head_1">
<frame name="head_1_frame"><pose>0 0 0 0 -0 0</pose></frame>
<collision name="head_1_3_head_plate_collision_1">
<pose>0.0185 0.000373 0.2956 1.5708 1.10158e-13 -1.5708</pose>
<geometry>
<box><size>0.008 0.05 0.003</size></box>
</geometry>
</collision>
<collision name="head_1_3_head_plate_collision_2">
<pose>0.0185 -0.037127 0.2956 1.5708 1.10158e-13 -1.5708</pose>
<geometry>
<box><size>0.008 0.05 0.003</size></box>
</geometry>
</collision>
<collision name="head_1_3_head_plate_collision_3">
<pose>0.0185 -0.074627 0.2956 1.5708 1.10158e-13 -1.5708</pose>
<geometry>
<box><size>0.008 0.05 0.003</size></box>
</geometry>
</collision>
<collision name="head_1_3_head_plate_collision_4">
<pose>0.0185 -0.037127 0.2726 1.5708 1.10158e-13 -1.5708</pose>
<geometry>
<box><size>0.083 0.008 0.003</size></box>
</geometry>
</collision>
<collision name="head_1_3_head_plate_collision_5">
<pose>0.0185 -0.037127 0.2956 1.5708 1.10158e-13 -1.5708</pose>
<geometry>
<box><size>0.083 0.008 0.003</size></box>
</geometry>
</collision>
<collision name="head_1_3_head_plate_collision_6">
<pose>0.0185 -0.037127 0.3186 1.5708 1.10158e-13 -1.5708</pose>
<geometry>
<box><size>0.083 0.008 0.003</size></box>
</geometry>
</collision>
<collision name="head_1_4_ptgrey_camera_collision_1">
<pose>7.40131e-15 -0.0420952 0.29485 1.12283e-13 3.18082e-15 8.38209e-14</pose>
<geometry>
<box><size>0.03 0.03 0.028</size></box>
</geometry>
</collision>
<collision name="head_1_5_head_plate_collision_1">
<pose>-0.0185 0.000373 0.2956 1.5708 1.1564e-13 -1.5708</pose>
<geometry>
<box><size>0.008 0.05 0.003</size></box>
</geometry>
</collision>
<collision name="head_1_5_head_plate_collision_2">
<pose>-0.0185 -0.037127 0.2956 1.5708 1.1564e-13 -1.5708</pose>
<geometry>
<box><size>0.008 0.05 0.003</size></box>
</geometry>
</collision>
<collision name="head_1_5_head_plate_collision_3">
<pose>-0.0185 -0.074627 0.2956 1.5708 1.1564e-13 -1.5708</pose>
<geometry>
<box><size>0.008 0.05 0.003</size></box>
</geometry>
</collision>
<collision name="head_1_5_head_plate_collision_4">
<pose>-0.0185 -0.037127 0.2726 1.5708 1.1564e-13 -1.5708</pose>
<geometry>
<box><size>0.083 0.008 0.003</size></box>
</geometry>
</collision>
<collision name="head_1_5_head_plate_collision_5">
<pose>-0.0185 -0.037127 0.2956 1.5708 1.1564e-13 -1.5708</pose>
<geometry>
<box><size>0.083 0.008 0.003</size></box>
</geometry>
</collision>
<collision name="head_1_5_head_plate_collision_6">
<pose>-0.0185 -0.037127 0.3186 1.5708 1.1564e-13 -1.5708</pose>
<geometry>
<box><size>0.083 0.008 0.003</size></box>
</geometry>
</collision>
<collision name="head_1_7_mx64_collision_1">
<pose>1.69274e-14 -0.037127 0.2408 -1.5708 -1.19741e-14 -1.5708</pose>
<geometry>
<box><size>0.029 0.05 0.04</size></box>
</geometry>
</collision>
<visual name="head_1_visual">
<pose>0 0 0 0 -0 0</pose>
<geometry>
<mesh><uri>file://head_1.stl</uri></mesh>
</geometry>
<material><ambient>0.384901 0.378788 0.360771 1</ambient><diffuse>0.384901 0.378788 0.360771 1</diffuse><specular>0.1 0.1 0.1 1</specular><emissive>0 0 0 0</emissive></material>
</visual>
<inertial>
<pose frame="head_1_frame">-0.000220887 -0.0384008 0.260152 0 0 0</pose>
<mass>0.228227</mass>
<inertia><ixx>0.000204774</ixx><ixy>-5.99156e-06</ixy><ixz>-6.51603e-06</ixz><iyy>0.000251524</iyy><iyz>7.61451e-06</iyz><izz>0.000103974</izz></inertia>
</inertial>
</link>

<link name="camera">
<pose>0 0 0 0 0 0</pose>
<inertial>
<pose>0 0 0 0 0 0</pose>
<mass>1e-9</mass>
<inertia>
<ixx>0</ixx><ixy>0</ixy><ixz>0</ixz><iyy>0</iyy><iyz>0</iyz><izz>0</izz>
</inertia>
</inertial>
</link>
<joint name="camera_frame" type="floating">
<pose>9.02158e-15 -0.06206 0.29485 -1.5708 -3.22939e-15 -3.14159</pose>
<parent>head_1</parent>
<child>camera</child>
</joint>

<link name="vive">
<pose>0 0 0 0 0 0</pose>
<inertial>
<pose>0 0 0 0 0 0</pose>
<mass>1e-9</mass>
<inertia>
<ixx>0</ixx><ixy>0</ixy><ixz>0</ixz><iyy>0</iyy><iyz>0</iyz><izz>0</izz>
</inertia>
</inertial>
</link>
<joint name="vive_frame" type="floating">
<pose>7.13318e-15 -0.037127 0.3256 2.33017e-15 -1.09718e-13 1.5708</pose>
<parent>head_1</parent>
<child>vive</child>
</joint>

<joint name="head_pitch" type="revolute">
<pose>0.0235 -0.037127 0.2258 -1.5708 -1.19741e-14 -1.5708</pose>
<parent>u_neck_1</parent>
<child>head_1</child>
<axis>
<xyz>0 0 1</xyz>
<limit><effort>10</effort><velocity>6</velocity></limit>
</axis>
</joint>

<joint name="head_yaw" type="revolute">
<pose>2.67834e-14 -0.037127 0.1858 1.12133e-14 -2.28241e-15 -3.14159</pose>
<parent>tronc</parent>
<child>u_neck_1</child>
<axis>
<xyz>-0 -0 1</xyz>
<limit><effort>10</effort><velocity>6</velocity></limit>
</axis>
</joint>


</model>
</sdf>
