<robot name="onshape">
<link name="tronc">
<collision>
<origin xyz="-0.031 -0.054127 0.0909" rpy="1.80079e-24 -1.48609e-23 8.63328e-14" />
<geometry>
<cylinder length="0.086" radius="0.004" />
</geometry>
</collision>
<visual>
<origin xyz="-0.031 -0.054127 0.0909" rpy="1.80079e-24 -1.48609e-23 8.63328e-14" />
<geometry>
<cylinder length="0.086" radius="0.004" />
</geometry>
<material name="pillar_tube_material">
<color rgba="0.501961 0.486275 0.439216 1.0"/>
</material>
</visual>
<collision>
<origin xyz="-0.046375 -0.026254 0.02" rpy="3.14159 1.48613e-23 -3.14159" />
<geometry>
<box size="0.029 0.05 0.04" />
</geometry>
</collision>
<visual>
<origin xyz="-0.046375 -0.026254 0.02" rpy="3.14159 1.48613e-23 -3.14159" />
<geometry>
<box size="0.029 0.05 0.04" />
</geometry>
<material name="mx64_material">
<color rgba="0.211765 0.211765 0.211765 1.0"/>
</material>
</visual>
<collision>
<origin xyz="0.05 -0.017127 0.1609" rpy="-3.14159 -1.5708 0" />
<geometry>
<box size="0.029 0.05 0.04" />
</geometry>
</collision>
<visual>
<origin xyz="0.05 -0.017127 0.1609" rpy="-3.14159 -1.5708 0" />
<geometry>
<box size="0.029 0.05 0.04" />
</geometry>
<material name="mx64_material">
<color rgba="0.211765 0.211765 0.211765 1.0"/>
</material>
</visual>
<collision>
<origin xyz="0.046375 -0.026254 0.02" rpy="3.14159 1.48609e-23 -3.14159" />
<geometry>
<box size="0.029 0.05 0.04" />
</geometry>
</collision>
<visual>
<origin xyz="0.046375 -0.026254 0.02" rpy="3.14159 1.48609e-23 -3.14159" />
<geometry>
<box size="0.029 0.05 0.04" />
</geometry>
<material name="mx64_material">
<color rgba="0.211765 0.211765 0.211765 1.0"/>
</material>
</visual>
<collision>
<origin xyz="7.29591e-15 0.071323 0.1899" rpy="1.5708 1.5708 0" />
<geometry>
<box size="0.01 0.13 0.003" />
</geometry>
</collision>
<collision>
<origin xyz="-0.06 0.071323 0.1649" rpy="1.5708 1.5708 0" />
<geometry>
<box size="0.04 0.01 0.003" />
</geometry>
</collision>
<collision>
<origin xyz="0.06 0.071323 0.1649" rpy="1.5708 1.5708 0" />
<geometry>
<box size="0.04 0.01 0.003" />
</geometry>
</collision>
<visual>
<origin xyz="7.29591e-15 0.071323 0.1899" rpy="1.5708 1.5708 0" />
<geometry>
<box size="0.01 0.13 0.003" />
</geometry>
<material name="handle_material">
<color rgba="0.701961 0.682353 0.623529 1.0"/>
</material>
</visual>
<visual>
<origin xyz="-0.06 0.071323 0.1649" rpy="1.5708 1.5708 0" />
<geometry>
<box size="0.04 0.01 0.003" />
</geometry>
<material name="handle_material">
<color rgba="0.701961 0.682353 0.623529 1.0"/>
</material>
</visual>
<visual>
<origin xyz="0.06 0.071323 0.1649" rpy="1.5708 1.5708 0" />
<geometry>
<box size="0.04 0.01 0.003" />
</geometry>
<material name="handle_material">
<color rgba="0.701961 0.682353 0.623529 1.0"/>
</material>
</visual>
<collision>
<origin xyz="0.0625 0.037873 0.0909" rpy="-3.14159 -1.48609e-23 8.63328e-14" />
<geometry>
<cylinder length="0.086" radius="0.004" />
</geometry>
</collision>
<visual>
<origin xyz="0.0625 0.037873 0.0909" rpy="-3.14159 -1.48609e-23 8.63328e-14" />
<geometry>
<cylinder length="0.086" radius="0.004" />
</geometry>
<material name="pillar_tube_material">
<color rgba="0.501961 0.486275 0.439216 1.0"/>
</material>
</visual>
<collision>
<origin xyz="-0.0505868 -0.017127 0.1609" rpy="3.14159 1.5708 0" />
<geometry>
<box size="0.029 0.05 0.04" />
</geometry>
</collision>
<visual>
<origin xyz="-0.0505868 -0.017127 0.1609" rpy="3.14159 1.5708 0" />
<geometry>
<box size="0.029 0.05 0.04" />
</geometry>
<material name="mx64_material">
<color rgba="0.211765 0.211765 0.211765 1.0"/>
</material>
</visual>
<collision>
<origin xyz="1.52206e-14 -0.019127 0.1354" rpy="3.14159 1.48609e-23 -3.14159" />
<geometry>
<box size="0.13 0.08 0.003" />
</geometry>
</collision>
<visual>
<origin xyz="1.52206e-14 -0.019127 0.1354" rpy="3.14159 1.48609e-23 -3.14159" />
<geometry>
<box size="0.13 0.08 0.003" />
</geometry>
<material name="torso_top_plate_nuc_material">
<color rgba="0.301961 0.301961 0.301961 1.0"/>
</material>
</visual>
<collision>
<origin xyz="1.27053e-14 0.010373 0.0469" rpy="1.78736e-24 -1.48609e-23 8.63328e-14" />
<geometry>
<box size="0.13 0.08 0.003" />
</geometry>
</collision>
<visual>
<origin xyz="1.27053e-14 0.010373 0.0469" rpy="1.78736e-24 -1.48609e-23 8.63328e-14" />
<geometry>
<box size="0.13 0.08 0.003" />
</geometry>
<material name="torso_middle_plate_nuc_material">
<color rgba="0.301961 0.301961 0.301961 1.0"/>
</material>
</visual>
<collision>
<origin xyz="-0.0625 0.037873 0.0909" rpy="1.80079e-24 -1.48609e-23 8.63328e-14" />
<geometry>
<cylinder length="0.086" radius="0.004" />
</geometry>
</collision>
<visual>
<origin xyz="-0.0625 0.037873 0.0909" rpy="1.80079e-24 -1.48609e-23 8.63328e-14" />
<geometry>
<cylinder length="0.086" radius="0.004" />
</geometry>
<material name="pillar_tube_material">
<color rgba="0.501961 0.486275 0.439216 1.0"/>
</material>
</visual>
<collision>
<origin xyz="1.24036e-14 0.035873 0.10615" rpy="1.5708 1.48609e-23 -3.14159" />
<geometry>
<box size="0.11 0.11 0.033" />
</geometry>
</collision>
<visual>
<origin xyz="1.24036e-14 0.035873 0.10615" rpy="1.5708 1.48609e-23 -3.14159" />
<geometry>
<box size="0.11 0.11 0.033" />
</geometry>
<material name="nuc_material">
<color rgba="0.301961 0.290196 0.262745 1.0"/>
</material>
</visual>
<collision>
<origin xyz="2.07506e-14 0.031123 0.00149996" rpy="-1.88432e-18 -5.37577e-17 8.62212e-14" />
<geometry>
<box size="0.13 0.044 0.003" />
</geometry>
</collision>
<collision>
<origin xyz="-0.03 -0.007877 0.00149996" rpy="-1.88432e-18 -5.37577e-17 8.62212e-14" />
<geometry>
<box size="0.01 0.035 0.003" />
</geometry>
</collision>
<collision>
<origin xyz="0.03 -0.007877 0.00149996" rpy="-1.88432e-18 -5.37577e-17 8.62212e-14" />
<geometry>
<box size="0.01 0.035 0.003" />
</geometry>
</collision>
<visual>
<origin xyz="2.07506e-14 0.031123 0.00149996" rpy="-1.88432e-18 -5.37577e-17 8.62212e-14" />
<geometry>
<box size="0.13 0.044 0.003" />
</geometry>
<material name="torso_bottom_plate_nuc_material">
<color rgba="0.4 0.4 0.4 1.0"/>
</material>
</visual>
<visual>
<origin xyz="-0.03 -0.007877 0.00149996" rpy="-1.88432e-18 -5.37577e-17 8.62212e-14" />
<geometry>
<box size="0.01 0.035 0.003" />
</geometry>
<material name="torso_bottom_plate_nuc_material">
<color rgba="0.4 0.4 0.4 1.0"/>
</material>
</visual>
<visual>
<origin xyz="0.03 -0.007877 0.00149996" rpy="-1.88432e-18 -5.37577e-17 8.62212e-14" />
<geometry>
<box size="0.01 0.035 0.003" />
</geometry>
<material name="torso_bottom_plate_nuc_material">
<color rgba="0.4 0.4 0.4 1.0"/>
</material>
</visual>
<collision>
<origin xyz="8.35455e-15 0.059373 0.1384" rpy="-3.14159 1.79405e-24 -1.5708" />
<geometry>
<box size="0.01 0.135 0.003" />
</geometry>
</collision>
<visual>
<origin xyz="8.35455e-15 0.059373 0.1384" rpy="-3.14159 1.79405e-24 -1.5708" />
<geometry>
<box size="0.01 0.135 0.003" />
</geometry>
<material name="nuc_fix_material">
<color rgba="0.301961 0.301961 0.301961 1.0"/>
</material>
</visual>
<collision>
<origin xyz="2.55418e-14 -0.022127 0.1623" rpy="1.12133e-14 -2.28241e-15 -3.14159" />
<geometry>
<box size="0.029 0.05 0.04" />
</geometry>
</collision>
<visual>
<origin xyz="2.55418e-14 -0.022127 0.1623" rpy="1.12133e-14 -2.28241e-15 -3.14159" />
<geometry>
<box size="0.029 0.05 0.04" />
</geometry>
<material name="mx64_material">
<color rgba="0.211765 0.211765 0.211765 1.0"/>
</material>
</visual>
<collision>
<origin xyz="0.031 -0.054127 0.0914" rpy="1.80079e-24 -1.48609e-23 8.63328e-14" />
<geometry>
<cylinder length="0.086" radius="0.004" />
</geometry>
</collision>
<visual>
<origin xyz="0.031 -0.054127 0.0914" rpy="1.80079e-24 -1.48609e-23 8.63328e-14" />
<geometry>
<cylinder length="0.086" radius="0.004" />
</geometry>
<material name="pillar_tube_material">
<color rgba="0.501961 0.486275 0.439216 1.0"/>
</material>
</visual>
<inertial>
<origin xyz="0.000185565 0.00052958 0.0922428" rpy="0 0 0"/>
<mass value="1.75912" />
<inertia ixx="0.00823896" ixy="2.57494e-06"  ixz="1.9734e-05" iyy="0.00915867" iyz="-0.000169433" izz="0.00511156" />
</inertial>
</link>

<link name="trunk">
<inertial>
<origin xyz="0 0 0" rpy="0 0 0" />
<mass value="1e-9" />
<inertia ixx="0" ixy="0" ixz="0" iyy="0" iyz="0" izz="0" />
</inertial>
</link>
<joint name="trunk_frame" type="floating">
<origin xyz="2.43796e-14 -0.011254 -0.0435" rpy="-5.7251e-17 -1.88432e-18 -1.5708" />
<parent link="tronc" />
<child link="trunk" />
<axis xyz="0 0 0"/>
</joint>

<link name="head_base">
<inertial>
<origin xyz="0 0 0" rpy="0 0 0" />
<mass value="1e-9" />
<inertia ixx="0" ixy="0" ixz="0" iyy="0" iyz="0" izz="0" />
</inertial>
</link>
<joint name="head_base_frame" type="floating">
<origin xyz="2.67832e-14 -0.037127 0.1858" rpy="2.77556e-17 1.38778e-17 -1.5708" />
<parent link="tronc" />
<child link="head_base" />
<axis xyz="0 0 0"/>
</joint>

<link name="u_block_1">
<collision>
<origin xyz="-0.00494 0 0.003" rpy="-7.30373e-33 3.5853e-41 -3.12137e-42" />
<geometry>
<box size="0.05 0.03 0.006" />
</geometry>
</collision>
<visual>
<origin xyz="-0.00494 0 0.003" rpy="-7.30373e-33 3.5853e-41 -3.12137e-42" />
<geometry>
<box size="0.05 0.03 0.006" />
</geometry>
<material name="u_base_motors_blocs_material">
<color rgba="0.301961 0.301961 0.301961 1.0"/>
</material>
</visual>
<collision>
<origin xyz="-0.03144 3.46945e-17 0.023" rpy="1.5708 -9.35682e-17 1.5708" />
<geometry>
<box size="0.025 0.044 0.003" />
</geometry>
</collision>
<visual>
<origin xyz="-0.03144 3.46945e-17 0.023" rpy="1.5708 -9.35682e-17 1.5708" />
<geometry>
<box size="0.025 0.044 0.003" />
</geometry>
<material name="u_side_small_material">
<color rgba="0.301961 0.301961 0.301961 1.0"/>
</material>
</visual>
<collision>
<origin xyz="0.0219 -4.33681e-17 0.023" rpy="1.5708 -3.9526e-17 -1.5708" />
<geometry>
<box size="0.027 0.042 0.003" />
</geometry>
</collision>
<visual>
<origin xyz="0.0219 -4.33681e-17 0.023" rpy="1.5708 -3.9526e-17 -1.5708" />
<geometry>
<box size="0.027 0.042 0.003" />
</geometry>
<material name="u_side_small_with_trace_material">
<color rgba="0.301961 0.301961 0.301961 1.0"/>
</material>
</visual>
<inertial>
<origin xyz="-0.00607049 2.12569e-09 0.0117654" rpy="0 0 0"/>
<mass value="0.0354404" />
<inertia ixx="6.0236e-06" ixy="-2.05966e-08"  ixz="7.97442e-07" iyy="2.4343e-05" iyz="-8.88603e-13" izz="2.1328e-05" />
</inertial>
</link>

<link name="mx106_block_mir_1">
<collision>
<origin xyz="-1.72422e-14 -0.015 0.0234" rpy="2.89425e-13 -1.5708 0" />
<geometry>
<box size="0.03 0.055 0.04" />
</geometry>
</collision>
<visual>
<origin xyz="-1.72422e-14 -0.015 0.0234" rpy="2.89425e-13 -1.5708 0" />
<geometry>
<box size="0.03 0.055 0.04" />
</geometry>
<material name="mx106_material">
<color rgba="0.301961 0.301961 0.301961 1.0"/>
</material>
</visual>
<collision>
<origin xyz="2.74835e-31 -0.015 -0.026" rpy="-1.68105e-40 3.81268e-29 -1.37931e-29" />
<geometry>
<box size="0.03 0.055 0.04" />
</geometry>
</collision>
<visual>
<origin xyz="2.74835e-31 -0.015 -0.026" rpy="-1.68105e-40 3.81268e-29 -1.37931e-29" />
<geometry>
<box size="0.03 0.055 0.04" />
</geometry>
<material name="mx106_material">
<color rgba="0.301961 0.301961 0.301961 1.0"/>
</material>
</visual>
<inertial>
<origin xyz="-0.000304417 -0.018098 0.00391715" rpy="0 0 0"/>
<mass value="0.427481" />
<inertia ixx="0.000482208" ixy="-1.57792e-05"  ixz="3.50396e-06" iyy="0.000408392" iyz="-3.68837e-05" izz="0.000203671" />
</inertial>
</link>

<link name="right_knee_1">
<collision>
<origin xyz="1.04229e-16 -0.0395 0.0535" rpy="4.996e-16 -2.77556e-16 1.32533e-15" />
<geometry>
<box size="0.04 0.09 0.003" />
</geometry>
</collision>
<visual>
<origin xyz="1.04229e-16 -0.0395 0.0535" rpy="4.996e-16 -2.77556e-16 1.32533e-15" />
<geometry>
<box size="0.04 0.09 0.003" />
</geometry>
<material name="u_side_femur_mir_material">
<color rgba="0.301961 0.301961 0.301961 1.0"/>
</material>
</visual>
<collision>
<origin xyz="2.53143e-14 -0.125 0.026" rpy="-3.14159 -1.81887e-16 4.5397e-13" />
<geometry>
<box size="0.03 0.055 0.04" />
</geometry>
</collision>
<visual>
<origin xyz="2.53143e-14 -0.125 0.026" rpy="-3.14159 -1.81887e-16 4.5397e-13" />
<geometry>
<box size="0.03 0.055 0.04" />
</geometry>
<material name="mx106_material">
<color rgba="0.301961 0.301961 0.301961 1.0"/>
</material>
</visual>
<collision>
<origin xyz="4.15808e-32 -0.0395 -0.0015" rpy="-3.64812e-34 3.52046e-29 -2.74809e-32" />
<geometry>
<box size="0.04 0.09 0.003" />
</geometry>
</collision>
<visual>
<origin xyz="4.15808e-32 -0.0395 -0.0015" rpy="-3.64812e-34 3.52046e-29 -2.74809e-32" />
<geometry>
<box size="0.04 0.09 0.003" />
</geometry>
<material name="u_side_femur_material">
<color rgba="0.301961 0.301961 0.301961 1.0"/>
</material>
</visual>
<collision>
<origin xyz="3.71606e-16 -0.0825 0.026" rpy="-1.5708 1.5708 0" />
<geometry>
<box size="0.047 0.0275 0.006" />
</geometry>
</collision>
<visual>
<origin xyz="3.71606e-16 -0.0825 0.026" rpy="-1.5708 1.5708 0" />
<geometry>
<box size="0.047 0.0275 0.006" />
</geometry>
<material name="u_base_64_material">
<color rgba="0.301961 0.301961 0.301961 1.0"/>
</material>
</visual>
<inertial>
<origin xyz="0.000224336 -0.0980339 0.0257133" rpy="0 0 0"/>
<mass value="0.269758" />
<inertia ixx="0.000503595" ixy="9.05865e-07"  ixz="-4.56779e-07" iyy="0.000109941" iyz="-5.72119e-06" izz="0.000438644" />
</inertial>
</link>

<link name="tibia_1">
<collision>
<origin xyz="-1.50984e-32 -0.067 0.0015" rpy="0 2.39826e-29 0" />
<geometry>
<box size="0.03 0.165 0.003" />
</geometry>
</collision>
<visual>
<origin xyz="-1.50984e-32 -0.067 0.0015" rpy="0 2.39826e-29 0" />
<geometry>
<box size="0.03 0.165 0.003" />
</geometry>
<material name="tibia_plate_material">
<color rgba="0.301961 0.301961 0.301961 1.0"/>
</material>
</visual>
<collision>
<origin xyz="5.06057e-18 -0.067 -0.0535" rpy="1.66533e-15 3.60822e-16 -1.11022e-16" />
<geometry>
<box size="0.03 0.165 0.003" />
</geometry>
</collision>
<visual>
<origin xyz="5.06057e-18 -0.067 -0.0535" rpy="1.66533e-15 3.60822e-16 -1.11022e-16" />
<geometry>
<box size="0.03 0.165 0.003" />
</geometry>
<material name="tibia_plate_material">
<color rgba="0.301961 0.301961 0.301961 1.0"/>
</material>
</visual>
<inertial>
<origin xyz="-0.00342169 -0.0646068 -0.026" rpy="0 0 0"/>
<mass value="0.0888437" />
<inertia ixx="0.000245247" ixy="6.12719e-06"  ixz="-1.44286e-11" iyy="7.67255e-05" iyz="3.8066e-11" izz="0.000187463" />
</inertial>
</link>

<link name="mx106_block_1">
<collision>
<origin xyz="1.63291e-31 -0.015 -0.026" rpy="4.45602e-32 -1.04974e-29 -5.28557e-30" />
<geometry>
<box size="0.03 0.055 0.04" />
</geometry>
</collision>
<visual>
<origin xyz="1.63291e-31 -0.015 -0.026" rpy="4.45602e-32 -1.04974e-29 -5.28557e-30" />
<geometry>
<box size="0.03 0.055 0.04" />
</geometry>
<material name="mx106_material">
<color rgba="0.301961 0.301961 0.301961 1.0"/>
</material>
</visual>
<collision>
<origin xyz="0.0494 -0.015 -0.026" rpy="7.80481e-16 -1.5708 0" />
<geometry>
<box size="0.03 0.055 0.04" />
</geometry>
</collision>
<visual>
<origin xyz="0.0494 -0.015 -0.026" rpy="7.80481e-16 -1.5708 0" />
<geometry>
<box size="0.03 0.055 0.04" />
</geometry>
<material name="mx106_material">
<color rgba="0.301961 0.301961 0.301961 1.0"/>
</material>
</visual>
<inertial>
<origin xyz="0.0195884 -0.018098 -0.0258252" rpy="0 0 0"/>
<mass value="0.427481" />
<inertia ixx="0.000194682" ixy="1.88861e-05"  ixz="4.22317e-07" iyy="0.000410191" iyz="-2.22493e-06" izz="0.000485925" />
</inertial>
</link>

<link name="right_foot_cleat_back_left">
<collision>
<origin xyz="-0.0435 -0.05 -0.03213" rpy="-1.5708 0.199727 3.14159" />
<geometry>
<cylinder length="0.02" radius="0.008" />
</geometry>
</collision>
<visual>
<origin xyz="-0.0435 -0.05 -0.03213" rpy="-1.5708 0.199727 3.14159" />
<geometry>
<cylinder length="0.02" radius="0.008" />
</geometry>
<material name="cleat_material">
<color rgba="0.301961 0.290196 0.262745 1.0"/>
</material>
</visual>
<collision>
<origin xyz="-0.0435 -0.05 0.10947" rpy="-1.5708 0.199727 3.14159" />
<geometry>
<cylinder length="0.02" radius="0.008" />
</geometry>
</collision>
<visual>
<origin xyz="-0.0435 -0.05 0.10947" rpy="-1.5708 0.199727 3.14159" />
<geometry>
<cylinder length="0.02" radius="0.008" />
</geometry>
<material name="cleat_material">
<color rgba="0.301961 0.290196 0.262745 1.0"/>
</material>
</visual>
<collision>
<origin xyz="6.76542e-17 -0.017 0.05484" rpy="-3.14159 -2.42855e-17 3.14159" />
<geometry>
<box size="0.025 0.044 0.003" />
</geometry>
</collision>
<visual>
<origin xyz="6.76542e-17 -0.017 0.05484" rpy="-3.14159 -2.42855e-17 3.14159" />
<geometry>
<box size="0.025 0.044 0.003" />
</geometry>
<material name="u_side_small_material">
<color rgba="0.301961 0.301961 0.301961 1.0"/>
</material>
</visual>
<collision>
<origin xyz="0.0325 -0.05 0.10947" rpy="1.5708 0.555221 -2.37021e-15" />
<geometry>
<cylinder length="0.02" radius="0.008" />
</geometry>
</collision>
<visual>
<origin xyz="0.0325 -0.05 0.10947" rpy="1.5708 0.555221 -2.37021e-15" />
<geometry>
<cylinder length="0.02" radius="0.008" />
</geometry>
<material name="cleat_material">
<color rgba="0.301961 0.290196 0.262745 1.0"/>
</material>
</visual>
<collision>
<origin xyz="-0.0055 -0.0415 0.03867" rpy="1.5708 -2.34865e-17 3.14159" />
<geometry>
<box size="0.09 0.155 0.003" />
</geometry>
</collision>
<visual>
<origin xyz="-0.0055 -0.0415 0.03867" rpy="1.5708 -2.34865e-17 3.14159" />
<geometry>
<box size="0.09 0.155 0.003" />
</geometry>
<material name="foot_plate_material">
<color rgba="0.301961 0.301961 0.301961 1.0"/>
</material>
</visual>
<collision>
<origin xyz="6.93889e-18 -0.017 0.0015" rpy="-1.36882e-30 1.1038e-29 2.36811e-31" />
<geometry>
<box size="0.027 0.042 0.003" />
</geometry>
</collision>
<visual>
<origin xyz="6.93889e-18 -0.017 0.0015" rpy="-1.36882e-30 1.1038e-29 2.36811e-31" />
<geometry>
<box size="0.027 0.042 0.003" />
</geometry>
<material name="u_side_small_with_trace_material">
<color rgba="0.301961 0.301961 0.301961 1.0"/>
</material>
</visual>
<collision>
<origin xyz="0.0325 -0.05 -0.03213" rpy="1.5708 -0.311457 -2.11626e-15" />
<geometry>
<cylinder length="0.02" radius="0.008" />
</geometry>
</collision>
<visual>
<origin xyz="0.0325 -0.05 -0.03213" rpy="1.5708 -0.311457 -2.11626e-15" />
<geometry>
<cylinder length="0.02" radius="0.008" />
</geometry>
<material name="cleat_material">
<color rgba="0.301961 0.290196 0.262745 1.0"/>
</material>
</visual>
<collision>
<origin xyz="-0.0055 -0.0275 0.12247" rpy="3.14159 0.785398 -1.5708" />
<geometry>
<box size="0.01 0.09 0.01" />
</geometry>
</collision>
<visual>
<origin xyz="-0.0055 -0.0275 0.12247" rpy="3.14159 0.785398 -1.5708" />
<geometry>
<box size="0.01 0.09 0.01" />
</geometry>
<material name="foot_protection_material">
<color rgba="0.301961 0.290196 0.262745 1.0"/>
</material>
</visual>
<collision>
<origin xyz="1.73472e-17 -0.037 0.02834" rpy="-1.5708 1.5708 0" />
<geometry>
<box size="0.05 0.03 0.006" />
</geometry>
</collision>
<visual>
<origin xyz="1.73472e-17 -0.037 0.02834" rpy="-1.5708 1.5708 0" />
<geometry>
<box size="0.05 0.03 0.006" />
</geometry>
<material name="u_base_motors_blocs_material">
<color rgba="0.301961 0.301961 0.301961 1.0"/>
</material>
</visual>
<inertial>
<origin xyz="-0.00468466 -0.0365779 0.0511529" rpy="0 0 0"/>
<mass value="0.239067" />
<inertia ixx="0.000644736" ixy="-2.73076e-06"  ixz="4.22638e-06" iyy="0.000780875" iyz="-2.65367e-05" izz="0.000195711" />
</inertial>
</link>

<link name="right_foot">
<inertial>
<origin xyz="0 0 0" rpy="0 0 0" />
<mass value="1e-9" />
<inertia ixx="0" ixy="0" ixz="0" iyy="0" iyz="0" izz="0" />
</inertial>
</link>
<joint name="right_foot_frame" type="floating">
<origin xyz="-5.55112e-17 -0.06 0.02317" rpy="-1.5708 -1.5708 0" />
<parent link="right_foot_cleat_back_left" />
<child link="right_foot" />
<axis xyz="0 0 0"/>
</joint>

<joint name="right_ankle_roll" type="revolute">
<origin xyz="0.0234 -4.55191e-15 -0.026" rpy="3.14159 1.5708 0" />
<parent link="mx106_block_1" />
<child link="right_foot_cleat_back_left" />
<axis xyz="-0 -0 1"/>
<limit effort="10" velocity="6" />
<joint_properties friction="0.0"/>
</joint>

<joint name="right_ankle_pitch" type="revolute">
<origin xyz="1.38778e-17 -0.14 0" rpy="-1.83187e-15 -2.77556e-16 3.14159" />
<parent link="tibia_1" />
<child link="mx106_block_1" />
<axis xyz="-0 -0 -1"/>
<limit effort="10" velocity="6" />
<joint_properties friction="0.0"/>
</joint>

<joint name="right_knee" type="revolute">
<origin xyz="3.21514e-14 -0.14 3.60822e-16" rpy="3.14159 -3.36029e-16 -3.14159" />
<parent link="right_knee_1" />
<child link="tibia_1" />
<axis xyz="0 0 -1"/>
<limit effort="10" velocity="6" />
<joint_properties friction="0.0"/>
</joint>

<joint name="right_hip_pitch" type="revolute">
<origin xyz="-0.026 -1.04222e-14 0.0234" rpy="-2.8919e-13 1.5708 0" />
<parent link="mx106_block_mir_1" />
<child link="right_knee_1" />
<axis xyz="0 0 1"/>
<limit effort="10" velocity="6" />
<joint_properties friction="0.0"/>
</joint>

<joint name="right_hip_roll" type="revolute">
<origin xyz="0.0234 -3.46945e-17 0.04" rpy="-1.5708 -2.89657e-13 1.5708" />
<parent link="u_block_1" />
<child link="mx106_block_mir_1" />
<axis xyz="0 0 1"/>
<limit effort="10" velocity="6" />
<joint_properties friction="0.0"/>
</joint>

<joint name="right_hip_yaw" type="revolute">
<origin xyz="-0.046375 -0.011254 -0.00350004" rpy="3.14159 -1.79404e-24 1.5708" />
<parent link="tronc" />
<child link="u_block_1" />
<axis xyz="0 0 -1"/>
<limit effort="10" velocity="6" />
<joint_properties friction="0.0"/>
</joint>

<link name="u_block_2">
<collision>
<origin xyz="-0.00494 -6.93889e-18 0.003" rpy="1.37852e-32 -3.18039e-32 -6.12454e-30" />
<geometry>
<box size="0.05 0.03 0.006" />
</geometry>
</collision>
<visual>
<origin xyz="-0.00494 -6.93889e-18 0.003" rpy="1.37852e-32 -3.18039e-32 -6.12454e-30" />
<geometry>
<box size="0.05 0.03 0.006" />
</geometry>
<material name="u_base_motors_blocs_material">
<color rgba="0.301961 0.301961 0.301961 1.0"/>
</material>
</visual>
<collision>
<origin xyz="0.0219 -5.20417e-18 0.023" rpy="1.5708 1.91186e-17 -1.5708" />
<geometry>
<box size="0.027 0.042 0.003" />
</geometry>
</collision>
<visual>
<origin xyz="0.0219 -5.20417e-18 0.023" rpy="1.5708 1.91186e-17 -1.5708" />
<geometry>
<box size="0.027 0.042 0.003" />
</geometry>
<material name="u_side_small_with_trace_material">
<color rgba="0.301961 0.301961 0.301961 1.0"/>
</material>
</visual>
<collision>
<origin xyz="-0.03144 -6.93889e-18 0.023" rpy="1.5708 6.60998e-17 1.5708" />
<geometry>
<box size="0.025 0.044 0.003" />
</geometry>
</collision>
<visual>
<origin xyz="-0.03144 -6.93889e-18 0.023" rpy="1.5708 6.60998e-17 1.5708" />
<geometry>
<box size="0.025 0.044 0.003" />
</geometry>
<material name="u_side_small_material">
<color rgba="0.301961 0.301961 0.301961 1.0"/>
</material>
</visual>
<inertial>
<origin xyz="-0.00607049 2.12569e-09 0.0117654" rpy="0 0 0"/>
<mass value="0.0354404" />
<inertia ixx="6.0236e-06" ixy="-2.05966e-08"  ixz="7.97442e-07" iyy="2.4343e-05" iyz="-8.88603e-13" izz="2.1328e-05" />
</inertial>
</link>

<link name="mx106_block_2">
<collision>
<origin xyz="-6.93889e-18 -0.015 -0.026" rpy="-3.62267e-32 -6.45673e-30 -2.33386e-29" />
<geometry>
<box size="0.03 0.055 0.04" />
</geometry>
</collision>
<visual>
<origin xyz="-6.93889e-18 -0.015 -0.026" rpy="-3.62267e-32 -6.45673e-30 -2.33386e-29" />
<geometry>
<box size="0.03 0.055 0.04" />
</geometry>
<material name="mx106_material">
<color rgba="0.301961 0.301961 0.301961 1.0"/>
</material>
</visual>
<collision>
<origin xyz="-1.72918e-14 -0.015 0.0234" rpy="-2.88049e-13 1.5708 0" />
<geometry>
<box size="0.03 0.055 0.04" />
</geometry>
</collision>
<visual>
<origin xyz="-1.72918e-14 -0.015 0.0234" rpy="-2.88049e-13 1.5708 0" />
<geometry>
<box size="0.03 0.055 0.04" />
</geometry>
<material name="mx106_material">
<color rgba="0.301961 0.301961 0.301961 1.0"/>
</material>
</visual>
<inertial>
<origin xyz="0.000174774 -0.018098 0.0038116" rpy="0 0 0"/>
<mass value="0.427481" />
<inertia ixx="0.000480875" ixy="1.44566e-05"  ixz="-4.949e-07" iyy="0.000406226" iyz="-3.86323e-05" izz="0.000203698" />
</inertial>
</link>

<link name="left_knee_1">
<collision>
<origin xyz="6.2117e-17 -0.0825 0.026" rpy="-1.5708 1.5708 0" />
<geometry>
<box size="0.047 0.0275 0.006" />
</geometry>
</collision>
<visual>
<origin xyz="6.2117e-17 -0.0825 0.026" rpy="-1.5708 1.5708 0" />
<geometry>
<box size="0.047 0.0275 0.006" />
</geometry>
<material name="u_base_64_material">
<color rgba="0.301961 0.301961 0.301961 1.0"/>
</material>
</visual>
<collision>
<origin xyz="1.73472e-18 -0.0395 -0.0015" rpy="4.35316e-32 2.13064e-30 1.27058e-31" />
<geometry>
<box size="0.04 0.09 0.003" />
</geometry>
</collision>
<visual>
<origin xyz="1.73472e-18 -0.0395 -0.0015" rpy="4.35316e-32 2.13064e-30 1.27058e-31" />
<geometry>
<box size="0.04 0.09 0.003" />
</geometry>
<material name="u_side_femur_material">
<color rgba="0.301961 0.301961 0.301961 1.0"/>
</material>
</visual>
<collision>
<origin xyz="4.36598e-17 -0.0395 0.0535" rpy="3.26957e-16 3.59516e-17 5.14922e-16" />
<geometry>
<box size="0.04 0.09 0.003" />
</geometry>
</collision>
<visual>
<origin xyz="4.36598e-17 -0.0395 0.0535" rpy="3.26957e-16 3.59516e-17 5.14922e-16" />
<geometry>
<box size="0.04 0.09 0.003" />
</geometry>
<material name="u_side_femur_mir_material">
<color rgba="0.301961 0.301961 0.301961 1.0"/>
</material>
</visual>
<collision>
<origin xyz="-2.4828e-14 -0.125 0.026" rpy="-3.14159 2.98198e-16 -4.53605e-13" />
<geometry>
<box size="0.03 0.055 0.04" />
</geometry>
</collision>
<visual>
<origin xyz="-2.4828e-14 -0.125 0.026" rpy="-3.14159 2.98198e-16 -4.53605e-13" />
<geometry>
<box size="0.03 0.055 0.04" />
</geometry>
<material name="mx106_material">
<color rgba="0.301961 0.301961 0.301961 1.0"/>
</material>
</visual>
<inertial>
<origin xyz="-5.70809e-05 -0.0980339 0.0255274" rpy="0 0 0"/>
<mass value="0.269758" />
<inertia ixx="0.000503557" ixy="1.64719e-06"  ixz="-5.01987e-07" iyy="0.000109916" iyz="-5.37384e-06" izz="0.000438656" />
</inertial>
</link>

<link name="tibia_2">
<collision>
<origin xyz="-5.58374e-31 -0.067 -0.0015" rpy="-4.50026e-32 -6.77291e-30 4.57972e-31" />
<geometry>
<box size="0.03 0.165 0.003" />
</geometry>
</collision>
<visual>
<origin xyz="-5.58374e-31 -0.067 -0.0015" rpy="-4.50026e-32 -6.77291e-30 4.57972e-31" />
<geometry>
<box size="0.03 0.165 0.003" />
</geometry>
<material name="tibia_plate_material">
<color rgba="0.301961 0.301961 0.301961 1.0"/>
</material>
</visual>
<collision>
<origin xyz="2.23209e-16 -0.067 0.0535" rpy="-9.24302e-16 1.29393e-16 -3.04496e-16" />
<geometry>
<box size="0.03 0.165 0.003" />
</geometry>
</collision>
<visual>
<origin xyz="2.23209e-16 -0.067 0.0535" rpy="-9.24302e-16 1.29393e-16 -3.04496e-16" />
<geometry>
<box size="0.03 0.165 0.003" />
</geometry>
<material name="tibia_plate_material">
<color rgba="0.301961 0.301961 0.301961 1.0"/>
</material>
</visual>
<inertial>
<origin xyz="-0.00342169 -0.0646068 0.026" rpy="0 0 0"/>
<mass value="0.0888437" />
<inertia ixx="0.000245247" ixy="6.12719e-06"  ixz="-1.44286e-11" iyy="7.67255e-05" iyz="3.8066e-11" izz="0.000187463" />
</inertial>
</link>

<link name="mx106_block_mir_2">
<collision>
<origin xyz="1.73472e-18 -0.015 -0.026" rpy="0 1.07112e-29 -5.04871e-29" />
<geometry>
<box size="0.03 0.055 0.04" />
</geometry>
</collision>
<visual>
<origin xyz="1.73472e-18 -0.015 -0.026" rpy="0 1.07112e-29 -5.04871e-29" />
<geometry>
<box size="0.03 0.055 0.04" />
</geometry>
<material name="mx106_material">
<color rgba="0.301961 0.301961 0.301961 1.0"/>
</material>
</visual>
<collision>
<origin xyz="-0.0494 -0.015 -0.026" rpy="-4.54893e-13 1.5708 0" />
<geometry>
<box size="0.03 0.055 0.04" />
</geometry>
</collision>
<visual>
<origin xyz="-0.0494 -0.015 -0.026" rpy="-4.54893e-13 1.5708 0" />
<geometry>
<box size="0.03 0.055 0.04" />
</geometry>
<material name="mx106_material">
<color rgba="0.301961 0.301961 0.301961 1.0"/>
</material>
</visual>
<inertial>
<origin xyz="-0.0194829 -0.018098 -0.0256956" rpy="0 0 0"/>
<mass value="0.427481" />
<inertia ixx="0.000194261" ixy="-2.04803e-05"  ixz="-3.71621e-06" iyy="0.000412323" iyz="-3.98084e-06" izz="0.000487688" />
</inertial>
</link>

<link name="left_foot_cleat_front_right">
<collision>
<origin xyz="0.0055 -0.0275 0.12247" rpy="-3.14159 0.785398 -1.5708" />
<geometry>
<box size="0.01 0.09 0.01" />
</geometry>
</collision>
<visual>
<origin xyz="0.0055 -0.0275 0.12247" rpy="-3.14159 0.785398 -1.5708" />
<geometry>
<box size="0.01 0.09 0.01" />
</geometry>
<material name="foot_protection_material">
<color rgba="0.301961 0.290196 0.262745 1.0"/>
</material>
</visual>
<collision>
<origin xyz="0.0435 -0.05 -0.03213" rpy="-1.5708 0.480536 3.14159" />
<geometry>
<cylinder length="0.02" radius="0.008" />
</geometry>
</collision>
<visual>
<origin xyz="0.0435 -0.05 -0.03213" rpy="-1.5708 0.480536 3.14159" />
<geometry>
<cylinder length="0.02" radius="0.008" />
</geometry>
<material name="cleat_material">
<color rgba="0.301961 0.290196 0.262745 1.0"/>
</material>
</visual>
<collision>
<origin xyz="-8.32667e-17 -0.017 0.05484" rpy="-3.14159 -3.72098e-16 -3.14159" />
<geometry>
<box size="0.025 0.044 0.003" />
</geometry>
</collision>
<visual>
<origin xyz="-8.32667e-17 -0.017 0.05484" rpy="-3.14159 -3.72098e-16 -3.14159" />
<geometry>
<box size="0.025 0.044 0.003" />
</geometry>
<material name="u_side_small_material">
<color rgba="0.301961 0.301961 0.301961 1.0"/>
</material>
</visual>
<collision>
<origin xyz="0.0435 -0.05 0.10947" rpy="-1.5708 0.480536 3.14159" />
<geometry>
<cylinder length="0.02" radius="0.008" />
</geometry>
</collision>
<visual>
<origin xyz="0.0435 -0.05 0.10947" rpy="-1.5708 0.480536 3.14159" />
<geometry>
<cylinder length="0.02" radius="0.008" />
</geometry>
<material name="cleat_material">
<color rgba="0.301961 0.290196 0.262745 1.0"/>
</material>
</visual>
<collision>
<origin xyz="-1.73472e-17 -0.037 0.02834" rpy="-1.5708 1.5708 0" />
<geometry>
<box size="0.05 0.03 0.006" />
</geometry>
</collision>
<visual>
<origin xyz="-1.73472e-17 -0.037 0.02834" rpy="-1.5708 1.5708 0" />
<geometry>
<box size="0.05 0.03 0.006" />
</geometry>
<material name="u_base_motors_blocs_material">
<color rgba="0.301961 0.301961 0.301961 1.0"/>
</material>
</visual>
<collision>
<origin xyz="-0.0325 -0.05 0.10947" rpy="-1.5708 0.480536 3.14159" />
<geometry>
<cylinder length="0.02" radius="0.008" />
</geometry>
</collision>
<visual>
<origin xyz="-0.0325 -0.05 0.10947" rpy="-1.5708 0.480536 3.14159" />
<geometry>
<cylinder length="0.02" radius="0.008" />
</geometry>
<material name="cleat_material">
<color rgba="0.301961 0.290196 0.262745 1.0"/>
</material>
</visual>
<collision>
<origin xyz="-0.0325 -0.05 -0.03213" rpy="-1.5708 0.480536 -3.14159" />
<geometry>
<cylinder length="0.02" radius="0.008" />
</geometry>
</collision>
<visual>
<origin xyz="-0.0325 -0.05 -0.03213" rpy="-1.5708 0.480536 -3.14159" />
<geometry>
<cylinder length="0.02" radius="0.008" />
</geometry>
<material name="cleat_material">
<color rgba="0.301961 0.290196 0.262745 1.0"/>
</material>
</visual>
<collision>
<origin xyz="0 -0.017 0.0015" rpy="-1.0102e-28 4.49356e-30 2.31749e-31" />
<geometry>
<box size="0.027 0.042 0.003" />
</geometry>
</collision>
<visual>
<origin xyz="0 -0.017 0.0015" rpy="-1.0102e-28 4.49356e-30 2.31749e-31" />
<geometry>
<box size="0.027 0.042 0.003" />
</geometry>
<material name="u_side_small_with_trace_material">
<color rgba="0.301961 0.301961 0.301961 1.0"/>
</material>
</visual>
<collision>
<origin xyz="0.0055 -0.0415 0.03867" rpy="1.5708 7.48198e-16 -3.14159" />
<geometry>
<box size="0.09 0.155 0.003" />
</geometry>
</collision>
<visual>
<origin xyz="0.0055 -0.0415 0.03867" rpy="1.5708 7.48198e-16 -3.14159" />
<geometry>
<box size="0.09 0.155 0.003" />
</geometry>
<material name="foot_plate_material">
<color rgba="0.301961 0.301961 0.301961 1.0"/>
</material>
</visual>
<inertial>
<origin xyz="0.00468466 -0.0365779 0.0511529" rpy="0 0 0"/>
<mass value="0.239067" />
<inertia ixx="0.000644736" ixy="5.21256e-07"  ixz="-4.22638e-06" iyy="0.000780874" iyz="-2.65367e-05" izz="0.000195711" />
</inertial>
</link>

<link name="left_foot">
<inertial>
<origin xyz="0 0 0" rpy="0 0 0" />
<mass value="1e-9" />
<inertia ixx="0" ixy="0" ixz="0" iyy="0" iyz="0" izz="0" />
</inertial>
</link>
<joint name="left_foot_frame" type="floating">
<origin xyz="-2.498e-16 -0.06 0.02317" rpy="-1.5708 -1.5708 0" />
<parent link="left_foot_cleat_front_right" />
<child link="left_foot" />
<axis xyz="0 0 0"/>
</joint>

<joint name="left_ankle_roll" type="revolute">
<origin xyz="-0.0234 -7.71605e-15 -0.026" rpy="-3.14159 -1.5708 0" />
<parent link="mx106_block_mir_2" />
<child link="left_foot_cleat_front_right" />
<axis xyz="-0 -0 1"/>
<limit effort="10" velocity="6" />
<joint_properties friction="0.0"/>
</joint>

<joint name="left_ankle_pitch" type="revolute">
<origin xyz="1.56125e-17 -0.14 0" rpy="3.14159 1.02268e-16 3.09772e-16" />
<parent link="tibia_2" />
<child link="mx106_block_mir_2" />
<axis xyz="0 0 1"/>
<limit effort="10" velocity="6" />
<joint_properties friction="0.0"/>
</joint>

<joint name="left_knee" type="revolute">
<origin xyz="-3.16396e-14 -0.14 -1.9984e-14" rpy="1.64154e-15 1.88306e-16 -4.53915e-13" />
<parent link="left_knee_1" />
<child link="tibia_2" />
<axis xyz="-0 -0 -1"/>
<limit effort="10" velocity="6" />
<joint_properties friction="0.0"/>
</joint>

<joint name="left_hip_pitch" type="revolute">
<origin xyz="0.026 1.24623e-14 0.0234" rpy="2.88049e-13 -1.5708 0" />
<parent link="mx106_block_2" />
<child link="left_knee_1" />
<axis xyz="-0 -0 -1"/>
<limit effort="10" velocity="6" />
<joint_properties friction="0.0"/>
</joint>

<joint name="left_hip_roll" type="revolute">
<origin xyz="0.0234 -6.93889e-18 0.04" rpy="-1.5708 -2.8828e-13 1.5708" />
<parent link="u_block_2" />
<child link="mx106_block_2" />
<axis xyz="0 0 1"/>
<limit effort="10" velocity="6" />
<joint_properties friction="0.0"/>
</joint>

<joint name="left_hip_yaw" type="revolute">
<origin xyz="0.046375 -0.011254 -0.00349999" rpy="-3.14159 -3.13509e-16 1.5708" />
<parent link="tronc" />
<child link="u_block_2" />
<axis xyz="0 0 -1"/>
<limit effort="10" velocity="6" />
<joint_properties friction="0.0"/>
</joint>

<link name="u_shoulder_1">
<collision>
<origin xyz="1.33839e-33 -2.77556e-17 0.003" rpy="-7.22126e-40 4.46115e-31 1.76672e-31" />
<geometry>
<box size="0.047 0.0275 0.006" />
</geometry>
</collision>
<visual>
<origin xyz="1.33839e-33 -2.77556e-17 0.003" rpy="-7.22126e-40 4.46115e-31 1.76672e-31" />
<geometry>
<box size="0.047 0.0275 0.006" />
</geometry>
<material name="u_base_64_material">
<color rgba="0.301961 0.301961 0.301961 1.0"/>
</material>
</visual>
<inertial>
<origin xyz="2.844e-18 0.00486029 0.0167829" rpy="0 0 0"/>
<mass value="0.042898" />
<inertia ixx="1.57991e-05" ixy="1.59248e-20"  ixz="-7.27391e-21" iyy="2.84983e-05" iyz="-3.76137e-06" izz="2.50037e-05" />
</inertial>
</link>

<link name="left_humerus_1">
<collision>
<origin xyz="-1.18835e-36 -0.015 -0.0235" rpy="-3.69779e-32 5.7326e-32 1.84671e-33" />
<geometry>
<box size="0.029 0.05 0.04" />
</geometry>
</collision>
<visual>
<origin xyz="-1.18835e-36 -0.015 -0.0235" rpy="-3.69779e-32 5.7326e-32 1.84671e-33" />
<geometry>
<box size="0.029 0.05 0.04" />
</geometry>
<material name="mx64_material">
<color rgba="0.211765 0.211765 0.211765 1.0"/>
</material>
</visual>
<collision>
<origin xyz="-1.0044e-14 -0.092 -0.0391736" rpy="3.45444e-16 -1.5708 0" />
<geometry>
<box size="0.003 0.07 0.03" />
</geometry>
</collision>
<collision>
<origin xyz="-1.00284e-14 -0.054 -0.0231736" rpy="3.45444e-16 -1.5708 0" />
<geometry>
<box size="0.03 0.003 0.03" />
</geometry>
</collision>
<visual>
<origin xyz="-1.0044e-14 -0.092 -0.0391736" rpy="3.45444e-16 -1.5708 0" />
<geometry>
<box size="0.003 0.07 0.03" />
</geometry>
<material name="humerus_plate_material">
<color rgba="0.301961 0.301961 0.301961 1.0"/>
</material>
</visual>
<visual>
<origin xyz="-1.00284e-14 -0.054 -0.0231736" rpy="3.45444e-16 -1.5708 0" />
<geometry>
<box size="0.03 0.003 0.03" />
</geometry>
<material name="humerus_plate_material">
<color rgba="0.301961 0.301961 0.301961 1.0"/>
</material>
</visual>
<inertial>
<origin xyz="-0.000852636 -0.0376399 -0.0248523" rpy="0 0 0"/>
<mass value="0.214223" />
<inertia ixx="0.000347701" ixy="-1.37313e-05"  ixz="2.97277e-06" iyy="6.51166e-05" iyz="-8.64098e-06" izz="0.000333302" />
</inertial>
</link>

<link name="left_radius_1">
<collision>
<origin xyz="-6.28624e-33 -0.015 -0.0235" rpy="2.98462e-31 -6.96352e-30 4.98955e-29" />
<geometry>
<box size="0.029 0.05 0.04" />
</geometry>
</collision>
<visual>
<origin xyz="-6.28624e-33 -0.015 -0.0235" rpy="2.98462e-31 -6.96352e-30 4.98955e-29" />
<geometry>
<box size="0.029 0.05 0.04" />
</geometry>
<material name="mx64_material">
<color rgba="0.211765 0.211765 0.211765 1.0"/>
</material>
</visual>
<collision>
<origin xyz="0.018 -0.0985 -0.0235" rpy="-3.14159 -1.63297e-15 3.14159" />
<geometry>
<box size="0.003 0.085 0.03" />
</geometry>
</collision>
<collision>
<origin xyz="0.0075 -0.141 -0.0235" rpy="-3.14159 -1.63297e-15 3.14159" />
<geometry>
<cylinder length="0.03" radius="0.012" />
</geometry>
</collision>
<visual>
<origin xyz="0.018 -0.0985 -0.0235" rpy="-3.14159 -1.63297e-15 3.14159" />
<geometry>
<box size="0.003 0.085 0.03" />
</geometry>
<material name="radius_plate_material">
<color rgba="0.301961 0.301961 0.301961 1.0"/>
</material>
</visual>
<visual>
<origin xyz="0.0075 -0.141 -0.0235" rpy="-3.14159 -1.63297e-15 3.14159" />
<geometry>
<cylinder length="0.03" radius="0.012" />
</geometry>
<material name="radius_plate_material">
<color rgba="0.301961 0.301961 0.301961 1.0"/>
</material>
</visual>
<inertial>
<origin xyz="0.00253363 -0.0370397 -0.0238779" rpy="0 0 0"/>
<mass value="0.20688" />
<inertia ixx="0.00037903" ixy="3.04226e-05"  ixz="4.20803e-07" iyy="5.36268e-05" iyz="-4.7904e-07" izz="0.00036378" />
</inertial>
</link>

<joint name="left_elbow" type="revolute">
<origin xyz="0.0235 -0.112 -0.00167365" rpy="4.539e-13 1.5708 0" />
<parent link="left_humerus_1" />
<child link="left_radius_1" />
<axis xyz="0 0 1"/>
<limit effort="10" velocity="6" />
<joint_properties friction="0.0"/>
</joint>

<joint name="left_shoulder_roll" type="revolute">
<origin xyz="0.0225 0.03 0.035" rpy="-3.14159 -1.5708 0" />
<parent link="u_shoulder_1" />
<child link="left_humerus_1" />
<axis xyz="0 0 1"/>
<limit effort="10" velocity="6" />
<joint_properties friction="0.0"/>
</joint>

<joint name="left_shoulder_pitch" type="revolute">
<origin xyz="0.0735 -0.032127 0.1609" rpy="-1.5708 -4.55145e-13 -1.5708" />
<parent link="tronc" />
<child link="u_shoulder_1" />
<axis xyz="-0 -0 1"/>
<limit effort="10" velocity="6" />
<joint_properties friction="0.0"/>
</joint>

<link name="u_shoulder_2">
<collision>
<origin xyz="1.93337e-32 -5.76021e-37 0.003" rpy="1.92007e-34 -6.15323e-30 3.0697e-32" />
<geometry>
<box size="0.047 0.0275 0.006" />
</geometry>
</collision>
<visual>
<origin xyz="1.93337e-32 -5.76021e-37 0.003" rpy="1.92007e-34 -6.15323e-30 3.0697e-32" />
<geometry>
<box size="0.047 0.0275 0.006" />
</geometry>
<material name="u_base_64_material">
<color rgba="0.301961 0.301961 0.301961 1.0"/>
</material>
</visual>
<inertial>
<origin xyz="2.52739e-18 0.00486029 0.0167829" rpy="0 0 0"/>
<mass value="0.042898" />
<inertia ixx="1.57991e-05" ixy="6.77626e-21"  ixz="-1.35525e-20" iyy="2.84983e-05" iyz="-3.76137e-06" izz="2.50037e-05" />
</inertial>
</link>

<link name="right_humerus_1">
<collision>
<origin xyz="-1.12653e-14 -0.092 -0.04" rpy="-4.54407e-13 -1.5708 0" />
<geometry>
<box size="0.003 0.07 0.03" />
</geometry>
</collision>
<collision>
<origin xyz="6.01949e-15 -0.054 -0.024" rpy="-4.54407e-13 -1.5708 0" />
<geometry>
<box size="0.03 0.003 0.03" />
</geometry>
</collision>
<visual>
<origin xyz="-1.12653e-14 -0.092 -0.04" rpy="-4.54407e-13 -1.5708 0" />
<geometry>
<box size="0.003 0.07 0.03" />
</geometry>
<material name="humerus_plate_material">
<color rgba="0.301961 0.301961 0.301961 1.0"/>
</material>
</visual>
<visual>
<origin xyz="6.01949e-15 -0.054 -0.024" rpy="-4.54407e-13 -1.5708 0" />
<geometry>
<box size="0.03 0.003 0.03" />
</geometry>
<material name="humerus_plate_material">
<color rgba="0.301961 0.301961 0.301961 1.0"/>
</material>
</visual>
<collision>
<origin xyz="-1.8006e-34 -0.015 -0.0235" rpy="-6.21528e-33 -3.83316e-31 7.07151e-34" />
<geometry>
<box size="0.029 0.05 0.04" />
</geometry>
</collision>
<visual>
<origin xyz="-1.8006e-34 -0.015 -0.0235" rpy="-6.21528e-33 -3.83316e-31 7.07151e-34" />
<geometry>
<box size="0.029 0.05 0.04" />
</geometry>
<material name="mx64_material">
<color rgba="0.211765 0.211765 0.211765 1.0"/>
</material>
</visual>
<inertial>
<origin xyz="0.00104402 -0.0376399 -0.0253663" rpy="0 0 0"/>
<mass value="0.214223" />
<inertia ixx="0.000347788" ixy="1.17167e-05"  ixz="-1.66771e-06" iyy="6.5125e-05" iyz="-1.16648e-05" izz="0.000333224" />
</inertial>
</link>

<link name="right_radius_1">
<collision>
<origin xyz="-0.018 -0.0985 -0.0235" rpy="2.95826e-16 1.82781e-15 2.61184e-16" />
<geometry>
<box size="0.003 0.085 0.03" />
</geometry>
</collision>
<collision>
<origin xyz="-0.0075 -0.141 -0.0235" rpy="2.95826e-16 1.82781e-15 2.61184e-16" />
<geometry>
<cylinder length="0.03" radius="0.012" />
</geometry>
</collision>
<visual>
<origin xyz="-0.018 -0.0985 -0.0235" rpy="2.95826e-16 1.82781e-15 2.61184e-16" />
<geometry>
<box size="0.003 0.085 0.03" />
</geometry>
<material name="radius_plate_material">
<color rgba="0.301961 0.301961 0.301961 1.0"/>
</material>
</visual>
<visual>
<origin xyz="-0.0075 -0.141 -0.0235" rpy="2.95826e-16 1.82781e-15 2.61184e-16" />
<geometry>
<cylinder length="0.03" radius="0.012" />
</geometry>
<material name="radius_plate_material">
<color rgba="0.301961 0.301961 0.301961 1.0"/>
</material>
</visual>
<collision>
<origin xyz="1.54086e-34 -0.015 -0.0235" rpy="-9.13831e-31 2.44997e-30 -2.05357e-33" />
<geometry>
<box size="0.029 0.05 0.04" />
</geometry>
</collision>
<visual>
<origin xyz="1.54086e-34 -0.015 -0.0235" rpy="-9.13831e-31 2.44997e-30 -2.05357e-33" />
<geometry>
<box size="0.029 0.05 0.04" />
</geometry>
<material name="mx64_material">
<color rgba="0.211765 0.211765 0.211765 1.0"/>
</material>
</visual>
<inertial>
<origin xyz="-0.00233545 -0.0370397 -0.0236354" rpy="0 0 0"/>
<mass value="0.20688" />
<inertia ixx="0.000379056" ixy="-3.24125e-05"  ixz="7.54143e-07" iyy="5.38522e-05" iyz="-9.99715e-09" izz="0.00036398" />
</inertial>
</link>

<joint name="right_elbow" type="revolute">
<origin xyz="-0.0235 -0.112 -0.0025" rpy="-9.07649e-13 -1.5708 0" />
<parent link="right_humerus_1" />
<child link="right_radius_1" />
<axis xyz="-0 -0 -1"/>
<limit effort="10" velocity="6" />
<joint_properties friction="0.0"/>
</joint>

<joint name="right_shoulder_roll" type="revolute">
<origin xyz="-0.0225 0.03 0.035" rpy="3.14159 1.5708 0" />
<parent link="u_shoulder_2" />
<child link="right_humerus_1" />
<axis xyz="0 0 1"/>
<limit effort="10" velocity="6" />
<joint_properties friction="0.0"/>
</joint>

<joint name="right_shoulder_pitch" type="revolute">
<origin xyz="-0.0740868 -0.032127 0.1609" rpy="-1.5708 -6.38201e-16 1.5708" />
<parent link="tronc" />
<child link="u_shoulder_2" />
<axis xyz="0 0 -1"/>
<limit effort="10" velocity="6" />
<joint_properties friction="0.0"/>
</joint>

<link name="u_neck_1">
<collision>
<origin xyz="3.15544e-30 -2.10311e-43 0.003" rpy="-2.95823e-31 8.24478e-32 -3.20328e-30" />
<geometry>
<box size="0.047 0.0275 0.006" />
</geometry>
</collision>
<visual>
<origin xyz="3.15544e-30 -2.10311e-43 0.003" rpy="-2.95823e-31 8.24478e-32 -3.20328e-30" />
<geometry>
<box size="0.047 0.0275 0.006" />
</geometry>
<material name="u_base_64_material">
<color rgba="0.301961 0.301961 0.301961 1.0"/>
</material>
</visual>
<collision>
<origin xyz="-0.025 -2.70617e-16 0.023" rpy="1.5708 -3.29254e-16 1.5708" />
<geometry>
<box size="0.025 0.044 0.003" />
</geometry>
</collision>
<visual>
<origin xyz="-0.025 -2.70617e-16 0.023" rpy="1.5708 -3.29254e-16 1.5708" />
<geometry>
<box size="0.025 0.044 0.003" />
</geometry>
<material name="u_side_small_material">
<color rgba="0.301961 0.301961 0.301961 1.0"/>
</material>
</visual>
<collision>
<origin xyz="0.025 -2.48065e-16 0.023" rpy="1.5708 7.60838e-16 -1.5708" />
<geometry>
<box size="0.025 0.044 0.003" />
</geometry>
</collision>
<visual>
<origin xyz="0.025 -2.48065e-16 0.023" rpy="1.5708 7.60838e-16 -1.5708" />
<geometry>
<box size="0.025 0.044 0.003" />
</geometry>
<material name="u_side_small_material">
<color rgba="0.301961 0.301961 0.301961 1.0"/>
</material>
</visual>
<inertial>
<origin xyz="-2.17085e-17 -1.29969e-16 0.0128918" rpy="0 0 0"/>
<mass value="0.0362092" />
<inertia ixx="6.41955e-06" ixy="4.27371e-12"  ixz="3.64701e-13" iyy="2.38199e-05" iyz="4.49501e-20" izz="2.02973e-05" />
</inertial>
</link>

<link name="head_1">
<collision>
<origin xyz="-0.0375 -0.0698 -0.005" rpy="-3.14159 9.99201e-16 1.22132e-13" />
<geometry>
<box size="0.008 0.05 0.003" />
</geometry>
</collision>
<collision>
<origin xyz="-6.61757e-15 -0.0698 -0.005" rpy="-3.14159 9.99201e-16 1.22132e-13" />
<geometry>
<box size="0.008 0.05 0.003" />
</geometry>
</collision>
<collision>
<origin xyz="0.0375 -0.0698 -0.005" rpy="-3.14159 9.99201e-16 1.22132e-13" />
<geometry>
<box size="0.008 0.05 0.003" />
</geometry>
</collision>
<collision>
<origin xyz="-9.43298e-15 -0.0468 -0.005" rpy="-3.14159 9.99201e-16 1.22132e-13" />
<geometry>
<box size="0.083 0.008 0.003" />
</geometry>
</collision>
<collision>
<origin xyz="-6.61757e-15 -0.0698 -0.005" rpy="-3.14159 9.99201e-16 1.22132e-13" />
<geometry>
<box size="0.083 0.008 0.003" />
</geometry>
</collision>
<collision>
<origin xyz="-3.80216e-15 -0.0928 -0.005" rpy="-3.14159 9.99201e-16 1.22132e-13" />
<geometry>
<box size="0.083 0.008 0.003" />
</geometry>
</collision>
<visual>
<origin xyz="-0.0375 -0.0698 -0.005" rpy="-3.14159 9.99201e-16 1.22132e-13" />
<geometry>
<box size="0.008 0.05 0.003" />
</geometry>
<material name="head_plate_material">
<color rgba="0.701961 0.682353 0.623529 1.0"/>
</material>
</visual>
<visual>
<origin xyz="-6.61757e-15 -0.0698 -0.005" rpy="-3.14159 9.99201e-16 1.22132e-13" />
<geometry>
<box size="0.008 0.05 0.003" />
</geometry>
<material name="head_plate_material">
<color rgba="0.701961 0.682353 0.623529 1.0"/>
</material>
</visual>
<visual>
<origin xyz="0.0375 -0.0698 -0.005" rpy="-3.14159 9.99201e-16 1.22132e-13" />
<geometry>
<box size="0.008 0.05 0.003" />
</geometry>
<material name="head_plate_material">
<color rgba="0.701961 0.682353 0.623529 1.0"/>
</material>
</visual>
<visual>
<origin xyz="-9.43298e-15 -0.0468 -0.005" rpy="-3.14159 9.99201e-16 1.22132e-13" />
<geometry>
<box size="0.083 0.008 0.003" />
</geometry>
<material name="head_plate_material">
<color rgba="0.701961 0.682353 0.623529 1.0"/>
</material>
</visual>
<visual>
<origin xyz="-6.61757e-15 -0.0698 -0.005" rpy="-3.14159 9.99201e-16 1.22132e-13" />
<geometry>
<box size="0.083 0.008 0.003" />
</geometry>
<material name="head_plate_material">
<color rgba="0.701961 0.682353 0.623529 1.0"/>
</material>
</visual>
<visual>
<origin xyz="-3.80216e-15 -0.0928 -0.005" rpy="-3.14159 9.99201e-16 1.22132e-13" />
<geometry>
<box size="0.083 0.008 0.003" />
</geometry>
<material name="head_plate_material">
<color rgba="0.701961 0.682353 0.623529 1.0"/>
</material>
</visual>
<collision>
<origin xyz="0.00496822 -0.06905 -0.0235" rpy="1.5708 -1.5708 0" />
<geometry>
<box size="0.03 0.03 0.028" />
</geometry>
</collision>
<visual>
<origin xyz="0.00496822 -0.06905 -0.0235" rpy="1.5708 -1.5708 0" />
<geometry>
<box size="0.03 0.03 0.028" />
</geometry>
<material name="ptgrey_camera_material">
<color rgba="0.4 0.4 0.4 1.0"/>
</material>
</visual>
<collision>
<origin xyz="-0.0375 -0.0698 -0.042" rpy="-3.14159 1.16573e-15 1.27614e-13" />
<geometry>
<box size="0.008 0.05 0.003" />
</geometry>
</collision>
<collision>
<origin xyz="-6.45418e-15 -0.0698 -0.042" rpy="-3.14159 1.16573e-15 1.27614e-13" />
<geometry>
<box size="0.008 0.05 0.003" />
</geometry>
</collision>
<collision>
<origin xyz="0.0375 -0.0698 -0.042" rpy="-3.14159 1.16573e-15 1.27614e-13" />
<geometry>
<box size="0.008 0.05 0.003" />
</geometry>
</collision>
<collision>
<origin xyz="-9.39695e-15 -0.0468 -0.042" rpy="-3.14159 1.16573e-15 1.27614e-13" />
<geometry>
<box size="0.083 0.008 0.003" />
</geometry>
</collision>
<collision>
<origin xyz="-6.45418e-15 -0.0698 -0.042" rpy="-3.14159 1.16573e-15 1.27614e-13" />
<geometry>
<box size="0.083 0.008 0.003" />
</geometry>
</collision>
<collision>
<origin xyz="-3.5114e-15 -0.0928 -0.042" rpy="-3.14159 1.16573e-15 1.27614e-13" />
<geometry>
<box size="0.083 0.008 0.003" />
</geometry>
</collision>
<visual>
<origin xyz="-0.0375 -0.0698 -0.042" rpy="-3.14159 1.16573e-15 1.27614e-13" />
<geometry>
<box size="0.008 0.05 0.003" />
</geometry>
<material name="head_plate_material">
<color rgba="0.701961 0.682353 0.623529 1.0"/>
</material>
</visual>
<visual>
<origin xyz="-6.45418e-15 -0.0698 -0.042" rpy="-3.14159 1.16573e-15 1.27614e-13" />
<geometry>
<box size="0.008 0.05 0.003" />
</geometry>
<material name="head_plate_material">
<color rgba="0.701961 0.682353 0.623529 1.0"/>
</material>
</visual>
<visual>
<origin xyz="0.0375 -0.0698 -0.042" rpy="-3.14159 1.16573e-15 1.27614e-13" />
<geometry>
<box size="0.008 0.05 0.003" />
</geometry>
<material name="head_plate_material">
<color rgba="0.701961 0.682353 0.623529 1.0"/>
</material>
</visual>
<visual>
<origin xyz="-9.39695e-15 -0.0468 -0.042" rpy="-3.14159 1.16573e-15 1.27614e-13" />
<geometry>
<box size="0.083 0.008 0.003" />
</geometry>
<material name="head_plate_material">
<color rgba="0.701961 0.682353 0.623529 1.0"/>
</material>
</visual>
<visual>
<origin xyz="-6.45418e-15 -0.0698 -0.042" rpy="-3.14159 1.16573e-15 1.27614e-13" />
<geometry>
<box size="0.083 0.008 0.003" />
</geometry>
<material name="head_plate_material">
<color rgba="0.701961 0.682353 0.623529 1.0"/>
</material>
</visual>
<visual>
<origin xyz="-3.5114e-15 -0.0928 -0.042" rpy="-3.14159 1.16573e-15 1.27614e-13" />
<geometry>
<box size="0.083 0.008 0.003" />
</geometry>
<material name="head_plate_material">
<color rgba="0.701961 0.682353 0.623529 1.0"/>
</material>
</visual>
<collision>
<origin xyz="8.35459e-33 -0.015 -0.0235" rpy="4.00673e-32 2.86713e-30 -1.80961e-30" />
<geometry>
<box size="0.029 0.05 0.04" />
</geometry>
</collision>
<visual>
<origin xyz="8.35459e-33 -0.015 -0.0235" rpy="4.00673e-32 2.86713e-30 -1.80961e-30" />
<geometry>
<box size="0.029 0.05 0.04" />
</geometry>
<material name="mx64_material">
<color rgba="0.211765 0.211765 0.211765 1.0"/>
</material>
</visual>
<inertial>
<origin xyz="0.00127384 -0.0343518 -0.0237209" rpy="0 0 0"/>
<mass value="0.228227" />
<inertia ixx="0.000236902" ixy="9.17476e-06"  ixz="5.76668e-07" iyy="8.77015e-05" iyz="-3.39163e-07" izz="0.000235668" />
</inertial>
</link>

<link name="camera">
<inertial>
<origin xyz="0 0 0" rpy="0 0 0" />
<mass value="1e-9" />
<inertia ixx="0" ixy="0" ixz="0" iyy="0" iyz="0" izz="0" />
</inertial>
</link>
<joint name="camera_frame" type="floating">
<origin xyz="0.024933 -0.06905 -0.0235" rpy="-1.24392e-13 1.5708 0" />
<parent link="head_1" />
<child link="camera" />
<axis xyz="0 0 0"/>
</joint>

<link name="vive">
<inertial>
<origin xyz="0 0 0" rpy="0 0 0" />
<mass value="1e-9" />
<inertia ixx="0" ixy="0" ixz="0" iyy="0" iyz="0" izz="0" />
</inertial>
</link>
<joint name="vive_frame" type="floating">
<origin xyz="-2.95597e-15 -0.0998 -0.0235" rpy="-1.5708 -1.16113e-15 -3.14159" />
<parent link="head_1" />
<child link="vive" />
<axis xyz="0 0 0"/>
</joint>

<joint name="head_pitch" type="revolute">
<origin xyz="-0.0235 -4.85723e-16 0.04" rpy="-1.5708 -7.60838e-16 1.5708" />
<parent link="u_neck_1" />
<child link="head_1" />
<axis xyz="0 0 1"/>
<limit effort="10" velocity="6" />
<joint_properties friction="0.0"/>
</joint>

<joint name="head_yaw" type="revolute">
<origin xyz="2.67834e-14 -0.037127 0.1858" rpy="1.12133e-14 -2.28241e-15 -3.14159" />
<parent link="tronc" />
<child link="u_neck_1" />
<axis xyz="-0 -0 1"/>
<limit effort="10" velocity="6" />
<joint_properties friction="0.0"/>
</joint>


</robot>
