<?xml version="1.0" ?>
<!-- Generated using onshape-to-robot -->
<!-- OnShape https://cad.onshape.com/documents/6a6e5b10ef079339c2ddde84/w/207da6d79692e0bbf50113f2/e/9f3edd12689fa0c486a7d0d7 -->
<mujoco model="adjustable_height_arm_mujoco">
    <compiler angle="radian" meshdir="assets" autolimits="true"/>
    <option noslip_iterations="1"/>
    <default>
        <default class="adjustable_height_arm_mujoco">
            <joint frictionloss="0.1" armature="0.005"/>
            <position kp="50" dampratio="1"/>
            <default class="visual">
                <geom type="mesh" contype="0" conaffinity="0" group="2"/>
            </default>
            <default class="collision">
                <geom group="3"/>
            </default>
        </default>
    </default>
    <worldbody>
        <!-- Link base -->
        <body name="base" pos="0 0 0" quat="1 0 0 0" childclass="adjustable_height_arm_mujoco">
            <inertial pos="-6.05295e-19 3.12294e-18 0.020169" mass="0.39382" fullinertia="0.000177195 0.000177195 0.000123463 0 0 0"/>
            <!-- Part base -->
            <!-- Mesh base -->
            <geom type="mesh" class="visual" pos="0 0 0" quat="1 0 0 0" mesh="base" material="base_material"/>
            <!-- Link part1 -->
            <body name="part1" pos="0 2.91893e-18 0.053" quat="1 0 0 0">
                <!-- Joint from base to part1 -->
                <joint name="slider" type="slide" range="-0.05 -0.0" frictionloss="5"/>
                <inertial pos="1.04896e-19 1.19328e-18 0.027892" mass="0.298971" fullinertia="0.000123868 0.000123868 9.58869e-05 0 0 0"/>
                <!-- Part part1 -->
                <!-- Mesh part1 -->
                <geom type="mesh" class="visual" pos="0 -4.65366e-18 -0.053" quat="1 0 0 0" mesh="part1" material="part1_material"/>
                <!-- Link part2 -->
                <body name="part2" pos="-2.82344e-18 2.35752e-18 0.053" quat="0 1 0 0">
                    <!-- Joint from part1 to part2 -->
                    <joint name="part2" type="hinge"/>
                    <inertial pos="6.6239e-09 -1.69553e-10 -0.0149478" mass="0.148575" fullinertia="6.89125e-05 6.97803e-05 6.69782e-05 6.11498e-11 -5.85353e-12 1.49834e-13"/>
                    <!-- Part part2 -->
                    <!-- Mesh part2 -->
                    <geom type="mesh" class="visual" pos="2.82344e-18 1.22153e-17 0.106" quat="0 1 0 0" mesh="part2" material="part2_material"/>
                    <!-- Link part3 -->
                    <body name="part3" pos="-0.02 1.22153e-17 -0.025" quat="0.5 0.5 -0.5 -0.5">
                        <!-- Joint from part2 to part3 -->
                        <joint name="part3" type="hinge"/>
                        <inertial pos="-3.06226e-08 -0.0314519 -0.02" mass="0.642728" fullinertia="0.000872587 0.000126043 0.000853226 2.83073e-11 2.04764e-10 -1.52882e-10"/>
                        <!-- Part part3 -->
                        <!-- Mesh part3 -->
                        <geom type="mesh" class="visual" pos="0 0.131 -0.02" quat="0.5 0.5 0.5 -0.5" mesh="part3" material="part3_material"/>
                        <!-- Link part4 -->
                        <body name="part4" pos="9.86076e-32 -0.0975 0" quat="1 0 6.50521e-19 -1.19928e-15">
                            <!-- Joint from part3 to part4 -->
                            <joint name="part4" type="hinge"/>
                            <inertial pos="-3.54611e-08 -0.0331362 -0.02" mass="0.64593" fullinertia="0.000969336 8.7724e-05 0.000952436 2.66297e-11 -2.9556e-10 2.45199e-10"/>
                            <!-- Part part4 -->
                            <!-- Mesh part4 -->
                            <geom type="mesh" class="visual" pos="0 0.2285 -0.02" quat="0.5 0.5 0.5 -0.5" mesh="part4" material="part4_material"/>
                            <!-- Frame tip (dummy link + fixed joint) -->
                            <site name="tip" pos="1.00568e-18 -0.1325 -0.02" quat="0.707107 0.707107 0 1.02846e-30"/>
                        </body>
                    </body>
                </body>
            </body>
        </body>
    </worldbody>
    <asset>
        <mesh file="part3.stl"/>
        <mesh file="part1.stl"/>
        <mesh file="part2.stl"/>
        <mesh file="base.stl"/>
        <mesh file="part4.stl"/>
        <material name="base_material" rgba="0.301961 0.290196 0.262745 1"/>
        <material name="part1_material" rgba="0.866667 0.321569 0.156863 1"/>
        <material name="part2_material" rgba="0.372549 0.654902 0.239216 1"/>
        <material name="part3_material" rgba="0.0862745 0.317647 0.690196 1"/>
        <material name="part4_material" rgba="0.972549 0.529412 0.00392157 1"/>
    </asset>
    <actuator>
        <position class="adjustable_height_arm_mujoco" name="part4" joint="part4"/>
        <position class="adjustable_height_arm_mujoco" name="part3" joint="part3"/>
        <position class="adjustable_height_arm_mujoco" name="part2" joint="part2"/>
        <position class="adjustable_height_arm_mujoco" name="slider" joint="slider" kp="10000" forcerange="-50 50" ctrlrange="-0.05 -0.0"/>
    </actuator>
    <equality/>
</mujoco>
